[2024-05-22 02:20:24,887] {taskinstance.py:1032} INFO - Dependencies all met for <TaskInstance: purpleair_api_dag.fetch_data scheduled__2024-05-21T10:00:00+00:00 [queued]>
[2024-05-22 02:20:24,909] {taskinstance.py:1032} INFO - Dependencies all met for <TaskInstance: purpleair_api_dag.fetch_data scheduled__2024-05-21T10:00:00+00:00 [queued]>
[2024-05-22 02:20:24,910] {taskinstance.py:1238} INFO - 
--------------------------------------------------------------------------------
[2024-05-22 02:20:24,910] {taskinstance.py:1239} INFO - Starting attempt 1 of 2
[2024-05-22 02:20:24,910] {taskinstance.py:1240} INFO - 
--------------------------------------------------------------------------------
[2024-05-22 02:20:24,934] {taskinstance.py:1259} INFO - Executing <Task(PythonOperator): fetch_data> on 2024-05-21 10:00:00+00:00
[2024-05-22 02:20:24,948] {standard_task_runner.py:52} INFO - Started process 2364 to run task
[2024-05-22 02:20:24,993] {standard_task_runner.py:76} INFO - Running: ['***', 'tasks', 'run', 'purpleair_api_dag', 'fetch_data', 'scheduled__2024-05-21T10:00:00+00:00', '--job-id', '12', '--raw', '--subdir', 'DAGS_FOLDER/data_ingestion.py', '--cfg-path', '/tmp/tmp5vtc_wqh', '--error-file', '/tmp/tmppw3o8bmi']
[2024-05-22 02:20:25,026] {standard_task_runner.py:77} INFO - Job 12: Subtask fetch_data
[2024-05-22 02:20:25,284] {logging_mixin.py:109} INFO - Running <TaskInstance: purpleair_api_dag.fetch_data scheduled__2024-05-21T10:00:00+00:00 [running]> on host 8fe6997c1526
[2024-05-22 02:20:25,458] {taskinstance.py:1426} INFO - Exporting the following env vars:
AIRFLOW_CTX_DAG_OWNER=***
AIRFLOW_CTX_DAG_ID=purpleair_api_dag
AIRFLOW_CTX_TASK_ID=fetch_data
AIRFLOW_CTX_EXECUTION_DATE=2024-05-21T10:00:00+00:00
AIRFLOW_CTX_DAG_RUN_ID=scheduled__2024-05-21T10:00:00+00:00
[2024-05-22 02:20:25,674] {logging_mixin.py:109} INFO - Failed to retrieve data: 403
[2024-05-22 02:20:25,690] {python.py:175} INFO - Done. Returned value was: None
[2024-05-22 02:20:25,756] {taskinstance.py:1277} INFO - Marking task as SUCCESS. dag_id=purpleair_api_dag, task_id=fetch_data, execution_date=20240521T100000, start_date=20240522T022024, end_date=20240522T022025
[2024-05-22 02:20:25,828] {local_task_job.py:154} INFO - Task exited with return code 0
[2024-05-22 02:20:25,931] {local_task_job.py:264} INFO - 0 downstream tasks scheduled from follow-on schedule check
[2024-05-22 04:14:13,396] {taskinstance.py:1032} INFO - Dependencies all met for <TaskInstance: purpleair_api_dag.fetch_data scheduled__2024-05-21T10:00:00+00:00 [queued]>
[2024-05-22 04:14:13,505] {taskinstance.py:1032} INFO - Dependencies all met for <TaskInstance: purpleair_api_dag.fetch_data scheduled__2024-05-21T10:00:00+00:00 [queued]>
[2024-05-22 04:14:13,508] {taskinstance.py:1238} INFO - 
--------------------------------------------------------------------------------
[2024-05-22 04:14:13,510] {taskinstance.py:1239} INFO - Starting attempt 1 of 2
[2024-05-22 04:14:13,511] {taskinstance.py:1240} INFO - 
--------------------------------------------------------------------------------
[2024-05-22 04:14:13,636] {taskinstance.py:1259} INFO - Executing <Task(PythonOperator): fetch_data> on 2024-05-21 10:00:00+00:00
[2024-05-22 04:14:13,737] {standard_task_runner.py:52} INFO - Started process 155 to run task
[2024-05-22 04:14:13,758] {standard_task_runner.py:76} INFO - Running: ['***', 'tasks', 'run', 'purpleair_api_dag', 'fetch_data', 'scheduled__2024-05-21T10:00:00+00:00', '--job-id', '13', '--raw', '--subdir', 'DAGS_FOLDER/data_ingestion.py', '--cfg-path', '/tmp/tmph43_noij', '--error-file', '/tmp/tmp377x3q7l']
[2024-05-22 04:14:13,800] {standard_task_runner.py:77} INFO - Job 13: Subtask fetch_data
[2024-05-22 04:14:14,108] {logging_mixin.py:109} INFO - Running <TaskInstance: purpleair_api_dag.fetch_data scheduled__2024-05-21T10:00:00+00:00 [running]> on host 3419eee920a5
[2024-05-22 04:14:14,372] {taskinstance.py:1426} INFO - Exporting the following env vars:
AIRFLOW_CTX_DAG_OWNER=***
AIRFLOW_CTX_DAG_ID=purpleair_api_dag
AIRFLOW_CTX_TASK_ID=fetch_data
AIRFLOW_CTX_EXECUTION_DATE=2024-05-21T10:00:00+00:00
AIRFLOW_CTX_DAG_RUN_ID=scheduled__2024-05-21T10:00:00+00:00
[2024-05-22 04:14:14,382] {taskinstance.py:1700} ERROR - Task failed with exception
Traceback (most recent call last):
  File "/home/airflow/.local/lib/python3.6/site-packages/airflow/models/taskinstance.py", line 1329, in _run_raw_task
    self._execute_task_with_callbacks(context)
  File "/home/airflow/.local/lib/python3.6/site-packages/airflow/models/taskinstance.py", line 1455, in _execute_task_with_callbacks
    result = self._execute_task(context, self.task)
  File "/home/airflow/.local/lib/python3.6/site-packages/airflow/models/taskinstance.py", line 1511, in _execute_task
    result = execute_callable(context=context)
  File "/home/airflow/.local/lib/python3.6/site-packages/airflow/operators/python.py", line 174, in execute
    return_value = self.execute_callable()
  File "/home/airflow/.local/lib/python3.6/site-packages/airflow/operators/python.py", line 185, in execute_callable
    return self.python_callable(*self.op_args, **self.op_kwargs)
  File "/opt/airflow/dags/data_ingestion.py", line 67, in api_url
    print(f" url is {url}")
NameError: name 'url' is not defined
[2024-05-22 04:14:14,423] {taskinstance.py:1277} INFO - Marking task as UP_FOR_RETRY. dag_id=purpleair_api_dag, task_id=fetch_data, execution_date=20240521T100000, start_date=20240522T041413, end_date=20240522T041414
[2024-05-22 04:14:14,481] {standard_task_runner.py:92} ERROR - Failed to execute job 13 for task fetch_data
Traceback (most recent call last):
  File "/home/airflow/.local/lib/python3.6/site-packages/airflow/task/task_runner/standard_task_runner.py", line 85, in _start_by_fork
    args.func(args, dag=self.dag)
  File "/home/airflow/.local/lib/python3.6/site-packages/airflow/cli/cli_parser.py", line 48, in command
    return func(*args, **kwargs)
  File "/home/airflow/.local/lib/python3.6/site-packages/airflow/utils/cli.py", line 92, in wrapper
    return f(*args, **kwargs)
  File "/home/airflow/.local/lib/python3.6/site-packages/airflow/cli/commands/task_command.py", line 298, in task_run
    _run_task_by_selected_method(args, dag, ti)
  File "/home/airflow/.local/lib/python3.6/site-packages/airflow/cli/commands/task_command.py", line 107, in _run_task_by_selected_method
    _run_raw_task(args, ti)
  File "/home/airflow/.local/lib/python3.6/site-packages/airflow/cli/commands/task_command.py", line 184, in _run_raw_task
    error_file=args.error_file,
  File "/home/airflow/.local/lib/python3.6/site-packages/airflow/utils/session.py", line 70, in wrapper
    return func(*args, session=session, **kwargs)
  File "/home/airflow/.local/lib/python3.6/site-packages/airflow/models/taskinstance.py", line 1329, in _run_raw_task
    self._execute_task_with_callbacks(context)
  File "/home/airflow/.local/lib/python3.6/site-packages/airflow/models/taskinstance.py", line 1455, in _execute_task_with_callbacks
    result = self._execute_task(context, self.task)
  File "/home/airflow/.local/lib/python3.6/site-packages/airflow/models/taskinstance.py", line 1511, in _execute_task
    result = execute_callable(context=context)
  File "/home/airflow/.local/lib/python3.6/site-packages/airflow/operators/python.py", line 174, in execute
    return_value = self.execute_callable()
  File "/home/airflow/.local/lib/python3.6/site-packages/airflow/operators/python.py", line 185, in execute_callable
    return self.python_callable(*self.op_args, **self.op_kwargs)
  File "/opt/airflow/dags/data_ingestion.py", line 67, in api_url
    print(f" url is {url}")
NameError: name 'url' is not defined
[2024-05-22 04:14:14,551] {local_task_job.py:154} INFO - Task exited with return code 1
[2024-05-22 04:14:15,260] {local_task_job.py:264} INFO - 0 downstream tasks scheduled from follow-on schedule check
[2024-05-22 04:17:39,028] {taskinstance.py:1032} INFO - Dependencies all met for <TaskInstance: purpleair_api_dag.fetch_data scheduled__2024-05-21T10:00:00+00:00 [queued]>
[2024-05-22 04:17:39,143] {taskinstance.py:1032} INFO - Dependencies all met for <TaskInstance: purpleair_api_dag.fetch_data scheduled__2024-05-21T10:00:00+00:00 [queued]>
[2024-05-22 04:17:39,152] {taskinstance.py:1238} INFO - 
--------------------------------------------------------------------------------
[2024-05-22 04:17:39,153] {taskinstance.py:1239} INFO - Starting attempt 1 of 2
[2024-05-22 04:17:39,153] {taskinstance.py:1240} INFO - 
--------------------------------------------------------------------------------
[2024-05-22 04:17:39,205] {taskinstance.py:1259} INFO - Executing <Task(PythonOperator): fetch_data> on 2024-05-21 10:00:00+00:00
[2024-05-22 04:17:39,239] {standard_task_runner.py:52} INFO - Started process 339 to run task
[2024-05-22 04:17:39,260] {standard_task_runner.py:76} INFO - Running: ['***', 'tasks', 'run', 'purpleair_api_dag', 'fetch_data', 'scheduled__2024-05-21T10:00:00+00:00', '--job-id', '30', '--raw', '--subdir', 'DAGS_FOLDER/data_ingestion.py', '--cfg-path', '/tmp/tmpkb2n1i7v', '--error-file', '/tmp/tmpopqv2yrr']
[2024-05-22 04:17:39,334] {standard_task_runner.py:77} INFO - Job 30: Subtask fetch_data
[2024-05-22 04:17:39,780] {logging_mixin.py:109} INFO - Running <TaskInstance: purpleair_api_dag.fetch_data scheduled__2024-05-21T10:00:00+00:00 [running]> on host 3419eee920a5
[2024-05-22 04:17:40,053] {taskinstance.py:1426} INFO - Exporting the following env vars:
AIRFLOW_CTX_DAG_OWNER=***
AIRFLOW_CTX_DAG_ID=purpleair_api_dag
AIRFLOW_CTX_TASK_ID=fetch_data
AIRFLOW_CTX_EXECUTION_DATE=2024-05-21T10:00:00+00:00
AIRFLOW_CTX_DAG_RUN_ID=scheduled__2024-05-21T10:00:00+00:00
[2024-05-22 04:17:40,059] {logging_mixin.py:109} INFO -  api is None
[2024-05-22 04:17:40,080] {logging_mixin.py:109} INFO - Full URL: https://api.purpleair.com/v1/sensors?fields=latitude%2Clongitude%2Chumidity%2Cpm2.5_60minute%2Clast_seen&location_type=0&max_age=300
[2024-05-22 04:17:40,084] {logging_mixin.py:109} INFO - Headers: {'X-API-Key': 'None'}
[2024-05-22 04:17:40,193] {logging_mixin.py:109} INFO - Status Code: 403
[2024-05-22 04:17:40,194] {logging_mixin.py:109} INFO - Response Content: {
  "api_version" : "V1.0.13-0.0.56",
  "time_stamp" : 1716351460,
  "error" : "ApiKeyInvalidError",
  "description" : "The provided api_key was not valid."
}
[2024-05-22 04:17:40,275] {logging_mixin.py:109} INFO - Failed to retrieve data: 403
[2024-05-22 04:17:40,285] {python.py:175} INFO - Done. Returned value was: None
[2024-05-22 04:17:40,336] {taskinstance.py:1277} INFO - Marking task as SUCCESS. dag_id=purpleair_api_dag, task_id=fetch_data, execution_date=20240521T100000, start_date=20240522T041739, end_date=20240522T041740
[2024-05-22 04:17:40,508] {local_task_job.py:154} INFO - Task exited with return code 0
[2024-05-22 04:17:40,662] {local_task_job.py:264} INFO - 0 downstream tasks scheduled from follow-on schedule check
