[2024-05-22 02:20:23,972] {taskinstance.py:1032} INFO - Dependencies all met for <TaskInstance: purpleair_api_dag.fetch_data scheduled__2024-05-21T09:00:00+00:00 [queued]>
[2024-05-22 02:20:24,164] {taskinstance.py:1032} INFO - Dependencies all met for <TaskInstance: purpleair_api_dag.fetch_data scheduled__2024-05-21T09:00:00+00:00 [queued]>
[2024-05-22 02:20:24,164] {taskinstance.py:1238} INFO - 
--------------------------------------------------------------------------------
[2024-05-22 02:20:24,165] {taskinstance.py:1239} INFO - Starting attempt 1 of 2
[2024-05-22 02:20:24,165] {taskinstance.py:1240} INFO - 
--------------------------------------------------------------------------------
[2024-05-22 02:20:24,233] {taskinstance.py:1259} INFO - Executing <Task(PythonOperator): fetch_data> on 2024-05-21 09:00:00+00:00
[2024-05-22 02:20:24,297] {standard_task_runner.py:52} INFO - Started process 2363 to run task
[2024-05-22 02:20:24,319] {standard_task_runner.py:76} INFO - Running: ['***', 'tasks', 'run', 'purpleair_api_dag', 'fetch_data', 'scheduled__2024-05-21T09:00:00+00:00', '--job-id', '11', '--raw', '--subdir', 'DAGS_FOLDER/data_ingestion.py', '--cfg-path', '/tmp/tmpnlk0f6m2', '--error-file', '/tmp/tmpvwphuz25']
[2024-05-22 02:20:24,363] {standard_task_runner.py:77} INFO - Job 11: Subtask fetch_data
[2024-05-22 02:20:24,886] {logging_mixin.py:109} INFO - Running <TaskInstance: purpleair_api_dag.fetch_data scheduled__2024-05-21T09:00:00+00:00 [running]> on host 8fe6997c1526
[2024-05-22 02:20:25,248] {taskinstance.py:1426} INFO - Exporting the following env vars:
AIRFLOW_CTX_DAG_OWNER=***
AIRFLOW_CTX_DAG_ID=purpleair_api_dag
AIRFLOW_CTX_TASK_ID=fetch_data
AIRFLOW_CTX_EXECUTION_DATE=2024-05-21T09:00:00+00:00
AIRFLOW_CTX_DAG_RUN_ID=scheduled__2024-05-21T09:00:00+00:00
[2024-05-22 02:20:25,463] {logging_mixin.py:109} INFO - Failed to retrieve data: 403
[2024-05-22 02:20:25,464] {python.py:175} INFO - Done. Returned value was: None
[2024-05-22 02:20:25,498] {taskinstance.py:1277} INFO - Marking task as SUCCESS. dag_id=purpleair_api_dag, task_id=fetch_data, execution_date=20240521T090000, start_date=20240522T022023, end_date=20240522T022025
[2024-05-22 02:20:25,603] {local_task_job.py:154} INFO - Task exited with return code 0
[2024-05-22 02:20:25,692] {local_task_job.py:264} INFO - 0 downstream tasks scheduled from follow-on schedule check
[2024-05-22 04:14:11,940] {taskinstance.py:1032} INFO - Dependencies all met for <TaskInstance: purpleair_api_dag.fetch_data scheduled__2024-05-21T09:00:00+00:00 [queued]>
[2024-05-22 04:14:12,114] {taskinstance.py:1032} INFO - Dependencies all met for <TaskInstance: purpleair_api_dag.fetch_data scheduled__2024-05-21T09:00:00+00:00 [queued]>
[2024-05-22 04:14:12,114] {taskinstance.py:1238} INFO - 
--------------------------------------------------------------------------------
[2024-05-22 04:14:12,114] {taskinstance.py:1239} INFO - Starting attempt 1 of 2
[2024-05-22 04:14:12,115] {taskinstance.py:1240} INFO - 
--------------------------------------------------------------------------------
[2024-05-22 04:14:12,238] {taskinstance.py:1259} INFO - Executing <Task(PythonOperator): fetch_data> on 2024-05-21 09:00:00+00:00
[2024-05-22 04:14:12,255] {standard_task_runner.py:52} INFO - Started process 152 to run task
[2024-05-22 04:14:12,303] {standard_task_runner.py:76} INFO - Running: ['***', 'tasks', 'run', 'purpleair_api_dag', 'fetch_data', 'scheduled__2024-05-21T09:00:00+00:00', '--job-id', '12', '--raw', '--subdir', 'DAGS_FOLDER/data_ingestion.py', '--cfg-path', '/tmp/tmpbysrn_xd', '--error-file', '/tmp/tmpp3gv07h3']
[2024-05-22 04:14:12,396] {standard_task_runner.py:77} INFO - Job 12: Subtask fetch_data
[2024-05-22 04:14:12,898] {logging_mixin.py:109} INFO - Running <TaskInstance: purpleair_api_dag.fetch_data scheduled__2024-05-21T09:00:00+00:00 [running]> on host 3419eee920a5
[2024-05-22 04:14:13,213] {taskinstance.py:1426} INFO - Exporting the following env vars:
AIRFLOW_CTX_DAG_OWNER=***
AIRFLOW_CTX_DAG_ID=purpleair_api_dag
AIRFLOW_CTX_TASK_ID=fetch_data
AIRFLOW_CTX_EXECUTION_DATE=2024-05-21T09:00:00+00:00
AIRFLOW_CTX_DAG_RUN_ID=scheduled__2024-05-21T09:00:00+00:00
[2024-05-22 04:14:13,217] {taskinstance.py:1700} ERROR - Task failed with exception
Traceback (most recent call last):
  File "/home/airflow/.local/lib/python3.6/site-packages/airflow/models/taskinstance.py", line 1329, in _run_raw_task
    self._execute_task_with_callbacks(context)
  File "/home/airflow/.local/lib/python3.6/site-packages/airflow/models/taskinstance.py", line 1455, in _execute_task_with_callbacks
    result = self._execute_task(context, self.task)
  File "/home/airflow/.local/lib/python3.6/site-packages/airflow/models/taskinstance.py", line 1511, in _execute_task
    result = execute_callable(context=context)
  File "/home/airflow/.local/lib/python3.6/site-packages/airflow/operators/python.py", line 174, in execute
    return_value = self.execute_callable()
  File "/home/airflow/.local/lib/python3.6/site-packages/airflow/operators/python.py", line 185, in execute_callable
    return self.python_callable(*self.op_args, **self.op_kwargs)
  File "/opt/airflow/dags/data_ingestion.py", line 67, in api_url
    print(f" url is {url}")
NameError: name 'url' is not defined
[2024-05-22 04:14:13,255] {taskinstance.py:1277} INFO - Marking task as UP_FOR_RETRY. dag_id=purpleair_api_dag, task_id=fetch_data, execution_date=20240521T090000, start_date=20240522T041411, end_date=20240522T041413
[2024-05-22 04:14:13,305] {standard_task_runner.py:92} ERROR - Failed to execute job 12 for task fetch_data
Traceback (most recent call last):
  File "/home/airflow/.local/lib/python3.6/site-packages/airflow/task/task_runner/standard_task_runner.py", line 85, in _start_by_fork
    args.func(args, dag=self.dag)
  File "/home/airflow/.local/lib/python3.6/site-packages/airflow/cli/cli_parser.py", line 48, in command
    return func(*args, **kwargs)
  File "/home/airflow/.local/lib/python3.6/site-packages/airflow/utils/cli.py", line 92, in wrapper
    return f(*args, **kwargs)
  File "/home/airflow/.local/lib/python3.6/site-packages/airflow/cli/commands/task_command.py", line 298, in task_run
    _run_task_by_selected_method(args, dag, ti)
  File "/home/airflow/.local/lib/python3.6/site-packages/airflow/cli/commands/task_command.py", line 107, in _run_task_by_selected_method
    _run_raw_task(args, ti)
  File "/home/airflow/.local/lib/python3.6/site-packages/airflow/cli/commands/task_command.py", line 184, in _run_raw_task
    error_file=args.error_file,
  File "/home/airflow/.local/lib/python3.6/site-packages/airflow/utils/session.py", line 70, in wrapper
    return func(*args, session=session, **kwargs)
  File "/home/airflow/.local/lib/python3.6/site-packages/airflow/models/taskinstance.py", line 1329, in _run_raw_task
    self._execute_task_with_callbacks(context)
  File "/home/airflow/.local/lib/python3.6/site-packages/airflow/models/taskinstance.py", line 1455, in _execute_task_with_callbacks
    result = self._execute_task(context, self.task)
  File "/home/airflow/.local/lib/python3.6/site-packages/airflow/models/taskinstance.py", line 1511, in _execute_task
    result = execute_callable(context=context)
  File "/home/airflow/.local/lib/python3.6/site-packages/airflow/operators/python.py", line 174, in execute
    return_value = self.execute_callable()
  File "/home/airflow/.local/lib/python3.6/site-packages/airflow/operators/python.py", line 185, in execute_callable
    return self.python_callable(*self.op_args, **self.op_kwargs)
  File "/opt/airflow/dags/data_ingestion.py", line 67, in api_url
    print(f" url is {url}")
NameError: name 'url' is not defined
[2024-05-22 04:14:13,352] {local_task_job.py:154} INFO - Task exited with return code 1
[2024-05-22 04:14:13,532] {local_task_job.py:264} INFO - 0 downstream tasks scheduled from follow-on schedule check
[2024-05-22 04:17:38,947] {taskinstance.py:1032} INFO - Dependencies all met for <TaskInstance: purpleair_api_dag.fetch_data scheduled__2024-05-21T09:00:00+00:00 [queued]>
[2024-05-22 04:17:39,008] {taskinstance.py:1032} INFO - Dependencies all met for <TaskInstance: purpleair_api_dag.fetch_data scheduled__2024-05-21T09:00:00+00:00 [queued]>
[2024-05-22 04:17:39,008] {taskinstance.py:1238} INFO - 
--------------------------------------------------------------------------------
[2024-05-22 04:17:39,008] {taskinstance.py:1239} INFO - Starting attempt 1 of 2
[2024-05-22 04:17:39,008] {taskinstance.py:1240} INFO - 
--------------------------------------------------------------------------------
[2024-05-22 04:17:39,093] {taskinstance.py:1259} INFO - Executing <Task(PythonOperator): fetch_data> on 2024-05-21 09:00:00+00:00
[2024-05-22 04:17:39,133] {standard_task_runner.py:52} INFO - Started process 338 to run task
[2024-05-22 04:17:39,171] {standard_task_runner.py:76} INFO - Running: ['***', 'tasks', 'run', 'purpleair_api_dag', 'fetch_data', 'scheduled__2024-05-21T09:00:00+00:00', '--job-id', '29', '--raw', '--subdir', 'DAGS_FOLDER/data_ingestion.py', '--cfg-path', '/tmp/tmpq_rt2fp7', '--error-file', '/tmp/tmph6o9ank4']
[2024-05-22 04:17:39,241] {standard_task_runner.py:77} INFO - Job 29: Subtask fetch_data
[2024-05-22 04:17:39,676] {logging_mixin.py:109} INFO - Running <TaskInstance: purpleair_api_dag.fetch_data scheduled__2024-05-21T09:00:00+00:00 [running]> on host 3419eee920a5
[2024-05-22 04:17:40,029] {taskinstance.py:1426} INFO - Exporting the following env vars:
AIRFLOW_CTX_DAG_OWNER=***
AIRFLOW_CTX_DAG_ID=purpleair_api_dag
AIRFLOW_CTX_TASK_ID=fetch_data
AIRFLOW_CTX_EXECUTION_DATE=2024-05-21T09:00:00+00:00
AIRFLOW_CTX_DAG_RUN_ID=scheduled__2024-05-21T09:00:00+00:00
[2024-05-22 04:17:40,043] {logging_mixin.py:109} INFO -  api is None
[2024-05-22 04:17:40,063] {logging_mixin.py:109} INFO - Full URL: https://api.purpleair.com/v1/sensors?fields=latitude%2Clongitude%2Chumidity%2Cpm2.5_60minute%2Clast_seen&location_type=0&max_age=300
[2024-05-22 04:17:40,063] {logging_mixin.py:109} INFO - Headers: {'X-API-Key': 'None'}
[2024-05-22 04:17:40,214] {logging_mixin.py:109} INFO - Status Code: 403
[2024-05-22 04:17:40,215] {logging_mixin.py:109} INFO - Response Content: {
  "api_version" : "V1.0.13-0.0.56",
  "time_stamp" : 1716351460,
  "error" : "ApiKeyInvalidError",
  "description" : "The provided api_key was not valid."
}
[2024-05-22 04:17:40,306] {logging_mixin.py:109} INFO - Failed to retrieve data: 403
[2024-05-22 04:17:40,307] {python.py:175} INFO - Done. Returned value was: None
[2024-05-22 04:17:40,348] {taskinstance.py:1277} INFO - Marking task as SUCCESS. dag_id=purpleair_api_dag, task_id=fetch_data, execution_date=20240521T090000, start_date=20240522T041738, end_date=20240522T041740
[2024-05-22 04:17:40,452] {local_task_job.py:154} INFO - Task exited with return code 0
[2024-05-22 04:17:40,558] {local_task_job.py:264} INFO - 0 downstream tasks scheduled from follow-on schedule check
