[2024-05-22 06:56:42,643] {taskinstance.py:1032} INFO - Dependencies all met for <TaskInstance: purpleair_api_dag.format_to_parquet_task scheduled__2024-05-21T18:00:00+00:00 [queued]>
[2024-05-22 06:56:42,839] {taskinstance.py:1032} INFO - Dependencies all met for <TaskInstance: purpleair_api_dag.format_to_parquet_task scheduled__2024-05-21T18:00:00+00:00 [queued]>
[2024-05-22 06:56:42,877] {taskinstance.py:1238} INFO - 
--------------------------------------------------------------------------------
[2024-05-22 06:56:42,878] {taskinstance.py:1239} INFO - Starting attempt 1 of 2
[2024-05-22 06:56:42,878] {taskinstance.py:1240} INFO - 
--------------------------------------------------------------------------------
[2024-05-22 06:56:43,075] {taskinstance.py:1259} INFO - Executing <Task(PythonOperator): format_to_parquet_task> on 2024-05-21 18:00:00+00:00
[2024-05-22 06:56:43,190] {standard_task_runner.py:52} INFO - Started process 605 to run task
[2024-05-22 06:56:43,210] {standard_task_runner.py:76} INFO - Running: ['***', 'tasks', 'run', 'purpleair_api_dag', 'format_to_parquet_task', 'scheduled__2024-05-21T18:00:00+00:00', '--job-id', '68', '--raw', '--subdir', 'DAGS_FOLDER/data_ingestion.py', '--cfg-path', '/tmp/tmpd71fgihb', '--error-file', '/tmp/tmp4kha6vdu']
[2024-05-22 06:56:43,313] {standard_task_runner.py:77} INFO - Job 68: Subtask format_to_parquet_task
[2024-05-22 06:56:43,816] {logging_mixin.py:109} INFO - Running <TaskInstance: purpleair_api_dag.format_to_parquet_task scheduled__2024-05-21T18:00:00+00:00 [running]> on host 148b4063f71c
[2024-05-22 06:56:44,045] {warnings.py:99} WARNING - /home/***/.local/lib/python3.6/site-packages/***/utils/context.py:152: AirflowContextDeprecationWarning: Accessing 'execution_date' from the template is deprecated and will be removed in a future version. Please use 'data_interval_start' or 'logical_date' instead.
  warnings.warn(_create_deprecation_warning(key, self._deprecation_replacements[key]))

[2024-05-22 06:56:44,207] {taskinstance.py:1426} INFO - Exporting the following env vars:
AIRFLOW_CTX_DAG_OWNER=***
AIRFLOW_CTX_DAG_ID=purpleair_api_dag
AIRFLOW_CTX_TASK_ID=format_to_parquet_task
AIRFLOW_CTX_EXECUTION_DATE=2024-05-21T18:00:00+00:00
AIRFLOW_CTX_DAG_RUN_ID=scheduled__2024-05-21T18:00:00+00:00
[2024-05-22 06:56:44,211] {taskinstance.py:1700} ERROR - Task failed with exception
Traceback (most recent call last):
  File "/home/airflow/.local/lib/python3.6/site-packages/airflow/models/taskinstance.py", line 1329, in _run_raw_task
    self._execute_task_with_callbacks(context)
  File "/home/airflow/.local/lib/python3.6/site-packages/airflow/models/taskinstance.py", line 1455, in _execute_task_with_callbacks
    result = self._execute_task(context, self.task)
  File "/home/airflow/.local/lib/python3.6/site-packages/airflow/models/taskinstance.py", line 1511, in _execute_task
    result = execute_callable(context=context)
  File "/home/airflow/.local/lib/python3.6/site-packages/airflow/operators/python.py", line 174, in execute
    return_value = self.execute_callable()
  File "/home/airflow/.local/lib/python3.6/site-packages/airflow/operators/python.py", line 185, in execute_callable
    return self.python_callable(*self.op_args, **self.op_kwargs)
  File "/opt/airflow/dags/data_ingestion.py", line 110, in format_to_parquet
    fields = glom(src_file, 'fields')
  File "/home/airflow/.local/lib/python3.6/site-packages/glom/core.py", line 2296, in glom
    raise err
glom.core.PathAccessError: error raised while processing, details below.
 Target-spec trace (most recent last):
 - Target: '/opt/airflow/2024-05-21-18.json'
 - Spec: 'fields'
glom.core.PathAccessError: could not access 'fields', part 0 of Path('fields'), got error: AttributeError("'str' object has no attribute 'fields'",)
[2024-05-22 06:56:44,305] {taskinstance.py:1277} INFO - Marking task as UP_FOR_RETRY. dag_id=purpleair_api_dag, task_id=format_to_parquet_task, execution_date=20240521T180000, start_date=20240522T065642, end_date=20240522T065644
[2024-05-22 06:56:44,470] {standard_task_runner.py:92} ERROR - Failed to execute job 68 for task format_to_parquet_task
Traceback (most recent call last):
  File "/home/airflow/.local/lib/python3.6/site-packages/airflow/task/task_runner/standard_task_runner.py", line 85, in _start_by_fork
    args.func(args, dag=self.dag)
  File "/home/airflow/.local/lib/python3.6/site-packages/airflow/cli/cli_parser.py", line 48, in command
    return func(*args, **kwargs)
  File "/home/airflow/.local/lib/python3.6/site-packages/airflow/utils/cli.py", line 92, in wrapper
    return f(*args, **kwargs)
  File "/home/airflow/.local/lib/python3.6/site-packages/airflow/cli/commands/task_command.py", line 298, in task_run
    _run_task_by_selected_method(args, dag, ti)
  File "/home/airflow/.local/lib/python3.6/site-packages/airflow/cli/commands/task_command.py", line 107, in _run_task_by_selected_method
    _run_raw_task(args, ti)
  File "/home/airflow/.local/lib/python3.6/site-packages/airflow/cli/commands/task_command.py", line 184, in _run_raw_task
    error_file=args.error_file,
  File "/home/airflow/.local/lib/python3.6/site-packages/airflow/utils/session.py", line 70, in wrapper
    return func(*args, session=session, **kwargs)
  File "/home/airflow/.local/lib/python3.6/site-packages/airflow/models/taskinstance.py", line 1329, in _run_raw_task
    self._execute_task_with_callbacks(context)
  File "/home/airflow/.local/lib/python3.6/site-packages/airflow/models/taskinstance.py", line 1455, in _execute_task_with_callbacks
    result = self._execute_task(context, self.task)
  File "/home/airflow/.local/lib/python3.6/site-packages/airflow/models/taskinstance.py", line 1511, in _execute_task
    result = execute_callable(context=context)
  File "/home/airflow/.local/lib/python3.6/site-packages/airflow/operators/python.py", line 174, in execute
    return_value = self.execute_callable()
  File "/home/airflow/.local/lib/python3.6/site-packages/airflow/operators/python.py", line 185, in execute_callable
    return self.python_callable(*self.op_args, **self.op_kwargs)
  File "/opt/airflow/dags/data_ingestion.py", line 110, in format_to_parquet
    fields = glom(src_file, 'fields')
  File "/home/airflow/.local/lib/python3.6/site-packages/glom/core.py", line 2296, in glom
    raise err
glom.core.PathAccessError: error raised while processing, details below.
 Target-spec trace (most recent last):
 - Target: '/opt/airflow/2024-05-21-18.json'
 - Spec: 'fields'
glom.core.PathAccessError: could not access 'fields', part 0 of Path('fields'), got error: AttributeError("'str' object has no attribute 'fields'",)
[2024-05-22 06:56:44,613] {local_task_job.py:154} INFO - Task exited with return code 1
[2024-05-22 06:56:44,697] {local_task_job.py:264} INFO - 0 downstream tasks scheduled from follow-on schedule check
[2024-05-22 07:05:07,384] {taskinstance.py:1032} INFO - Dependencies all met for <TaskInstance: purpleair_api_dag.format_to_parquet_task scheduled__2024-05-21T18:00:00+00:00 [queued]>
[2024-05-22 07:05:07,434] {taskinstance.py:1032} INFO - Dependencies all met for <TaskInstance: purpleair_api_dag.format_to_parquet_task scheduled__2024-05-21T18:00:00+00:00 [queued]>
[2024-05-22 07:05:07,434] {taskinstance.py:1238} INFO - 
--------------------------------------------------------------------------------
[2024-05-22 07:05:07,435] {taskinstance.py:1239} INFO - Starting attempt 1 of 2
[2024-05-22 07:05:07,435] {taskinstance.py:1240} INFO - 
--------------------------------------------------------------------------------
[2024-05-22 07:05:07,489] {taskinstance.py:1259} INFO - Executing <Task(PythonOperator): format_to_parquet_task> on 2024-05-21 18:00:00+00:00
[2024-05-22 07:05:07,507] {standard_task_runner.py:52} INFO - Started process 1154 to run task
[2024-05-22 07:05:07,567] {standard_task_runner.py:76} INFO - Running: ['***', 'tasks', 'run', 'purpleair_api_dag', 'format_to_parquet_task', 'scheduled__2024-05-21T18:00:00+00:00', '--job-id', '146', '--raw', '--subdir', 'DAGS_FOLDER/data_ingestion.py', '--cfg-path', '/tmp/tmpq8h2ev0z', '--error-file', '/tmp/tmp3jioqqsq']
[2024-05-22 07:05:07,598] {standard_task_runner.py:77} INFO - Job 146: Subtask format_to_parquet_task
[2024-05-22 07:05:08,114] {logging_mixin.py:109} INFO - Running <TaskInstance: purpleair_api_dag.format_to_parquet_task scheduled__2024-05-21T18:00:00+00:00 [running]> on host 148b4063f71c
[2024-05-22 07:05:08,582] {warnings.py:99} WARNING - /home/***/.local/lib/python3.6/site-packages/***/utils/context.py:152: AirflowContextDeprecationWarning: Accessing 'execution_date' from the template is deprecated and will be removed in a future version. Please use 'data_interval_start' or 'logical_date' instead.
  warnings.warn(_create_deprecation_warning(key, self._deprecation_replacements[key]))

[2024-05-22 07:05:08,813] {taskinstance.py:1426} INFO - Exporting the following env vars:
AIRFLOW_CTX_DAG_OWNER=***
AIRFLOW_CTX_DAG_ID=purpleair_api_dag
AIRFLOW_CTX_TASK_ID=format_to_parquet_task
AIRFLOW_CTX_EXECUTION_DATE=2024-05-21T18:00:00+00:00
AIRFLOW_CTX_DAG_RUN_ID=scheduled__2024-05-21T18:00:00+00:00
[2024-05-22 07:05:08,842] {taskinstance.py:1700} ERROR - Task failed with exception
Traceback (most recent call last):
  File "/home/airflow/.local/lib/python3.6/site-packages/airflow/models/taskinstance.py", line 1329, in _run_raw_task
    self._execute_task_with_callbacks(context)
  File "/home/airflow/.local/lib/python3.6/site-packages/airflow/models/taskinstance.py", line 1455, in _execute_task_with_callbacks
    result = self._execute_task(context, self.task)
  File "/home/airflow/.local/lib/python3.6/site-packages/airflow/models/taskinstance.py", line 1511, in _execute_task
    result = execute_callable(context=context)
  File "/home/airflow/.local/lib/python3.6/site-packages/airflow/operators/python.py", line 174, in execute
    return_value = self.execute_callable()
  File "/home/airflow/.local/lib/python3.6/site-packages/airflow/operators/python.py", line 185, in execute_callable
    return self.python_callable(*self.op_args, **self.op_kwargs)
  File "/opt/airflow/dags/data_ingestion.py", line 110, in format_to_parquet
    fields = glom(src_file, 'fields')
  File "/home/airflow/.local/lib/python3.6/site-packages/glom/core.py", line 2296, in glom
    raise err
glom.core.PathAccessError: error raised while processing, details below.
 Target-spec trace (most recent last):
 - Target: '/opt/airflow/2024-05-21-18.json'
 - Spec: 'fields'
glom.core.PathAccessError: could not access 'fields', part 0 of Path('fields'), got error: AttributeError("'str' object has no attribute 'fields'",)
[2024-05-22 07:05:09,030] {taskinstance.py:1277} INFO - Marking task as UP_FOR_RETRY. dag_id=purpleair_api_dag, task_id=format_to_parquet_task, execution_date=20240521T180000, start_date=20240522T070507, end_date=20240522T070509
[2024-05-22 07:05:09,191] {standard_task_runner.py:92} ERROR - Failed to execute job 146 for task format_to_parquet_task
Traceback (most recent call last):
  File "/home/airflow/.local/lib/python3.6/site-packages/airflow/task/task_runner/standard_task_runner.py", line 85, in _start_by_fork
    args.func(args, dag=self.dag)
  File "/home/airflow/.local/lib/python3.6/site-packages/airflow/cli/cli_parser.py", line 48, in command
    return func(*args, **kwargs)
  File "/home/airflow/.local/lib/python3.6/site-packages/airflow/utils/cli.py", line 92, in wrapper
    return f(*args, **kwargs)
  File "/home/airflow/.local/lib/python3.6/site-packages/airflow/cli/commands/task_command.py", line 298, in task_run
    _run_task_by_selected_method(args, dag, ti)
  File "/home/airflow/.local/lib/python3.6/site-packages/airflow/cli/commands/task_command.py", line 107, in _run_task_by_selected_method
    _run_raw_task(args, ti)
  File "/home/airflow/.local/lib/python3.6/site-packages/airflow/cli/commands/task_command.py", line 184, in _run_raw_task
    error_file=args.error_file,
  File "/home/airflow/.local/lib/python3.6/site-packages/airflow/utils/session.py", line 70, in wrapper
    return func(*args, session=session, **kwargs)
  File "/home/airflow/.local/lib/python3.6/site-packages/airflow/models/taskinstance.py", line 1329, in _run_raw_task
    self._execute_task_with_callbacks(context)
  File "/home/airflow/.local/lib/python3.6/site-packages/airflow/models/taskinstance.py", line 1455, in _execute_task_with_callbacks
    result = self._execute_task(context, self.task)
  File "/home/airflow/.local/lib/python3.6/site-packages/airflow/models/taskinstance.py", line 1511, in _execute_task
    result = execute_callable(context=context)
  File "/home/airflow/.local/lib/python3.6/site-packages/airflow/operators/python.py", line 174, in execute
    return_value = self.execute_callable()
  File "/home/airflow/.local/lib/python3.6/site-packages/airflow/operators/python.py", line 185, in execute_callable
    return self.python_callable(*self.op_args, **self.op_kwargs)
  File "/opt/airflow/dags/data_ingestion.py", line 110, in format_to_parquet
    fields = glom(src_file, 'fields')
  File "/home/airflow/.local/lib/python3.6/site-packages/glom/core.py", line 2296, in glom
    raise err
glom.core.PathAccessError: error raised while processing, details below.
 Target-spec trace (most recent last):
 - Target: '/opt/airflow/2024-05-21-18.json'
 - Spec: 'fields'
glom.core.PathAccessError: could not access 'fields', part 0 of Path('fields'), got error: AttributeError("'str' object has no attribute 'fields'",)
[2024-05-22 07:05:09,328] {local_task_job.py:154} INFO - Task exited with return code 1
[2024-05-22 07:05:10,071] {local_task_job.py:264} INFO - 0 downstream tasks scheduled from follow-on schedule check
[2024-05-22 07:12:55,038] {taskinstance.py:1032} INFO - Dependencies all met for <TaskInstance: purpleair_api_dag.format_to_parquet_task scheduled__2024-05-21T18:00:00+00:00 [queued]>
[2024-05-22 07:12:55,204] {taskinstance.py:1032} INFO - Dependencies all met for <TaskInstance: purpleair_api_dag.format_to_parquet_task scheduled__2024-05-21T18:00:00+00:00 [queued]>
[2024-05-22 07:12:55,223] {taskinstance.py:1238} INFO - 
--------------------------------------------------------------------------------
[2024-05-22 07:12:55,223] {taskinstance.py:1239} INFO - Starting attempt 1 of 2
[2024-05-22 07:12:55,223] {taskinstance.py:1240} INFO - 
--------------------------------------------------------------------------------
[2024-05-22 07:12:55,485] {taskinstance.py:1259} INFO - Executing <Task(PythonOperator): format_to_parquet_task> on 2024-05-21 18:00:00+00:00
[2024-05-22 07:12:55,495] {standard_task_runner.py:52} INFO - Started process 1679 to run task
[2024-05-22 07:12:55,586] {standard_task_runner.py:76} INFO - Running: ['***', 'tasks', 'run', 'purpleair_api_dag', 'format_to_parquet_task', 'scheduled__2024-05-21T18:00:00+00:00', '--job-id', '222', '--raw', '--subdir', 'DAGS_FOLDER/data_ingestion.py', '--cfg-path', '/tmp/tmpavzf2ugq', '--error-file', '/tmp/tmprvsreqr8']
[2024-05-22 07:12:55,648] {standard_task_runner.py:77} INFO - Job 222: Subtask format_to_parquet_task
[2024-05-22 07:12:56,258] {logging_mixin.py:109} INFO - Running <TaskInstance: purpleair_api_dag.format_to_parquet_task scheduled__2024-05-21T18:00:00+00:00 [running]> on host 148b4063f71c
[2024-05-22 07:12:56,811] {warnings.py:99} WARNING - /home/***/.local/lib/python3.6/site-packages/***/utils/context.py:152: AirflowContextDeprecationWarning: Accessing 'execution_date' from the template is deprecated and will be removed in a future version. Please use 'data_interval_start' or 'logical_date' instead.
  warnings.warn(_create_deprecation_warning(key, self._deprecation_replacements[key]))

[2024-05-22 07:12:56,952] {taskinstance.py:1426} INFO - Exporting the following env vars:
AIRFLOW_CTX_DAG_OWNER=***
AIRFLOW_CTX_DAG_ID=purpleair_api_dag
AIRFLOW_CTX_TASK_ID=format_to_parquet_task
AIRFLOW_CTX_EXECUTION_DATE=2024-05-21T18:00:00+00:00
AIRFLOW_CTX_DAG_RUN_ID=scheduled__2024-05-21T18:00:00+00:00
[2024-05-22 07:12:56,954] {taskinstance.py:1700} ERROR - Task failed with exception
Traceback (most recent call last):
  File "/home/airflow/.local/lib/python3.6/site-packages/airflow/models/taskinstance.py", line 1329, in _run_raw_task
    self._execute_task_with_callbacks(context)
  File "/home/airflow/.local/lib/python3.6/site-packages/airflow/models/taskinstance.py", line 1455, in _execute_task_with_callbacks
    result = self._execute_task(context, self.task)
  File "/home/airflow/.local/lib/python3.6/site-packages/airflow/models/taskinstance.py", line 1511, in _execute_task
    result = execute_callable(context=context)
  File "/home/airflow/.local/lib/python3.6/site-packages/airflow/operators/python.py", line 174, in execute
    return_value = self.execute_callable()
  File "/home/airflow/.local/lib/python3.6/site-packages/airflow/operators/python.py", line 185, in execute_callable
    return self.python_callable(*self.op_args, **self.op_kwargs)
  File "/opt/airflow/dags/data_ingestion.py", line 108, in format_to_parquet
    with open(src_file, 'r') as file:
FileNotFoundError: [Errno 2] No such file or directory: '/opt/airflow/2024-05-21-18.json'
[2024-05-22 07:12:56,999] {taskinstance.py:1277} INFO - Marking task as UP_FOR_RETRY. dag_id=purpleair_api_dag, task_id=format_to_parquet_task, execution_date=20240521T180000, start_date=20240522T071255, end_date=20240522T071256
[2024-05-22 07:12:57,185] {standard_task_runner.py:92} ERROR - Failed to execute job 222 for task format_to_parquet_task
Traceback (most recent call last):
  File "/home/airflow/.local/lib/python3.6/site-packages/airflow/task/task_runner/standard_task_runner.py", line 85, in _start_by_fork
    args.func(args, dag=self.dag)
  File "/home/airflow/.local/lib/python3.6/site-packages/airflow/cli/cli_parser.py", line 48, in command
    return func(*args, **kwargs)
  File "/home/airflow/.local/lib/python3.6/site-packages/airflow/utils/cli.py", line 92, in wrapper
    return f(*args, **kwargs)
  File "/home/airflow/.local/lib/python3.6/site-packages/airflow/cli/commands/task_command.py", line 298, in task_run
    _run_task_by_selected_method(args, dag, ti)
  File "/home/airflow/.local/lib/python3.6/site-packages/airflow/cli/commands/task_command.py", line 107, in _run_task_by_selected_method
    _run_raw_task(args, ti)
  File "/home/airflow/.local/lib/python3.6/site-packages/airflow/cli/commands/task_command.py", line 184, in _run_raw_task
    error_file=args.error_file,
  File "/home/airflow/.local/lib/python3.6/site-packages/airflow/utils/session.py", line 70, in wrapper
    return func(*args, session=session, **kwargs)
  File "/home/airflow/.local/lib/python3.6/site-packages/airflow/models/taskinstance.py", line 1329, in _run_raw_task
    self._execute_task_with_callbacks(context)
  File "/home/airflow/.local/lib/python3.6/site-packages/airflow/models/taskinstance.py", line 1455, in _execute_task_with_callbacks
    result = self._execute_task(context, self.task)
  File "/home/airflow/.local/lib/python3.6/site-packages/airflow/models/taskinstance.py", line 1511, in _execute_task
    result = execute_callable(context=context)
  File "/home/airflow/.local/lib/python3.6/site-packages/airflow/operators/python.py", line 174, in execute
    return_value = self.execute_callable()
  File "/home/airflow/.local/lib/python3.6/site-packages/airflow/operators/python.py", line 185, in execute_callable
    return self.python_callable(*self.op_args, **self.op_kwargs)
  File "/opt/airflow/dags/data_ingestion.py", line 108, in format_to_parquet
    with open(src_file, 'r') as file:
FileNotFoundError: [Errno 2] No such file or directory: '/opt/airflow/2024-05-21-18.json'
[2024-05-22 07:12:57,344] {local_task_job.py:154} INFO - Task exited with return code 1
[2024-05-22 07:12:57,673] {local_task_job.py:264} INFO - 0 downstream tasks scheduled from follow-on schedule check
[2024-05-22 07:22:41,648] {taskinstance.py:1032} INFO - Dependencies all met for <TaskInstance: purpleair_api_dag.format_to_parquet_task scheduled__2024-05-21T18:00:00+00:00 [queued]>
[2024-05-22 07:22:41,798] {taskinstance.py:1032} INFO - Dependencies all met for <TaskInstance: purpleair_api_dag.format_to_parquet_task scheduled__2024-05-21T18:00:00+00:00 [queued]>
[2024-05-22 07:22:41,798] {taskinstance.py:1238} INFO - 
--------------------------------------------------------------------------------
[2024-05-22 07:22:41,798] {taskinstance.py:1239} INFO - Starting attempt 1 of 2
[2024-05-22 07:22:41,798] {taskinstance.py:1240} INFO - 
--------------------------------------------------------------------------------
[2024-05-22 07:22:41,928] {taskinstance.py:1259} INFO - Executing <Task(PythonOperator): format_to_parquet_task> on 2024-05-21 18:00:00+00:00
[2024-05-22 07:22:42,001] {standard_task_runner.py:52} INFO - Started process 2393 to run task
[2024-05-22 07:22:42,053] {standard_task_runner.py:76} INFO - Running: ['***', 'tasks', 'run', 'purpleair_api_dag', 'format_to_parquet_task', 'scheduled__2024-05-21T18:00:00+00:00', '--job-id', '339', '--raw', '--subdir', 'DAGS_FOLDER/data_ingestion.py', '--cfg-path', '/tmp/tmp7ecqm8td', '--error-file', '/tmp/tmp2ntfwz3n']
[2024-05-22 07:22:42,116] {standard_task_runner.py:77} INFO - Job 339: Subtask format_to_parquet_task
[2024-05-22 07:22:42,776] {logging_mixin.py:109} INFO - Running <TaskInstance: purpleair_api_dag.format_to_parquet_task scheduled__2024-05-21T18:00:00+00:00 [running]> on host 148b4063f71c
[2024-05-22 07:22:43,029] {warnings.py:99} WARNING - /home/***/.local/lib/python3.6/site-packages/***/utils/context.py:152: AirflowContextDeprecationWarning: Accessing 'execution_date' from the template is deprecated and will be removed in a future version. Please use 'data_interval_start' or 'logical_date' instead.
  warnings.warn(_create_deprecation_warning(key, self._deprecation_replacements[key]))

[2024-05-22 07:22:43,294] {taskinstance.py:1426} INFO - Exporting the following env vars:
AIRFLOW_CTX_DAG_OWNER=***
AIRFLOW_CTX_DAG_ID=purpleair_api_dag
AIRFLOW_CTX_TASK_ID=format_to_parquet_task
AIRFLOW_CTX_EXECUTION_DATE=2024-05-21T18:00:00+00:00
AIRFLOW_CTX_DAG_RUN_ID=scheduled__2024-05-21T18:00:00+00:00
[2024-05-22 07:22:43,315] {taskinstance.py:1700} ERROR - Task failed with exception
Traceback (most recent call last):
  File "/home/airflow/.local/lib/python3.6/site-packages/airflow/models/taskinstance.py", line 1329, in _run_raw_task
    self._execute_task_with_callbacks(context)
  File "/home/airflow/.local/lib/python3.6/site-packages/airflow/models/taskinstance.py", line 1455, in _execute_task_with_callbacks
    result = self._execute_task(context, self.task)
  File "/home/airflow/.local/lib/python3.6/site-packages/airflow/models/taskinstance.py", line 1511, in _execute_task
    result = execute_callable(context=context)
  File "/home/airflow/.local/lib/python3.6/site-packages/airflow/operators/python.py", line 174, in execute
    return_value = self.execute_callable()
  File "/home/airflow/.local/lib/python3.6/site-packages/airflow/operators/python.py", line 185, in execute_callable
    return self.python_callable(*self.op_args, **self.op_kwargs)
  File "/opt/airflow/dags/data_ingestion.py", line 108, in format_to_parquet
    with open(src_file, 'r') as file:
FileNotFoundError: [Errno 2] No such file or directory: '/opt/airflow/2024-05-21-18.json'
[2024-05-22 07:22:43,454] {taskinstance.py:1277} INFO - Marking task as UP_FOR_RETRY. dag_id=purpleair_api_dag, task_id=format_to_parquet_task, execution_date=20240521T180000, start_date=20240522T072241, end_date=20240522T072243
[2024-05-22 07:22:43,545] {standard_task_runner.py:92} ERROR - Failed to execute job 339 for task format_to_parquet_task
Traceback (most recent call last):
  File "/home/airflow/.local/lib/python3.6/site-packages/airflow/task/task_runner/standard_task_runner.py", line 85, in _start_by_fork
    args.func(args, dag=self.dag)
  File "/home/airflow/.local/lib/python3.6/site-packages/airflow/cli/cli_parser.py", line 48, in command
    return func(*args, **kwargs)
  File "/home/airflow/.local/lib/python3.6/site-packages/airflow/utils/cli.py", line 92, in wrapper
    return f(*args, **kwargs)
  File "/home/airflow/.local/lib/python3.6/site-packages/airflow/cli/commands/task_command.py", line 298, in task_run
    _run_task_by_selected_method(args, dag, ti)
  File "/home/airflow/.local/lib/python3.6/site-packages/airflow/cli/commands/task_command.py", line 107, in _run_task_by_selected_method
    _run_raw_task(args, ti)
  File "/home/airflow/.local/lib/python3.6/site-packages/airflow/cli/commands/task_command.py", line 184, in _run_raw_task
    error_file=args.error_file,
  File "/home/airflow/.local/lib/python3.6/site-packages/airflow/utils/session.py", line 70, in wrapper
    return func(*args, session=session, **kwargs)
  File "/home/airflow/.local/lib/python3.6/site-packages/airflow/models/taskinstance.py", line 1329, in _run_raw_task
    self._execute_task_with_callbacks(context)
  File "/home/airflow/.local/lib/python3.6/site-packages/airflow/models/taskinstance.py", line 1455, in _execute_task_with_callbacks
    result = self._execute_task(context, self.task)
  File "/home/airflow/.local/lib/python3.6/site-packages/airflow/models/taskinstance.py", line 1511, in _execute_task
    result = execute_callable(context=context)
  File "/home/airflow/.local/lib/python3.6/site-packages/airflow/operators/python.py", line 174, in execute
    return_value = self.execute_callable()
  File "/home/airflow/.local/lib/python3.6/site-packages/airflow/operators/python.py", line 185, in execute_callable
    return self.python_callable(*self.op_args, **self.op_kwargs)
  File "/opt/airflow/dags/data_ingestion.py", line 108, in format_to_parquet
    with open(src_file, 'r') as file:
FileNotFoundError: [Errno 2] No such file or directory: '/opt/airflow/2024-05-21-18.json'
[2024-05-22 07:22:43,705] {local_task_job.py:154} INFO - Task exited with return code 1
[2024-05-22 07:22:44,011] {local_task_job.py:264} INFO - 0 downstream tasks scheduled from follow-on schedule check
