[2024-05-22 02:32:58,305] {taskinstance.py:1032} INFO - Dependencies all met for <TaskInstance: purpleair_api_dag.fetch_data manual__2024-05-22T02:32:56.664722+00:00 [queued]>
[2024-05-22 02:32:58,323] {taskinstance.py:1032} INFO - Dependencies all met for <TaskInstance: purpleair_api_dag.fetch_data manual__2024-05-22T02:32:56.664722+00:00 [queued]>
[2024-05-22 02:32:58,323] {taskinstance.py:1238} INFO - 
--------------------------------------------------------------------------------
[2024-05-22 02:32:58,324] {taskinstance.py:1239} INFO - Starting attempt 1 of 2
[2024-05-22 02:32:58,324] {taskinstance.py:1240} INFO - 
--------------------------------------------------------------------------------
[2024-05-22 02:32:58,339] {taskinstance.py:1259} INFO - Executing <Task(PythonOperator): fetch_data> on 2024-05-22 02:32:56.664722+00:00
[2024-05-22 02:32:58,347] {standard_task_runner.py:52} INFO - Started process 2951 to run task
[2024-05-22 02:32:58,354] {standard_task_runner.py:76} INFO - Running: ['***', 'tasks', 'run', 'purpleair_api_dag', 'fetch_data', 'manual__2024-05-22T02:32:56.664722+00:00', '--job-id', '30', '--raw', '--subdir', 'DAGS_FOLDER/data_ingestion.py', '--cfg-path', '/tmp/tmptwbocw52', '--error-file', '/tmp/tmpqq1sqk14']
[2024-05-22 02:32:58,363] {standard_task_runner.py:77} INFO - Job 30: Subtask fetch_data
[2024-05-22 02:32:58,446] {logging_mixin.py:109} INFO - Running <TaskInstance: purpleair_api_dag.fetch_data manual__2024-05-22T02:32:56.664722+00:00 [running]> on host 8fe6997c1526
[2024-05-22 02:32:58,522] {taskinstance.py:1426} INFO - Exporting the following env vars:
AIRFLOW_CTX_DAG_OWNER=***
AIRFLOW_CTX_DAG_ID=purpleair_api_dag
AIRFLOW_CTX_TASK_ID=fetch_data
AIRFLOW_CTX_EXECUTION_DATE=2024-05-22T02:32:56.664722+00:00
AIRFLOW_CTX_DAG_RUN_ID=manual__2024-05-22T02:32:56.664722+00:00
[2024-05-22 02:32:58,527] {taskinstance.py:1700} ERROR - Task failed with exception
Traceback (most recent call last):
  File "/home/airflow/.local/lib/python3.6/site-packages/requests/utils.py", line 977, in check_header_validity
    if not pat.match(value):
TypeError: expected string or bytes-like object

During handling of the above exception, another exception occurred:

Traceback (most recent call last):
  File "/home/airflow/.local/lib/python3.6/site-packages/airflow/models/taskinstance.py", line 1329, in _run_raw_task
    self._execute_task_with_callbacks(context)
  File "/home/airflow/.local/lib/python3.6/site-packages/airflow/models/taskinstance.py", line 1455, in _execute_task_with_callbacks
    result = self._execute_task(context, self.task)
  File "/home/airflow/.local/lib/python3.6/site-packages/airflow/models/taskinstance.py", line 1511, in _execute_task
    result = execute_callable(context=context)
  File "/home/airflow/.local/lib/python3.6/site-packages/airflow/operators/python.py", line 174, in execute
    return_value = self.execute_callable()
  File "/home/airflow/.local/lib/python3.6/site-packages/airflow/operators/python.py", line 185, in execute_callable
    return self.python_callable(*self.op_args, **self.op_kwargs)
  File "/opt/airflow/dags/data_ingestion.py", line 76, in api_url
    prepared = req.prepare()
  File "/home/airflow/.local/lib/python3.6/site-packages/requests/models.py", line 267, in prepare
    hooks=self.hooks,
  File "/home/airflow/.local/lib/python3.6/site-packages/requests/models.py", line 317, in prepare
    self.prepare_headers(headers)
  File "/home/airflow/.local/lib/python3.6/site-packages/requests/models.py", line 451, in prepare_headers
    check_header_validity(header)
  File "/home/airflow/.local/lib/python3.6/site-packages/requests/utils.py", line 981, in check_header_validity
    "bytes, not %s" % (name, value, type(value)))
requests.exceptions.InvalidHeader: Value for header {X-API-Key: None} must be of type str or bytes, not <class 'NoneType'>
[2024-05-22 02:32:58,543] {taskinstance.py:1277} INFO - Marking task as UP_FOR_RETRY. dag_id=purpleair_api_dag, task_id=fetch_data, execution_date=20240522T023256, start_date=20240522T023258, end_date=20240522T023258
[2024-05-22 02:32:58,559] {standard_task_runner.py:92} ERROR - Failed to execute job 30 for task fetch_data
Traceback (most recent call last):
  File "/home/airflow/.local/lib/python3.6/site-packages/requests/utils.py", line 977, in check_header_validity
    if not pat.match(value):
TypeError: expected string or bytes-like object

During handling of the above exception, another exception occurred:

Traceback (most recent call last):
  File "/home/airflow/.local/lib/python3.6/site-packages/airflow/task/task_runner/standard_task_runner.py", line 85, in _start_by_fork
    args.func(args, dag=self.dag)
  File "/home/airflow/.local/lib/python3.6/site-packages/airflow/cli/cli_parser.py", line 48, in command
    return func(*args, **kwargs)
  File "/home/airflow/.local/lib/python3.6/site-packages/airflow/utils/cli.py", line 92, in wrapper
    return f(*args, **kwargs)
  File "/home/airflow/.local/lib/python3.6/site-packages/airflow/cli/commands/task_command.py", line 298, in task_run
    _run_task_by_selected_method(args, dag, ti)
  File "/home/airflow/.local/lib/python3.6/site-packages/airflow/cli/commands/task_command.py", line 107, in _run_task_by_selected_method
    _run_raw_task(args, ti)
  File "/home/airflow/.local/lib/python3.6/site-packages/airflow/cli/commands/task_command.py", line 184, in _run_raw_task
    error_file=args.error_file,
  File "/home/airflow/.local/lib/python3.6/site-packages/airflow/utils/session.py", line 70, in wrapper
    return func(*args, session=session, **kwargs)
  File "/home/airflow/.local/lib/python3.6/site-packages/airflow/models/taskinstance.py", line 1329, in _run_raw_task
    self._execute_task_with_callbacks(context)
  File "/home/airflow/.local/lib/python3.6/site-packages/airflow/models/taskinstance.py", line 1455, in _execute_task_with_callbacks
    result = self._execute_task(context, self.task)
  File "/home/airflow/.local/lib/python3.6/site-packages/airflow/models/taskinstance.py", line 1511, in _execute_task
    result = execute_callable(context=context)
  File "/home/airflow/.local/lib/python3.6/site-packages/airflow/operators/python.py", line 174, in execute
    return_value = self.execute_callable()
  File "/home/airflow/.local/lib/python3.6/site-packages/airflow/operators/python.py", line 185, in execute_callable
    return self.python_callable(*self.op_args, **self.op_kwargs)
  File "/opt/airflow/dags/data_ingestion.py", line 76, in api_url
    prepared = req.prepare()
  File "/home/airflow/.local/lib/python3.6/site-packages/requests/models.py", line 267, in prepare
    hooks=self.hooks,
  File "/home/airflow/.local/lib/python3.6/site-packages/requests/models.py", line 317, in prepare
    self.prepare_headers(headers)
  File "/home/airflow/.local/lib/python3.6/site-packages/requests/models.py", line 451, in prepare_headers
    check_header_validity(header)
  File "/home/airflow/.local/lib/python3.6/site-packages/requests/utils.py", line 981, in check_header_validity
    "bytes, not %s" % (name, value, type(value)))
requests.exceptions.InvalidHeader: Value for header {X-API-Key: None} must be of type str or bytes, not <class 'NoneType'>
[2024-05-22 02:32:58,605] {local_task_job.py:154} INFO - Task exited with return code 1
[2024-05-22 02:32:58,648] {local_task_job.py:264} INFO - 0 downstream tasks scheduled from follow-on schedule check
