[2024-05-22 06:50:35,158] {taskinstance.py:1032} INFO - Dependencies all met for <TaskInstance: purpleair_api_dag.format_to_parquet_task scheduled__2024-05-21T01:00:00+00:00 [queued]>
[2024-05-22 06:50:35,276] {taskinstance.py:1032} INFO - Dependencies all met for <TaskInstance: purpleair_api_dag.format_to_parquet_task scheduled__2024-05-21T01:00:00+00:00 [queued]>
[2024-05-22 06:50:35,278] {taskinstance.py:1238} INFO - 
--------------------------------------------------------------------------------
[2024-05-22 06:50:35,279] {taskinstance.py:1239} INFO - Starting attempt 1 of 2
[2024-05-22 06:50:35,284] {taskinstance.py:1240} INFO - 
--------------------------------------------------------------------------------
[2024-05-22 06:50:35,387] {taskinstance.py:1259} INFO - Executing <Task(PythonOperator): format_to_parquet_task> on 2024-05-21 01:00:00+00:00
[2024-05-22 06:50:35,446] {standard_task_runner.py:52} INFO - Started process 257 to run task
[2024-05-22 06:50:35,434] {standard_task_runner.py:76} INFO - Running: ['***', 'tasks', 'run', 'purpleair_api_dag', 'format_to_parquet_task', 'scheduled__2024-05-21T01:00:00+00:00', '--job-id', '31', '--raw', '--subdir', 'DAGS_FOLDER/data_ingestion.py', '--cfg-path', '/tmp/tmpalti3g3v', '--error-file', '/tmp/tmpn01tcbkg']
[2024-05-22 06:50:35,502] {standard_task_runner.py:77} INFO - Job 31: Subtask format_to_parquet_task
[2024-05-22 06:50:35,879] {logging_mixin.py:109} INFO - Running <TaskInstance: purpleair_api_dag.format_to_parquet_task scheduled__2024-05-21T01:00:00+00:00 [running]> on host 148b4063f71c
[2024-05-22 06:50:35,990] {warnings.py:99} WARNING - /home/***/.local/lib/python3.6/site-packages/***/utils/context.py:152: AirflowContextDeprecationWarning: Accessing 'execution_date' from the template is deprecated and will be removed in a future version. Please use 'data_interval_start' or 'logical_date' instead.
  warnings.warn(_create_deprecation_warning(key, self._deprecation_replacements[key]))

[2024-05-22 06:50:36,077] {taskinstance.py:1426} INFO - Exporting the following env vars:
AIRFLOW_CTX_DAG_OWNER=***
AIRFLOW_CTX_DAG_ID=purpleair_api_dag
AIRFLOW_CTX_TASK_ID=format_to_parquet_task
AIRFLOW_CTX_EXECUTION_DATE=2024-05-21T01:00:00+00:00
AIRFLOW_CTX_DAG_RUN_ID=scheduled__2024-05-21T01:00:00+00:00
[2024-05-22 06:50:36,081] {taskinstance.py:1700} ERROR - Task failed with exception
Traceback (most recent call last):
  File "/home/airflow/.local/lib/python3.6/site-packages/airflow/models/taskinstance.py", line 1329, in _run_raw_task
    self._execute_task_with_callbacks(context)
  File "/home/airflow/.local/lib/python3.6/site-packages/airflow/models/taskinstance.py", line 1455, in _execute_task_with_callbacks
    result = self._execute_task(context, self.task)
  File "/home/airflow/.local/lib/python3.6/site-packages/airflow/models/taskinstance.py", line 1511, in _execute_task
    result = execute_callable(context=context)
  File "/home/airflow/.local/lib/python3.6/site-packages/airflow/operators/python.py", line 174, in execute
    return_value = self.execute_callable()
  File "/home/airflow/.local/lib/python3.6/site-packages/airflow/operators/python.py", line 185, in execute_callable
    return self.python_callable(*self.op_args, **self.op_kwargs)
  File "/opt/airflow/dags/data_ingestion.py", line 110, in format_to_parquet
    fields = glom(src_file, 'fields')
TypeError: 'module' object is not callable
[2024-05-22 06:50:36,121] {taskinstance.py:1277} INFO - Marking task as UP_FOR_RETRY. dag_id=purpleair_api_dag, task_id=format_to_parquet_task, execution_date=20240521T010000, start_date=20240522T065035, end_date=20240522T065036
[2024-05-22 06:50:36,170] {standard_task_runner.py:92} ERROR - Failed to execute job 31 for task format_to_parquet_task
Traceback (most recent call last):
  File "/home/airflow/.local/lib/python3.6/site-packages/airflow/task/task_runner/standard_task_runner.py", line 85, in _start_by_fork
    args.func(args, dag=self.dag)
  File "/home/airflow/.local/lib/python3.6/site-packages/airflow/cli/cli_parser.py", line 48, in command
    return func(*args, **kwargs)
  File "/home/airflow/.local/lib/python3.6/site-packages/airflow/utils/cli.py", line 92, in wrapper
    return f(*args, **kwargs)
  File "/home/airflow/.local/lib/python3.6/site-packages/airflow/cli/commands/task_command.py", line 298, in task_run
    _run_task_by_selected_method(args, dag, ti)
  File "/home/airflow/.local/lib/python3.6/site-packages/airflow/cli/commands/task_command.py", line 107, in _run_task_by_selected_method
    _run_raw_task(args, ti)
  File "/home/airflow/.local/lib/python3.6/site-packages/airflow/cli/commands/task_command.py", line 184, in _run_raw_task
    error_file=args.error_file,
  File "/home/airflow/.local/lib/python3.6/site-packages/airflow/utils/session.py", line 70, in wrapper
    return func(*args, session=session, **kwargs)
  File "/home/airflow/.local/lib/python3.6/site-packages/airflow/models/taskinstance.py", line 1329, in _run_raw_task
    self._execute_task_with_callbacks(context)
  File "/home/airflow/.local/lib/python3.6/site-packages/airflow/models/taskinstance.py", line 1455, in _execute_task_with_callbacks
    result = self._execute_task(context, self.task)
  File "/home/airflow/.local/lib/python3.6/site-packages/airflow/models/taskinstance.py", line 1511, in _execute_task
    result = execute_callable(context=context)
  File "/home/airflow/.local/lib/python3.6/site-packages/airflow/operators/python.py", line 174, in execute
    return_value = self.execute_callable()
  File "/home/airflow/.local/lib/python3.6/site-packages/airflow/operators/python.py", line 185, in execute_callable
    return self.python_callable(*self.op_args, **self.op_kwargs)
  File "/opt/airflow/dags/data_ingestion.py", line 110, in format_to_parquet
    fields = glom(src_file, 'fields')
TypeError: 'module' object is not callable
[2024-05-22 06:50:36,220] {local_task_job.py:154} INFO - Task exited with return code 1
[2024-05-22 06:50:36,369] {local_task_job.py:264} INFO - 0 downstream tasks scheduled from follow-on schedule check
[2024-05-22 06:59:13,436] {taskinstance.py:1032} INFO - Dependencies all met for <TaskInstance: purpleair_api_dag.format_to_parquet_task scheduled__2024-05-21T01:00:00+00:00 [queued]>
[2024-05-22 06:59:13,678] {taskinstance.py:1032} INFO - Dependencies all met for <TaskInstance: purpleair_api_dag.format_to_parquet_task scheduled__2024-05-21T01:00:00+00:00 [queued]>
[2024-05-22 06:59:13,692] {taskinstance.py:1238} INFO - 
--------------------------------------------------------------------------------
[2024-05-22 06:59:13,693] {taskinstance.py:1239} INFO - Starting attempt 1 of 2
[2024-05-22 06:59:13,693] {taskinstance.py:1240} INFO - 
--------------------------------------------------------------------------------
[2024-05-22 06:59:13,778] {taskinstance.py:1259} INFO - Executing <Task(PythonOperator): format_to_parquet_task> on 2024-05-21 01:00:00+00:00
[2024-05-22 06:59:13,916] {standard_task_runner.py:52} INFO - Started process 790 to run task
[2024-05-22 06:59:13,951] {standard_task_runner.py:76} INFO - Running: ['***', 'tasks', 'run', 'purpleair_api_dag', 'format_to_parquet_task', 'scheduled__2024-05-21T01:00:00+00:00', '--job-id', '98', '--raw', '--subdir', 'DAGS_FOLDER/data_ingestion.py', '--cfg-path', '/tmp/tmpe106cd66', '--error-file', '/tmp/tmp3y5jtd1r']
[2024-05-22 06:59:14,113] {standard_task_runner.py:77} INFO - Job 98: Subtask format_to_parquet_task
[2024-05-22 06:59:14,861] {logging_mixin.py:109} INFO - Running <TaskInstance: purpleair_api_dag.format_to_parquet_task scheduled__2024-05-21T01:00:00+00:00 [running]> on host 148b4063f71c
[2024-05-22 06:59:15,467] {warnings.py:99} WARNING - /home/***/.local/lib/python3.6/site-packages/***/utils/context.py:152: AirflowContextDeprecationWarning: Accessing 'execution_date' from the template is deprecated and will be removed in a future version. Please use 'data_interval_start' or 'logical_date' instead.
  warnings.warn(_create_deprecation_warning(key, self._deprecation_replacements[key]))

[2024-05-22 06:59:15,744] {taskinstance.py:1426} INFO - Exporting the following env vars:
AIRFLOW_CTX_DAG_OWNER=***
AIRFLOW_CTX_DAG_ID=purpleair_api_dag
AIRFLOW_CTX_TASK_ID=format_to_parquet_task
AIRFLOW_CTX_EXECUTION_DATE=2024-05-21T01:00:00+00:00
AIRFLOW_CTX_DAG_RUN_ID=scheduled__2024-05-21T01:00:00+00:00
[2024-05-22 06:59:15,750] {taskinstance.py:1700} ERROR - Task failed with exception
Traceback (most recent call last):
  File "/home/airflow/.local/lib/python3.6/site-packages/airflow/models/taskinstance.py", line 1329, in _run_raw_task
    self._execute_task_with_callbacks(context)
  File "/home/airflow/.local/lib/python3.6/site-packages/airflow/models/taskinstance.py", line 1455, in _execute_task_with_callbacks
    result = self._execute_task(context, self.task)
  File "/home/airflow/.local/lib/python3.6/site-packages/airflow/models/taskinstance.py", line 1511, in _execute_task
    result = execute_callable(context=context)
  File "/home/airflow/.local/lib/python3.6/site-packages/airflow/operators/python.py", line 174, in execute
    return_value = self.execute_callable()
  File "/home/airflow/.local/lib/python3.6/site-packages/airflow/operators/python.py", line 185, in execute_callable
    return self.python_callable(*self.op_args, **self.op_kwargs)
  File "/opt/airflow/dags/data_ingestion.py", line 110, in format_to_parquet
    fields = glom(src_file, 'fields')
  File "/home/airflow/.local/lib/python3.6/site-packages/glom/core.py", line 2296, in glom
    raise err
glom.core.PathAccessError: error raised while processing, details below.
 Target-spec trace (most recent last):
 - Target: '/opt/airflow/2024-05-21-1.json'
 - Spec: 'fields'
glom.core.PathAccessError: could not access 'fields', part 0 of Path('fields'), got error: AttributeError("'str' object has no attribute 'fields'",)
[2024-05-22 06:59:15,861] {taskinstance.py:1277} INFO - Marking task as UP_FOR_RETRY. dag_id=purpleair_api_dag, task_id=format_to_parquet_task, execution_date=20240521T010000, start_date=20240522T065913, end_date=20240522T065915
[2024-05-22 06:59:16,298] {standard_task_runner.py:92} ERROR - Failed to execute job 98 for task format_to_parquet_task
Traceback (most recent call last):
  File "/home/airflow/.local/lib/python3.6/site-packages/airflow/task/task_runner/standard_task_runner.py", line 85, in _start_by_fork
    args.func(args, dag=self.dag)
  File "/home/airflow/.local/lib/python3.6/site-packages/airflow/cli/cli_parser.py", line 48, in command
    return func(*args, **kwargs)
  File "/home/airflow/.local/lib/python3.6/site-packages/airflow/utils/cli.py", line 92, in wrapper
    return f(*args, **kwargs)
  File "/home/airflow/.local/lib/python3.6/site-packages/airflow/cli/commands/task_command.py", line 298, in task_run
    _run_task_by_selected_method(args, dag, ti)
  File "/home/airflow/.local/lib/python3.6/site-packages/airflow/cli/commands/task_command.py", line 107, in _run_task_by_selected_method
    _run_raw_task(args, ti)
  File "/home/airflow/.local/lib/python3.6/site-packages/airflow/cli/commands/task_command.py", line 184, in _run_raw_task
    error_file=args.error_file,
  File "/home/airflow/.local/lib/python3.6/site-packages/airflow/utils/session.py", line 70, in wrapper
    return func(*args, session=session, **kwargs)
  File "/home/airflow/.local/lib/python3.6/site-packages/airflow/models/taskinstance.py", line 1329, in _run_raw_task
    self._execute_task_with_callbacks(context)
  File "/home/airflow/.local/lib/python3.6/site-packages/airflow/models/taskinstance.py", line 1455, in _execute_task_with_callbacks
    result = self._execute_task(context, self.task)
  File "/home/airflow/.local/lib/python3.6/site-packages/airflow/models/taskinstance.py", line 1511, in _execute_task
    result = execute_callable(context=context)
  File "/home/airflow/.local/lib/python3.6/site-packages/airflow/operators/python.py", line 174, in execute
    return_value = self.execute_callable()
  File "/home/airflow/.local/lib/python3.6/site-packages/airflow/operators/python.py", line 185, in execute_callable
    return self.python_callable(*self.op_args, **self.op_kwargs)
  File "/opt/airflow/dags/data_ingestion.py", line 110, in format_to_parquet
    fields = glom(src_file, 'fields')
  File "/home/airflow/.local/lib/python3.6/site-packages/glom/core.py", line 2296, in glom
    raise err
glom.core.PathAccessError: error raised while processing, details below.
 Target-spec trace (most recent last):
 - Target: '/opt/airflow/2024-05-21-1.json'
 - Spec: 'fields'
glom.core.PathAccessError: could not access 'fields', part 0 of Path('fields'), got error: AttributeError("'str' object has no attribute 'fields'",)
[2024-05-22 06:59:16,403] {local_task_job.py:154} INFO - Task exited with return code 1
[2024-05-22 06:59:16,543] {local_task_job.py:264} INFO - 0 downstream tasks scheduled from follow-on schedule check
[2024-05-22 07:06:59,195] {taskinstance.py:1032} INFO - Dependencies all met for <TaskInstance: purpleair_api_dag.format_to_parquet_task scheduled__2024-05-21T01:00:00+00:00 [queued]>
[2024-05-22 07:06:59,338] {taskinstance.py:1032} INFO - Dependencies all met for <TaskInstance: purpleair_api_dag.format_to_parquet_task scheduled__2024-05-21T01:00:00+00:00 [queued]>
[2024-05-22 07:06:59,356] {taskinstance.py:1238} INFO - 
--------------------------------------------------------------------------------
[2024-05-22 07:06:59,357] {taskinstance.py:1239} INFO - Starting attempt 1 of 2
[2024-05-22 07:06:59,357] {taskinstance.py:1240} INFO - 
--------------------------------------------------------------------------------
[2024-05-22 07:06:59,515] {taskinstance.py:1259} INFO - Executing <Task(PythonOperator): format_to_parquet_task> on 2024-05-21 01:00:00+00:00
[2024-05-22 07:06:59,571] {standard_task_runner.py:52} INFO - Started process 1320 to run task
[2024-05-22 07:06:59,647] {standard_task_runner.py:76} INFO - Running: ['***', 'tasks', 'run', 'purpleair_api_dag', 'format_to_parquet_task', 'scheduled__2024-05-21T01:00:00+00:00', '--job-id', '178', '--raw', '--subdir', 'DAGS_FOLDER/data_ingestion.py', '--cfg-path', '/tmp/tmpymda80az', '--error-file', '/tmp/tmpvgfo0t5z']
[2024-05-22 07:06:59,765] {standard_task_runner.py:77} INFO - Job 178: Subtask format_to_parquet_task
[2024-05-22 07:07:00,534] {logging_mixin.py:109} INFO - Running <TaskInstance: purpleair_api_dag.format_to_parquet_task scheduled__2024-05-21T01:00:00+00:00 [running]> on host 148b4063f71c
[2024-05-22 07:07:00,739] {warnings.py:99} WARNING - /home/***/.local/lib/python3.6/site-packages/***/utils/context.py:152: AirflowContextDeprecationWarning: Accessing 'execution_date' from the template is deprecated and will be removed in a future version. Please use 'data_interval_start' or 'logical_date' instead.
  warnings.warn(_create_deprecation_warning(key, self._deprecation_replacements[key]))

[2024-05-22 07:07:00,973] {taskinstance.py:1426} INFO - Exporting the following env vars:
AIRFLOW_CTX_DAG_OWNER=***
AIRFLOW_CTX_DAG_ID=purpleair_api_dag
AIRFLOW_CTX_TASK_ID=format_to_parquet_task
AIRFLOW_CTX_EXECUTION_DATE=2024-05-21T01:00:00+00:00
AIRFLOW_CTX_DAG_RUN_ID=scheduled__2024-05-21T01:00:00+00:00
[2024-05-22 07:07:00,977] {taskinstance.py:1700} ERROR - Task failed with exception
Traceback (most recent call last):
  File "/home/airflow/.local/lib/python3.6/site-packages/airflow/models/taskinstance.py", line 1329, in _run_raw_task
    self._execute_task_with_callbacks(context)
  File "/home/airflow/.local/lib/python3.6/site-packages/airflow/models/taskinstance.py", line 1455, in _execute_task_with_callbacks
    result = self._execute_task(context, self.task)
  File "/home/airflow/.local/lib/python3.6/site-packages/airflow/models/taskinstance.py", line 1511, in _execute_task
    result = execute_callable(context=context)
  File "/home/airflow/.local/lib/python3.6/site-packages/airflow/operators/python.py", line 174, in execute
    return_value = self.execute_callable()
  File "/home/airflow/.local/lib/python3.6/site-packages/airflow/operators/python.py", line 185, in execute_callable
    return self.python_callable(*self.op_args, **self.op_kwargs)
  File "/opt/airflow/dags/data_ingestion.py", line 108, in format_to_parquet
    with open(src_file, 'r') as file:
FileNotFoundError: [Errno 2] No such file or directory: '/opt/airflow/2024-05-21-1.json'
[2024-05-22 07:07:01,075] {taskinstance.py:1277} INFO - Marking task as UP_FOR_RETRY. dag_id=purpleair_api_dag, task_id=format_to_parquet_task, execution_date=20240521T010000, start_date=20240522T070659, end_date=20240522T070701
[2024-05-22 07:07:01,228] {standard_task_runner.py:92} ERROR - Failed to execute job 178 for task format_to_parquet_task
Traceback (most recent call last):
  File "/home/airflow/.local/lib/python3.6/site-packages/airflow/task/task_runner/standard_task_runner.py", line 85, in _start_by_fork
    args.func(args, dag=self.dag)
  File "/home/airflow/.local/lib/python3.6/site-packages/airflow/cli/cli_parser.py", line 48, in command
    return func(*args, **kwargs)
  File "/home/airflow/.local/lib/python3.6/site-packages/airflow/utils/cli.py", line 92, in wrapper
    return f(*args, **kwargs)
  File "/home/airflow/.local/lib/python3.6/site-packages/airflow/cli/commands/task_command.py", line 298, in task_run
    _run_task_by_selected_method(args, dag, ti)
  File "/home/airflow/.local/lib/python3.6/site-packages/airflow/cli/commands/task_command.py", line 107, in _run_task_by_selected_method
    _run_raw_task(args, ti)
  File "/home/airflow/.local/lib/python3.6/site-packages/airflow/cli/commands/task_command.py", line 184, in _run_raw_task
    error_file=args.error_file,
  File "/home/airflow/.local/lib/python3.6/site-packages/airflow/utils/session.py", line 70, in wrapper
    return func(*args, session=session, **kwargs)
  File "/home/airflow/.local/lib/python3.6/site-packages/airflow/models/taskinstance.py", line 1329, in _run_raw_task
    self._execute_task_with_callbacks(context)
  File "/home/airflow/.local/lib/python3.6/site-packages/airflow/models/taskinstance.py", line 1455, in _execute_task_with_callbacks
    result = self._execute_task(context, self.task)
  File "/home/airflow/.local/lib/python3.6/site-packages/airflow/models/taskinstance.py", line 1511, in _execute_task
    result = execute_callable(context=context)
  File "/home/airflow/.local/lib/python3.6/site-packages/airflow/operators/python.py", line 174, in execute
    return_value = self.execute_callable()
  File "/home/airflow/.local/lib/python3.6/site-packages/airflow/operators/python.py", line 185, in execute_callable
    return self.python_callable(*self.op_args, **self.op_kwargs)
  File "/opt/airflow/dags/data_ingestion.py", line 108, in format_to_parquet
    with open(src_file, 'r') as file:
FileNotFoundError: [Errno 2] No such file or directory: '/opt/airflow/2024-05-21-1.json'
[2024-05-22 07:07:01,460] {local_task_job.py:154} INFO - Task exited with return code 1
[2024-05-22 07:07:02,044] {local_task_job.py:264} INFO - 0 downstream tasks scheduled from follow-on schedule check
[2024-05-22 07:14:20,094] {taskinstance.py:1032} INFO - Dependencies all met for <TaskInstance: purpleair_api_dag.format_to_parquet_task scheduled__2024-05-21T01:00:00+00:00 [queued]>
[2024-05-22 07:14:20,282] {taskinstance.py:1032} INFO - Dependencies all met for <TaskInstance: purpleair_api_dag.format_to_parquet_task scheduled__2024-05-21T01:00:00+00:00 [queued]>
[2024-05-22 07:14:20,304] {taskinstance.py:1238} INFO - 
--------------------------------------------------------------------------------
[2024-05-22 07:14:20,308] {taskinstance.py:1239} INFO - Starting attempt 1 of 2
[2024-05-22 07:14:20,312] {taskinstance.py:1240} INFO - 
--------------------------------------------------------------------------------
[2024-05-22 07:14:20,361] {taskinstance.py:1259} INFO - Executing <Task(PythonOperator): format_to_parquet_task> on 2024-05-21 01:00:00+00:00
[2024-05-22 07:14:20,371] {standard_task_runner.py:52} INFO - Started process 1837 to run task
[2024-05-22 07:14:20,396] {standard_task_runner.py:76} INFO - Running: ['***', 'tasks', 'run', 'purpleair_api_dag', 'format_to_parquet_task', 'scheduled__2024-05-21T01:00:00+00:00', '--job-id', '258', '--raw', '--subdir', 'DAGS_FOLDER/data_ingestion.py', '--cfg-path', '/tmp/tmpda7dj519', '--error-file', '/tmp/tmpynub9v0a']
[2024-05-22 07:14:20,435] {standard_task_runner.py:77} INFO - Job 258: Subtask format_to_parquet_task
[2024-05-22 07:14:20,844] {logging_mixin.py:109} INFO - Running <TaskInstance: purpleair_api_dag.format_to_parquet_task scheduled__2024-05-21T01:00:00+00:00 [running]> on host 148b4063f71c
[2024-05-22 07:14:21,122] {warnings.py:99} WARNING - /home/***/.local/lib/python3.6/site-packages/***/utils/context.py:152: AirflowContextDeprecationWarning: Accessing 'execution_date' from the template is deprecated and will be removed in a future version. Please use 'data_interval_start' or 'logical_date' instead.
  warnings.warn(_create_deprecation_warning(key, self._deprecation_replacements[key]))

[2024-05-22 07:14:21,281] {taskinstance.py:1426} INFO - Exporting the following env vars:
AIRFLOW_CTX_DAG_OWNER=***
AIRFLOW_CTX_DAG_ID=purpleair_api_dag
AIRFLOW_CTX_TASK_ID=format_to_parquet_task
AIRFLOW_CTX_EXECUTION_DATE=2024-05-21T01:00:00+00:00
AIRFLOW_CTX_DAG_RUN_ID=scheduled__2024-05-21T01:00:00+00:00
[2024-05-22 07:14:21,283] {taskinstance.py:1700} ERROR - Task failed with exception
Traceback (most recent call last):
  File "/home/airflow/.local/lib/python3.6/site-packages/airflow/models/taskinstance.py", line 1329, in _run_raw_task
    self._execute_task_with_callbacks(context)
  File "/home/airflow/.local/lib/python3.6/site-packages/airflow/models/taskinstance.py", line 1455, in _execute_task_with_callbacks
    result = self._execute_task(context, self.task)
  File "/home/airflow/.local/lib/python3.6/site-packages/airflow/models/taskinstance.py", line 1511, in _execute_task
    result = execute_callable(context=context)
  File "/home/airflow/.local/lib/python3.6/site-packages/airflow/operators/python.py", line 174, in execute
    return_value = self.execute_callable()
  File "/home/airflow/.local/lib/python3.6/site-packages/airflow/operators/python.py", line 185, in execute_callable
    return self.python_callable(*self.op_args, **self.op_kwargs)
  File "/opt/airflow/dags/data_ingestion.py", line 108, in format_to_parquet
    with open(src_file, 'r') as file:
FileNotFoundError: [Errno 2] No such file or directory: '/opt/airflow/2024-05-21-1.json'
[2024-05-22 07:14:21,365] {taskinstance.py:1277} INFO - Marking task as UP_FOR_RETRY. dag_id=purpleair_api_dag, task_id=format_to_parquet_task, execution_date=20240521T010000, start_date=20240522T071420, end_date=20240522T071421
[2024-05-22 07:14:21,539] {standard_task_runner.py:92} ERROR - Failed to execute job 258 for task format_to_parquet_task
Traceback (most recent call last):
  File "/home/airflow/.local/lib/python3.6/site-packages/airflow/task/task_runner/standard_task_runner.py", line 85, in _start_by_fork
    args.func(args, dag=self.dag)
  File "/home/airflow/.local/lib/python3.6/site-packages/airflow/cli/cli_parser.py", line 48, in command
    return func(*args, **kwargs)
  File "/home/airflow/.local/lib/python3.6/site-packages/airflow/utils/cli.py", line 92, in wrapper
    return f(*args, **kwargs)
  File "/home/airflow/.local/lib/python3.6/site-packages/airflow/cli/commands/task_command.py", line 298, in task_run
    _run_task_by_selected_method(args, dag, ti)
  File "/home/airflow/.local/lib/python3.6/site-packages/airflow/cli/commands/task_command.py", line 107, in _run_task_by_selected_method
    _run_raw_task(args, ti)
  File "/home/airflow/.local/lib/python3.6/site-packages/airflow/cli/commands/task_command.py", line 184, in _run_raw_task
    error_file=args.error_file,
  File "/home/airflow/.local/lib/python3.6/site-packages/airflow/utils/session.py", line 70, in wrapper
    return func(*args, session=session, **kwargs)
  File "/home/airflow/.local/lib/python3.6/site-packages/airflow/models/taskinstance.py", line 1329, in _run_raw_task
    self._execute_task_with_callbacks(context)
  File "/home/airflow/.local/lib/python3.6/site-packages/airflow/models/taskinstance.py", line 1455, in _execute_task_with_callbacks
    result = self._execute_task(context, self.task)
  File "/home/airflow/.local/lib/python3.6/site-packages/airflow/models/taskinstance.py", line 1511, in _execute_task
    result = execute_callable(context=context)
  File "/home/airflow/.local/lib/python3.6/site-packages/airflow/operators/python.py", line 174, in execute
    return_value = self.execute_callable()
  File "/home/airflow/.local/lib/python3.6/site-packages/airflow/operators/python.py", line 185, in execute_callable
    return self.python_callable(*self.op_args, **self.op_kwargs)
  File "/opt/airflow/dags/data_ingestion.py", line 108, in format_to_parquet
    with open(src_file, 'r') as file:
FileNotFoundError: [Errno 2] No such file or directory: '/opt/airflow/2024-05-21-1.json'
[2024-05-22 07:14:21,656] {local_task_job.py:154} INFO - Task exited with return code 1
[2024-05-22 07:14:21,954] {local_task_job.py:264} INFO - 0 downstream tasks scheduled from follow-on schedule check
[2024-05-22 07:16:44,813] {taskinstance.py:1032} INFO - Dependencies all met for <TaskInstance: purpleair_api_dag.format_to_parquet_task scheduled__2024-05-21T01:00:00+00:00 [queued]>
[2024-05-22 07:16:45,106] {taskinstance.py:1032} INFO - Dependencies all met for <TaskInstance: purpleair_api_dag.format_to_parquet_task scheduled__2024-05-21T01:00:00+00:00 [queued]>
[2024-05-22 07:16:45,106] {taskinstance.py:1238} INFO - 
--------------------------------------------------------------------------------
[2024-05-22 07:16:45,106] {taskinstance.py:1239} INFO - Starting attempt 1 of 2
[2024-05-22 07:16:45,106] {taskinstance.py:1240} INFO - 
--------------------------------------------------------------------------------
[2024-05-22 07:16:45,377] {taskinstance.py:1259} INFO - Executing <Task(PythonOperator): format_to_parquet_task> on 2024-05-21 01:00:00+00:00
[2024-05-22 07:16:45,394] {standard_task_runner.py:52} INFO - Started process 2024 to run task
[2024-05-22 07:16:45,418] {standard_task_runner.py:76} INFO - Running: ['***', 'tasks', 'run', 'purpleair_api_dag', 'format_to_parquet_task', 'scheduled__2024-05-21T01:00:00+00:00', '--job-id', '290', '--raw', '--subdir', 'DAGS_FOLDER/data_ingestion.py', '--cfg-path', '/tmp/tmp3ahopz9r', '--error-file', '/tmp/tmpucyzfdhf']
[2024-05-22 07:16:45,426] {standard_task_runner.py:77} INFO - Job 290: Subtask format_to_parquet_task
[2024-05-22 07:16:45,976] {logging_mixin.py:109} INFO - Running <TaskInstance: purpleair_api_dag.format_to_parquet_task scheduled__2024-05-21T01:00:00+00:00 [running]> on host 148b4063f71c
[2024-05-22 07:16:46,506] {warnings.py:99} WARNING - /home/***/.local/lib/python3.6/site-packages/***/utils/context.py:152: AirflowContextDeprecationWarning: Accessing 'execution_date' from the template is deprecated and will be removed in a future version. Please use 'data_interval_start' or 'logical_date' instead.
  warnings.warn(_create_deprecation_warning(key, self._deprecation_replacements[key]))

[2024-05-22 07:16:46,778] {taskinstance.py:1426} INFO - Exporting the following env vars:
AIRFLOW_CTX_DAG_OWNER=***
AIRFLOW_CTX_DAG_ID=purpleair_api_dag
AIRFLOW_CTX_TASK_ID=format_to_parquet_task
AIRFLOW_CTX_EXECUTION_DATE=2024-05-21T01:00:00+00:00
AIRFLOW_CTX_DAG_RUN_ID=scheduled__2024-05-21T01:00:00+00:00
[2024-05-22 07:16:46,780] {taskinstance.py:1700} ERROR - Task failed with exception
Traceback (most recent call last):
  File "/home/airflow/.local/lib/python3.6/site-packages/airflow/models/taskinstance.py", line 1329, in _run_raw_task
    self._execute_task_with_callbacks(context)
  File "/home/airflow/.local/lib/python3.6/site-packages/airflow/models/taskinstance.py", line 1455, in _execute_task_with_callbacks
    result = self._execute_task(context, self.task)
  File "/home/airflow/.local/lib/python3.6/site-packages/airflow/models/taskinstance.py", line 1511, in _execute_task
    result = execute_callable(context=context)
  File "/home/airflow/.local/lib/python3.6/site-packages/airflow/operators/python.py", line 174, in execute
    return_value = self.execute_callable()
  File "/home/airflow/.local/lib/python3.6/site-packages/airflow/operators/python.py", line 185, in execute_callable
    return self.python_callable(*self.op_args, **self.op_kwargs)
  File "/opt/airflow/dags/data_ingestion.py", line 108, in format_to_parquet
    with open(src_file, 'r') as file:
FileNotFoundError: [Errno 2] No such file or directory: '/opt/airflow/2024-05-21-1.json'
[2024-05-22 07:16:46,927] {taskinstance.py:1277} INFO - Marking task as UP_FOR_RETRY. dag_id=purpleair_api_dag, task_id=format_to_parquet_task, execution_date=20240521T010000, start_date=20240522T071644, end_date=20240522T071646
[2024-05-22 07:16:47,117] {standard_task_runner.py:92} ERROR - Failed to execute job 290 for task format_to_parquet_task
Traceback (most recent call last):
  File "/home/airflow/.local/lib/python3.6/site-packages/airflow/task/task_runner/standard_task_runner.py", line 85, in _start_by_fork
    args.func(args, dag=self.dag)
  File "/home/airflow/.local/lib/python3.6/site-packages/airflow/cli/cli_parser.py", line 48, in command
    return func(*args, **kwargs)
  File "/home/airflow/.local/lib/python3.6/site-packages/airflow/utils/cli.py", line 92, in wrapper
    return f(*args, **kwargs)
  File "/home/airflow/.local/lib/python3.6/site-packages/airflow/cli/commands/task_command.py", line 298, in task_run
    _run_task_by_selected_method(args, dag, ti)
  File "/home/airflow/.local/lib/python3.6/site-packages/airflow/cli/commands/task_command.py", line 107, in _run_task_by_selected_method
    _run_raw_task(args, ti)
  File "/home/airflow/.local/lib/python3.6/site-packages/airflow/cli/commands/task_command.py", line 184, in _run_raw_task
    error_file=args.error_file,
  File "/home/airflow/.local/lib/python3.6/site-packages/airflow/utils/session.py", line 70, in wrapper
    return func(*args, session=session, **kwargs)
  File "/home/airflow/.local/lib/python3.6/site-packages/airflow/models/taskinstance.py", line 1329, in _run_raw_task
    self._execute_task_with_callbacks(context)
  File "/home/airflow/.local/lib/python3.6/site-packages/airflow/models/taskinstance.py", line 1455, in _execute_task_with_callbacks
    result = self._execute_task(context, self.task)
  File "/home/airflow/.local/lib/python3.6/site-packages/airflow/models/taskinstance.py", line 1511, in _execute_task
    result = execute_callable(context=context)
  File "/home/airflow/.local/lib/python3.6/site-packages/airflow/operators/python.py", line 174, in execute
    return_value = self.execute_callable()
  File "/home/airflow/.local/lib/python3.6/site-packages/airflow/operators/python.py", line 185, in execute_callable
    return self.python_callable(*self.op_args, **self.op_kwargs)
  File "/opt/airflow/dags/data_ingestion.py", line 108, in format_to_parquet
    with open(src_file, 'r') as file:
FileNotFoundError: [Errno 2] No such file or directory: '/opt/airflow/2024-05-21-1.json'
[2024-05-22 07:16:47,290] {local_task_job.py:154} INFO - Task exited with return code 1
[2024-05-22 07:16:47,502] {local_task_job.py:264} INFO - 0 downstream tasks scheduled from follow-on schedule check
[2024-05-22 07:29:16,410] {taskinstance.py:1032} INFO - Dependencies all met for <TaskInstance: purpleair_api_dag.format_to_parquet_task scheduled__2024-05-21T01:00:00+00:00 [queued]>
[2024-05-22 07:29:16,570] {taskinstance.py:1032} INFO - Dependencies all met for <TaskInstance: purpleair_api_dag.format_to_parquet_task scheduled__2024-05-21T01:00:00+00:00 [queued]>
[2024-05-22 07:29:16,584] {taskinstance.py:1238} INFO - 
--------------------------------------------------------------------------------
[2024-05-22 07:29:16,585] {taskinstance.py:1239} INFO - Starting attempt 1 of 2
[2024-05-22 07:29:16,590] {taskinstance.py:1240} INFO - 
--------------------------------------------------------------------------------
[2024-05-22 07:29:16,745] {taskinstance.py:1259} INFO - Executing <Task(PythonOperator): format_to_parquet_task> on 2024-05-21 01:00:00+00:00
[2024-05-22 07:29:16,835] {standard_task_runner.py:76} INFO - Running: ['***', 'tasks', 'run', 'purpleair_api_dag', 'format_to_parquet_task', 'scheduled__2024-05-21T01:00:00+00:00', '--job-id', '386', '--raw', '--subdir', 'DAGS_FOLDER/data_ingestion.py', '--cfg-path', '/tmp/tmpqpkxc1re', '--error-file', '/tmp/tmpflaiotsv']
[2024-05-22 07:29:16,820] {standard_task_runner.py:52} INFO - Started process 2783 to run task
[2024-05-22 07:29:16,876] {standard_task_runner.py:77} INFO - Job 386: Subtask format_to_parquet_task
[2024-05-22 07:29:17,387] {logging_mixin.py:109} INFO - Running <TaskInstance: purpleair_api_dag.format_to_parquet_task scheduled__2024-05-21T01:00:00+00:00 [running]> on host 148b4063f71c
[2024-05-22 07:29:17,731] {warnings.py:99} WARNING - /home/***/.local/lib/python3.6/site-packages/***/utils/context.py:152: AirflowContextDeprecationWarning: Accessing 'execution_date' from the template is deprecated and will be removed in a future version. Please use 'data_interval_start' or 'logical_date' instead.
  warnings.warn(_create_deprecation_warning(key, self._deprecation_replacements[key]))

[2024-05-22 07:29:17,841] {taskinstance.py:1426} INFO - Exporting the following env vars:
AIRFLOW_CTX_DAG_OWNER=***
AIRFLOW_CTX_DAG_ID=purpleair_api_dag
AIRFLOW_CTX_TASK_ID=format_to_parquet_task
AIRFLOW_CTX_EXECUTION_DATE=2024-05-21T01:00:00+00:00
AIRFLOW_CTX_DAG_RUN_ID=scheduled__2024-05-21T01:00:00+00:00
[2024-05-22 07:29:17,842] {taskinstance.py:1700} ERROR - Task failed with exception
Traceback (most recent call last):
  File "/home/airflow/.local/lib/python3.6/site-packages/airflow/models/taskinstance.py", line 1329, in _run_raw_task
    self._execute_task_with_callbacks(context)
  File "/home/airflow/.local/lib/python3.6/site-packages/airflow/models/taskinstance.py", line 1455, in _execute_task_with_callbacks
    result = self._execute_task(context, self.task)
  File "/home/airflow/.local/lib/python3.6/site-packages/airflow/models/taskinstance.py", line 1511, in _execute_task
    result = execute_callable(context=context)
  File "/home/airflow/.local/lib/python3.6/site-packages/airflow/operators/python.py", line 174, in execute
    return_value = self.execute_callable()
  File "/home/airflow/.local/lib/python3.6/site-packages/airflow/operators/python.py", line 185, in execute_callable
    return self.python_callable(*self.op_args, **self.op_kwargs)
  File "/opt/airflow/dags/data_ingestion.py", line 108, in format_to_parquet
    with open(src_file, 'r') as file:
FileNotFoundError: [Errno 2] No such file or directory: '/opt/airflow/2024-05-21-1.json'
[2024-05-22 07:29:17,943] {taskinstance.py:1277} INFO - Marking task as UP_FOR_RETRY. dag_id=purpleair_api_dag, task_id=format_to_parquet_task, execution_date=20240521T010000, start_date=20240522T072916, end_date=20240522T072917
[2024-05-22 07:29:18,246] {standard_task_runner.py:92} ERROR - Failed to execute job 386 for task format_to_parquet_task
Traceback (most recent call last):
  File "/home/airflow/.local/lib/python3.6/site-packages/airflow/task/task_runner/standard_task_runner.py", line 85, in _start_by_fork
    args.func(args, dag=self.dag)
  File "/home/airflow/.local/lib/python3.6/site-packages/airflow/cli/cli_parser.py", line 48, in command
    return func(*args, **kwargs)
  File "/home/airflow/.local/lib/python3.6/site-packages/airflow/utils/cli.py", line 92, in wrapper
    return f(*args, **kwargs)
  File "/home/airflow/.local/lib/python3.6/site-packages/airflow/cli/commands/task_command.py", line 298, in task_run
    _run_task_by_selected_method(args, dag, ti)
  File "/home/airflow/.local/lib/python3.6/site-packages/airflow/cli/commands/task_command.py", line 107, in _run_task_by_selected_method
    _run_raw_task(args, ti)
  File "/home/airflow/.local/lib/python3.6/site-packages/airflow/cli/commands/task_command.py", line 184, in _run_raw_task
    error_file=args.error_file,
  File "/home/airflow/.local/lib/python3.6/site-packages/airflow/utils/session.py", line 70, in wrapper
    return func(*args, session=session, **kwargs)
  File "/home/airflow/.local/lib/python3.6/site-packages/airflow/models/taskinstance.py", line 1329, in _run_raw_task
    self._execute_task_with_callbacks(context)
  File "/home/airflow/.local/lib/python3.6/site-packages/airflow/models/taskinstance.py", line 1455, in _execute_task_with_callbacks
    result = self._execute_task(context, self.task)
  File "/home/airflow/.local/lib/python3.6/site-packages/airflow/models/taskinstance.py", line 1511, in _execute_task
    result = execute_callable(context=context)
  File "/home/airflow/.local/lib/python3.6/site-packages/airflow/operators/python.py", line 174, in execute
    return_value = self.execute_callable()
  File "/home/airflow/.local/lib/python3.6/site-packages/airflow/operators/python.py", line 185, in execute_callable
    return self.python_callable(*self.op_args, **self.op_kwargs)
  File "/opt/airflow/dags/data_ingestion.py", line 108, in format_to_parquet
    with open(src_file, 'r') as file:
FileNotFoundError: [Errno 2] No such file or directory: '/opt/airflow/2024-05-21-1.json'
[2024-05-22 07:29:18,316] {local_task_job.py:154} INFO - Task exited with return code 1
[2024-05-22 07:29:18,785] {local_task_job.py:264} INFO - 0 downstream tasks scheduled from follow-on schedule check
[2024-05-22 07:33:26,402] {taskinstance.py:1032} INFO - Dependencies all met for <TaskInstance: purpleair_api_dag.format_to_parquet_task scheduled__2024-05-21T01:00:00+00:00 [queued]>
[2024-05-22 07:33:26,598] {taskinstance.py:1032} INFO - Dependencies all met for <TaskInstance: purpleair_api_dag.format_to_parquet_task scheduled__2024-05-21T01:00:00+00:00 [queued]>
[2024-05-22 07:33:26,624] {taskinstance.py:1238} INFO - 
--------------------------------------------------------------------------------
[2024-05-22 07:33:26,636] {taskinstance.py:1239} INFO - Starting attempt 1 of 2
[2024-05-22 07:33:26,637] {taskinstance.py:1240} INFO - 
--------------------------------------------------------------------------------
[2024-05-22 07:33:26,771] {taskinstance.py:1259} INFO - Executing <Task(PythonOperator): format_to_parquet_task> on 2024-05-21 01:00:00+00:00
[2024-05-22 07:33:26,912] {standard_task_runner.py:76} INFO - Running: ['***', 'tasks', 'run', 'purpleair_api_dag', 'format_to_parquet_task', 'scheduled__2024-05-21T01:00:00+00:00', '--job-id', '419', '--raw', '--subdir', 'DAGS_FOLDER/data_ingestion.py', '--cfg-path', '/tmp/tmpwkfjp1do', '--error-file', '/tmp/tmpegwu5_sf']
[2024-05-22 07:33:26,959] {standard_task_runner.py:77} INFO - Job 419: Subtask format_to_parquet_task
[2024-05-22 07:33:26,830] {standard_task_runner.py:52} INFO - Started process 3035 to run task
[2024-05-22 07:33:27,409] {logging_mixin.py:109} INFO - Running <TaskInstance: purpleair_api_dag.format_to_parquet_task scheduled__2024-05-21T01:00:00+00:00 [running]> on host 148b4063f71c
[2024-05-22 07:33:27,676] {warnings.py:99} WARNING - /home/***/.local/lib/python3.6/site-packages/***/utils/context.py:152: AirflowContextDeprecationWarning: Accessing 'execution_date' from the template is deprecated and will be removed in a future version. Please use 'data_interval_start' or 'logical_date' instead.
  warnings.warn(_create_deprecation_warning(key, self._deprecation_replacements[key]))

[2024-05-22 07:33:27,993] {taskinstance.py:1426} INFO - Exporting the following env vars:
AIRFLOW_CTX_DAG_OWNER=***
AIRFLOW_CTX_DAG_ID=purpleair_api_dag
AIRFLOW_CTX_TASK_ID=format_to_parquet_task
AIRFLOW_CTX_EXECUTION_DATE=2024-05-21T01:00:00+00:00
AIRFLOW_CTX_DAG_RUN_ID=scheduled__2024-05-21T01:00:00+00:00
[2024-05-22 07:33:27,994] {logging_mixin.py:109} INFO - The file 'data.json' was not found.
[2024-05-22 07:33:28,016] {taskinstance.py:1700} ERROR - Task failed with exception
Traceback (most recent call last):
  File "/home/airflow/.local/lib/python3.6/site-packages/airflow/models/taskinstance.py", line 1329, in _run_raw_task
    self._execute_task_with_callbacks(context)
  File "/home/airflow/.local/lib/python3.6/site-packages/airflow/models/taskinstance.py", line 1455, in _execute_task_with_callbacks
    result = self._execute_task(context, self.task)
  File "/home/airflow/.local/lib/python3.6/site-packages/airflow/models/taskinstance.py", line 1511, in _execute_task
    result = execute_callable(context=context)
  File "/home/airflow/.local/lib/python3.6/site-packages/airflow/operators/python.py", line 174, in execute
    return_value = self.execute_callable()
  File "/home/airflow/.local/lib/python3.6/site-packages/airflow/operators/python.py", line 185, in execute_callable
    return self.python_callable(*self.op_args, **self.op_kwargs)
  File "/opt/airflow/dags/data_ingestion.py", line 120, in format_to_parquet
    print(glom(json_data, 'fields'))
UnboundLocalError: local variable 'json_data' referenced before assignment
[2024-05-22 07:33:28,135] {taskinstance.py:1277} INFO - Marking task as UP_FOR_RETRY. dag_id=purpleair_api_dag, task_id=format_to_parquet_task, execution_date=20240521T010000, start_date=20240522T073326, end_date=20240522T073328
[2024-05-22 07:33:28,377] {standard_task_runner.py:92} ERROR - Failed to execute job 419 for task format_to_parquet_task
Traceback (most recent call last):
  File "/home/airflow/.local/lib/python3.6/site-packages/airflow/task/task_runner/standard_task_runner.py", line 85, in _start_by_fork
    args.func(args, dag=self.dag)
  File "/home/airflow/.local/lib/python3.6/site-packages/airflow/cli/cli_parser.py", line 48, in command
    return func(*args, **kwargs)
  File "/home/airflow/.local/lib/python3.6/site-packages/airflow/utils/cli.py", line 92, in wrapper
    return f(*args, **kwargs)
  File "/home/airflow/.local/lib/python3.6/site-packages/airflow/cli/commands/task_command.py", line 298, in task_run
    _run_task_by_selected_method(args, dag, ti)
  File "/home/airflow/.local/lib/python3.6/site-packages/airflow/cli/commands/task_command.py", line 107, in _run_task_by_selected_method
    _run_raw_task(args, ti)
  File "/home/airflow/.local/lib/python3.6/site-packages/airflow/cli/commands/task_command.py", line 184, in _run_raw_task
    error_file=args.error_file,
  File "/home/airflow/.local/lib/python3.6/site-packages/airflow/utils/session.py", line 70, in wrapper
    return func(*args, session=session, **kwargs)
  File "/home/airflow/.local/lib/python3.6/site-packages/airflow/models/taskinstance.py", line 1329, in _run_raw_task
    self._execute_task_with_callbacks(context)
  File "/home/airflow/.local/lib/python3.6/site-packages/airflow/models/taskinstance.py", line 1455, in _execute_task_with_callbacks
    result = self._execute_task(context, self.task)
  File "/home/airflow/.local/lib/python3.6/site-packages/airflow/models/taskinstance.py", line 1511, in _execute_task
    result = execute_callable(context=context)
  File "/home/airflow/.local/lib/python3.6/site-packages/airflow/operators/python.py", line 174, in execute
    return_value = self.execute_callable()
  File "/home/airflow/.local/lib/python3.6/site-packages/airflow/operators/python.py", line 185, in execute_callable
    return self.python_callable(*self.op_args, **self.op_kwargs)
  File "/opt/airflow/dags/data_ingestion.py", line 120, in format_to_parquet
    print(glom(json_data, 'fields'))
UnboundLocalError: local variable 'json_data' referenced before assignment
[2024-05-22 07:33:28,517] {local_task_job.py:154} INFO - Task exited with return code 1
[2024-05-22 07:33:28,765] {local_task_job.py:264} INFO - 0 downstream tasks scheduled from follow-on schedule check
