[2024-05-22 02:20:21,405] {taskinstance.py:1032} INFO - Dependencies all met for <TaskInstance: purpleair_api_dag.fetch_data scheduled__2024-05-21T05:00:00+00:00 [queued]>
[2024-05-22 02:20:21,497] {taskinstance.py:1032} INFO - Dependencies all met for <TaskInstance: purpleair_api_dag.fetch_data scheduled__2024-05-21T05:00:00+00:00 [queued]>
[2024-05-22 02:20:21,498] {taskinstance.py:1238} INFO - 
--------------------------------------------------------------------------------
[2024-05-22 02:20:21,498] {taskinstance.py:1239} INFO - Starting attempt 1 of 2
[2024-05-22 02:20:21,498] {taskinstance.py:1240} INFO - 
--------------------------------------------------------------------------------
[2024-05-22 02:20:21,580] {taskinstance.py:1259} INFO - Executing <Task(PythonOperator): fetch_data> on 2024-05-21 05:00:00+00:00
[2024-05-22 02:20:21,617] {standard_task_runner.py:52} INFO - Started process 2351 to run task
[2024-05-22 02:20:21,663] {standard_task_runner.py:76} INFO - Running: ['***', 'tasks', 'run', 'purpleair_api_dag', 'fetch_data', 'scheduled__2024-05-21T05:00:00+00:00', '--job-id', '6', '--raw', '--subdir', 'DAGS_FOLDER/data_ingestion.py', '--cfg-path', '/tmp/tmpg9aqdoq_', '--error-file', '/tmp/tmpupqtd1jk']
[2024-05-22 02:20:21,759] {standard_task_runner.py:77} INFO - Job 6: Subtask fetch_data
[2024-05-22 02:20:22,381] {logging_mixin.py:109} INFO - Running <TaskInstance: purpleair_api_dag.fetch_data scheduled__2024-05-21T05:00:00+00:00 [running]> on host 8fe6997c1526
[2024-05-22 02:20:22,780] {taskinstance.py:1426} INFO - Exporting the following env vars:
AIRFLOW_CTX_DAG_OWNER=***
AIRFLOW_CTX_DAG_ID=purpleair_api_dag
AIRFLOW_CTX_TASK_ID=fetch_data
AIRFLOW_CTX_EXECUTION_DATE=2024-05-21T05:00:00+00:00
AIRFLOW_CTX_DAG_RUN_ID=scheduled__2024-05-21T05:00:00+00:00
[2024-05-22 02:20:23,039] {logging_mixin.py:109} INFO - Failed to retrieve data: 403
[2024-05-22 02:20:23,050] {python.py:175} INFO - Done. Returned value was: None
[2024-05-22 02:20:23,135] {taskinstance.py:1277} INFO - Marking task as SUCCESS. dag_id=purpleair_api_dag, task_id=fetch_data, execution_date=20240521T050000, start_date=20240522T022021, end_date=20240522T022023
[2024-05-22 02:20:23,338] {local_task_job.py:154} INFO - Task exited with return code 0
[2024-05-22 02:20:23,522] {local_task_job.py:264} INFO - 0 downstream tasks scheduled from follow-on schedule check
[2024-05-22 04:14:08,432] {taskinstance.py:1032} INFO - Dependencies all met for <TaskInstance: purpleair_api_dag.fetch_data scheduled__2024-05-21T05:00:00+00:00 [queued]>
[2024-05-22 04:14:08,581] {taskinstance.py:1032} INFO - Dependencies all met for <TaskInstance: purpleair_api_dag.fetch_data scheduled__2024-05-21T05:00:00+00:00 [queued]>
[2024-05-22 04:14:08,582] {taskinstance.py:1238} INFO - 
--------------------------------------------------------------------------------
[2024-05-22 04:14:08,582] {taskinstance.py:1239} INFO - Starting attempt 1 of 2
[2024-05-22 04:14:08,582] {taskinstance.py:1240} INFO - 
--------------------------------------------------------------------------------
[2024-05-22 04:14:08,714] {taskinstance.py:1259} INFO - Executing <Task(PythonOperator): fetch_data> on 2024-05-21 05:00:00+00:00
[2024-05-22 04:14:08,755] {standard_task_runner.py:52} INFO - Started process 136 to run task
[2024-05-22 04:14:08,839] {standard_task_runner.py:76} INFO - Running: ['***', 'tasks', 'run', 'purpleair_api_dag', 'fetch_data', 'scheduled__2024-05-21T05:00:00+00:00', '--job-id', '4', '--raw', '--subdir', 'DAGS_FOLDER/data_ingestion.py', '--cfg-path', '/tmp/tmp8gybptg9', '--error-file', '/tmp/tmp20mt64uo']
[2024-05-22 04:14:08,952] {standard_task_runner.py:77} INFO - Job 4: Subtask fetch_data
[2024-05-22 04:14:09,427] {logging_mixin.py:109} INFO - Running <TaskInstance: purpleair_api_dag.fetch_data scheduled__2024-05-21T05:00:00+00:00 [running]> on host 3419eee920a5
[2024-05-22 04:14:09,819] {taskinstance.py:1426} INFO - Exporting the following env vars:
AIRFLOW_CTX_DAG_OWNER=***
AIRFLOW_CTX_DAG_ID=purpleair_api_dag
AIRFLOW_CTX_TASK_ID=fetch_data
AIRFLOW_CTX_EXECUTION_DATE=2024-05-21T05:00:00+00:00
AIRFLOW_CTX_DAG_RUN_ID=scheduled__2024-05-21T05:00:00+00:00
[2024-05-22 04:14:09,834] {taskinstance.py:1700} ERROR - Task failed with exception
Traceback (most recent call last):
  File "/home/airflow/.local/lib/python3.6/site-packages/airflow/models/taskinstance.py", line 1329, in _run_raw_task
    self._execute_task_with_callbacks(context)
  File "/home/airflow/.local/lib/python3.6/site-packages/airflow/models/taskinstance.py", line 1455, in _execute_task_with_callbacks
    result = self._execute_task(context, self.task)
  File "/home/airflow/.local/lib/python3.6/site-packages/airflow/models/taskinstance.py", line 1511, in _execute_task
    result = execute_callable(context=context)
  File "/home/airflow/.local/lib/python3.6/site-packages/airflow/operators/python.py", line 174, in execute
    return_value = self.execute_callable()
  File "/home/airflow/.local/lib/python3.6/site-packages/airflow/operators/python.py", line 185, in execute_callable
    return self.python_callable(*self.op_args, **self.op_kwargs)
  File "/opt/airflow/dags/data_ingestion.py", line 67, in api_url
    print(f" url is {url}")
NameError: name 'url' is not defined
[2024-05-22 04:14:09,899] {taskinstance.py:1277} INFO - Marking task as UP_FOR_RETRY. dag_id=purpleair_api_dag, task_id=fetch_data, execution_date=20240521T050000, start_date=20240522T041408, end_date=20240522T041409
[2024-05-22 04:14:09,997] {standard_task_runner.py:92} ERROR - Failed to execute job 4 for task fetch_data
Traceback (most recent call last):
  File "/home/airflow/.local/lib/python3.6/site-packages/airflow/task/task_runner/standard_task_runner.py", line 85, in _start_by_fork
    args.func(args, dag=self.dag)
  File "/home/airflow/.local/lib/python3.6/site-packages/airflow/cli/cli_parser.py", line 48, in command
    return func(*args, **kwargs)
  File "/home/airflow/.local/lib/python3.6/site-packages/airflow/utils/cli.py", line 92, in wrapper
    return f(*args, **kwargs)
  File "/home/airflow/.local/lib/python3.6/site-packages/airflow/cli/commands/task_command.py", line 298, in task_run
    _run_task_by_selected_method(args, dag, ti)
  File "/home/airflow/.local/lib/python3.6/site-packages/airflow/cli/commands/task_command.py", line 107, in _run_task_by_selected_method
    _run_raw_task(args, ti)
  File "/home/airflow/.local/lib/python3.6/site-packages/airflow/cli/commands/task_command.py", line 184, in _run_raw_task
    error_file=args.error_file,
  File "/home/airflow/.local/lib/python3.6/site-packages/airflow/utils/session.py", line 70, in wrapper
    return func(*args, session=session, **kwargs)
  File "/home/airflow/.local/lib/python3.6/site-packages/airflow/models/taskinstance.py", line 1329, in _run_raw_task
    self._execute_task_with_callbacks(context)
  File "/home/airflow/.local/lib/python3.6/site-packages/airflow/models/taskinstance.py", line 1455, in _execute_task_with_callbacks
    result = self._execute_task(context, self.task)
  File "/home/airflow/.local/lib/python3.6/site-packages/airflow/models/taskinstance.py", line 1511, in _execute_task
    result = execute_callable(context=context)
  File "/home/airflow/.local/lib/python3.6/site-packages/airflow/operators/python.py", line 174, in execute
    return_value = self.execute_callable()
  File "/home/airflow/.local/lib/python3.6/site-packages/airflow/operators/python.py", line 185, in execute_callable
    return self.python_callable(*self.op_args, **self.op_kwargs)
  File "/opt/airflow/dags/data_ingestion.py", line 67, in api_url
    print(f" url is {url}")
NameError: name 'url' is not defined
[2024-05-22 04:14:10,099] {local_task_job.py:154} INFO - Task exited with return code 1
[2024-05-22 04:14:10,293] {local_task_job.py:264} INFO - 0 downstream tasks scheduled from follow-on schedule check
[2024-05-22 04:17:35,473] {taskinstance.py:1032} INFO - Dependencies all met for <TaskInstance: purpleair_api_dag.fetch_data scheduled__2024-05-21T05:00:00+00:00 [queued]>
[2024-05-22 04:17:35,742] {taskinstance.py:1032} INFO - Dependencies all met for <TaskInstance: purpleair_api_dag.fetch_data scheduled__2024-05-21T05:00:00+00:00 [queued]>
[2024-05-22 04:17:35,742] {taskinstance.py:1238} INFO - 
--------------------------------------------------------------------------------
[2024-05-22 04:17:35,743] {taskinstance.py:1239} INFO - Starting attempt 1 of 2
[2024-05-22 04:17:35,743] {taskinstance.py:1240} INFO - 
--------------------------------------------------------------------------------
[2024-05-22 04:17:36,061] {taskinstance.py:1259} INFO - Executing <Task(PythonOperator): fetch_data> on 2024-05-21 05:00:00+00:00
[2024-05-22 04:17:36,103] {standard_task_runner.py:52} INFO - Started process 327 to run task
[2024-05-22 04:17:36,181] {standard_task_runner.py:76} INFO - Running: ['***', 'tasks', 'run', 'purpleair_api_dag', 'fetch_data', 'scheduled__2024-05-21T05:00:00+00:00', '--job-id', '24', '--raw', '--subdir', 'DAGS_FOLDER/data_ingestion.py', '--cfg-path', '/tmp/tmp68c9u6hc', '--error-file', '/tmp/tmpnszp663l']
[2024-05-22 04:17:36,290] {standard_task_runner.py:77} INFO - Job 24: Subtask fetch_data
[2024-05-22 04:17:36,840] {logging_mixin.py:109} INFO - Running <TaskInstance: purpleair_api_dag.fetch_data scheduled__2024-05-21T05:00:00+00:00 [running]> on host 3419eee920a5
[2024-05-22 04:17:37,145] {taskinstance.py:1426} INFO - Exporting the following env vars:
AIRFLOW_CTX_DAG_OWNER=***
AIRFLOW_CTX_DAG_ID=purpleair_api_dag
AIRFLOW_CTX_TASK_ID=fetch_data
AIRFLOW_CTX_EXECUTION_DATE=2024-05-21T05:00:00+00:00
AIRFLOW_CTX_DAG_RUN_ID=scheduled__2024-05-21T05:00:00+00:00
[2024-05-22 04:17:37,149] {logging_mixin.py:109} INFO -  api is None
[2024-05-22 04:17:37,165] {logging_mixin.py:109} INFO - Full URL: https://api.purpleair.com/v1/sensors?fields=latitude%2Clongitude%2Chumidity%2Cpm2.5_60minute%2Clast_seen&location_type=0&max_age=300
[2024-05-22 04:17:37,168] {logging_mixin.py:109} INFO - Headers: {'X-API-Key': 'None'}
[2024-05-22 04:17:37,378] {logging_mixin.py:109} INFO - Status Code: 403
[2024-05-22 04:17:37,386] {logging_mixin.py:109} INFO - Response Content: {
  "api_version" : "V1.0.13-0.0.56",
  "time_stamp" : 1716351457,
  "error" : "ApiKeyInvalidError",
  "description" : "The provided api_key was not valid."
}
[2024-05-22 04:17:37,555] {logging_mixin.py:109} INFO - Failed to retrieve data: 403
[2024-05-22 04:17:37,564] {python.py:175} INFO - Done. Returned value was: None
[2024-05-22 04:17:37,608] {taskinstance.py:1277} INFO - Marking task as SUCCESS. dag_id=purpleair_api_dag, task_id=fetch_data, execution_date=20240521T050000, start_date=20240522T041735, end_date=20240522T041737
[2024-05-22 04:17:37,773] {local_task_job.py:154} INFO - Task exited with return code 0
[2024-05-22 04:17:37,894] {local_task_job.py:264} INFO - 0 downstream tasks scheduled from follow-on schedule check
