[2024-05-22 02:20:23,983] {taskinstance.py:1032} INFO - Dependencies all met for <TaskInstance: purpleair_api_dag.fetch_data scheduled__2024-05-21T07:00:00+00:00 [queued]>
[2024-05-22 02:20:24,100] {taskinstance.py:1032} INFO - Dependencies all met for <TaskInstance: purpleair_api_dag.fetch_data scheduled__2024-05-21T07:00:00+00:00 [queued]>
[2024-05-22 02:20:24,104] {taskinstance.py:1238} INFO - 
--------------------------------------------------------------------------------
[2024-05-22 02:20:24,108] {taskinstance.py:1239} INFO - Starting attempt 1 of 2
[2024-05-22 02:20:24,115] {taskinstance.py:1240} INFO - 
--------------------------------------------------------------------------------
[2024-05-22 02:20:24,203] {taskinstance.py:1259} INFO - Executing <Task(PythonOperator): fetch_data> on 2024-05-21 07:00:00+00:00
[2024-05-22 02:20:24,223] {standard_task_runner.py:52} INFO - Started process 2361 to run task
[2024-05-22 02:20:24,279] {standard_task_runner.py:76} INFO - Running: ['***', 'tasks', 'run', 'purpleair_api_dag', 'fetch_data', 'scheduled__2024-05-21T07:00:00+00:00', '--job-id', '9', '--raw', '--subdir', 'DAGS_FOLDER/data_ingestion.py', '--cfg-path', '/tmp/tmpya92q38i', '--error-file', '/tmp/tmphjg3703k']
[2024-05-22 02:20:24,367] {standard_task_runner.py:77} INFO - Job 9: Subtask fetch_data
[2024-05-22 02:20:24,717] {logging_mixin.py:109} INFO - Running <TaskInstance: purpleair_api_dag.fetch_data scheduled__2024-05-21T07:00:00+00:00 [running]> on host 8fe6997c1526
[2024-05-22 02:20:24,989] {taskinstance.py:1426} INFO - Exporting the following env vars:
AIRFLOW_CTX_DAG_OWNER=***
AIRFLOW_CTX_DAG_ID=purpleair_api_dag
AIRFLOW_CTX_TASK_ID=fetch_data
AIRFLOW_CTX_EXECUTION_DATE=2024-05-21T07:00:00+00:00
AIRFLOW_CTX_DAG_RUN_ID=scheduled__2024-05-21T07:00:00+00:00
[2024-05-22 02:20:25,197] {logging_mixin.py:109} INFO - Failed to retrieve data: 403
[2024-05-22 02:20:25,198] {python.py:175} INFO - Done. Returned value was: None
[2024-05-22 02:20:25,425] {taskinstance.py:1277} INFO - Marking task as SUCCESS. dag_id=purpleair_api_dag, task_id=fetch_data, execution_date=20240521T070000, start_date=20240522T022023, end_date=20240522T022025
[2024-05-22 02:20:25,518] {local_task_job.py:154} INFO - Task exited with return code 0
[2024-05-22 02:20:25,592] {local_task_job.py:264} INFO - 0 downstream tasks scheduled from follow-on schedule check
[2024-05-22 04:14:10,564] {taskinstance.py:1032} INFO - Dependencies all met for <TaskInstance: purpleair_api_dag.fetch_data scheduled__2024-05-21T07:00:00+00:00 [queued]>
[2024-05-22 04:14:10,714] {taskinstance.py:1032} INFO - Dependencies all met for <TaskInstance: purpleair_api_dag.fetch_data scheduled__2024-05-21T07:00:00+00:00 [queued]>
[2024-05-22 04:14:10,715] {taskinstance.py:1238} INFO - 
--------------------------------------------------------------------------------
[2024-05-22 04:14:10,715] {taskinstance.py:1239} INFO - Starting attempt 1 of 2
[2024-05-22 04:14:10,725] {taskinstance.py:1240} INFO - 
--------------------------------------------------------------------------------
[2024-05-22 04:14:10,870] {taskinstance.py:1259} INFO - Executing <Task(PythonOperator): fetch_data> on 2024-05-21 07:00:00+00:00
[2024-05-22 04:14:10,988] {standard_task_runner.py:52} INFO - Started process 144 to run task
[2024-05-22 04:14:11,046] {standard_task_runner.py:76} INFO - Running: ['***', 'tasks', 'run', 'purpleair_api_dag', 'fetch_data', 'scheduled__2024-05-21T07:00:00+00:00', '--job-id', '11', '--raw', '--subdir', 'DAGS_FOLDER/data_ingestion.py', '--cfg-path', '/tmp/tmp3hpjm6s5', '--error-file', '/tmp/tmpvxwz77vm']
[2024-05-22 04:14:11,173] {standard_task_runner.py:77} INFO - Job 11: Subtask fetch_data
[2024-05-22 04:14:11,855] {logging_mixin.py:109} INFO - Running <TaskInstance: purpleair_api_dag.fetch_data scheduled__2024-05-21T07:00:00+00:00 [running]> on host 3419eee920a5
[2024-05-22 04:14:12,429] {taskinstance.py:1426} INFO - Exporting the following env vars:
AIRFLOW_CTX_DAG_OWNER=***
AIRFLOW_CTX_DAG_ID=purpleair_api_dag
AIRFLOW_CTX_TASK_ID=fetch_data
AIRFLOW_CTX_EXECUTION_DATE=2024-05-21T07:00:00+00:00
AIRFLOW_CTX_DAG_RUN_ID=scheduled__2024-05-21T07:00:00+00:00
[2024-05-22 04:14:12,450] {taskinstance.py:1700} ERROR - Task failed with exception
Traceback (most recent call last):
  File "/home/airflow/.local/lib/python3.6/site-packages/airflow/models/taskinstance.py", line 1329, in _run_raw_task
    self._execute_task_with_callbacks(context)
  File "/home/airflow/.local/lib/python3.6/site-packages/airflow/models/taskinstance.py", line 1455, in _execute_task_with_callbacks
    result = self._execute_task(context, self.task)
  File "/home/airflow/.local/lib/python3.6/site-packages/airflow/models/taskinstance.py", line 1511, in _execute_task
    result = execute_callable(context=context)
  File "/home/airflow/.local/lib/python3.6/site-packages/airflow/operators/python.py", line 174, in execute
    return_value = self.execute_callable()
  File "/home/airflow/.local/lib/python3.6/site-packages/airflow/operators/python.py", line 185, in execute_callable
    return self.python_callable(*self.op_args, **self.op_kwargs)
  File "/opt/airflow/dags/data_ingestion.py", line 67, in api_url
    print(f" url is {url}")
NameError: name 'url' is not defined
[2024-05-22 04:14:12,570] {taskinstance.py:1277} INFO - Marking task as UP_FOR_RETRY. dag_id=purpleair_api_dag, task_id=fetch_data, execution_date=20240521T070000, start_date=20240522T041410, end_date=20240522T041412
[2024-05-22 04:14:12,782] {standard_task_runner.py:92} ERROR - Failed to execute job 11 for task fetch_data
Traceback (most recent call last):
  File "/home/airflow/.local/lib/python3.6/site-packages/airflow/task/task_runner/standard_task_runner.py", line 85, in _start_by_fork
    args.func(args, dag=self.dag)
  File "/home/airflow/.local/lib/python3.6/site-packages/airflow/cli/cli_parser.py", line 48, in command
    return func(*args, **kwargs)
  File "/home/airflow/.local/lib/python3.6/site-packages/airflow/utils/cli.py", line 92, in wrapper
    return f(*args, **kwargs)
  File "/home/airflow/.local/lib/python3.6/site-packages/airflow/cli/commands/task_command.py", line 298, in task_run
    _run_task_by_selected_method(args, dag, ti)
  File "/home/airflow/.local/lib/python3.6/site-packages/airflow/cli/commands/task_command.py", line 107, in _run_task_by_selected_method
    _run_raw_task(args, ti)
  File "/home/airflow/.local/lib/python3.6/site-packages/airflow/cli/commands/task_command.py", line 184, in _run_raw_task
    error_file=args.error_file,
  File "/home/airflow/.local/lib/python3.6/site-packages/airflow/utils/session.py", line 70, in wrapper
    return func(*args, session=session, **kwargs)
  File "/home/airflow/.local/lib/python3.6/site-packages/airflow/models/taskinstance.py", line 1329, in _run_raw_task
    self._execute_task_with_callbacks(context)
  File "/home/airflow/.local/lib/python3.6/site-packages/airflow/models/taskinstance.py", line 1455, in _execute_task_with_callbacks
    result = self._execute_task(context, self.task)
  File "/home/airflow/.local/lib/python3.6/site-packages/airflow/models/taskinstance.py", line 1511, in _execute_task
    result = execute_callable(context=context)
  File "/home/airflow/.local/lib/python3.6/site-packages/airflow/operators/python.py", line 174, in execute
    return_value = self.execute_callable()
  File "/home/airflow/.local/lib/python3.6/site-packages/airflow/operators/python.py", line 185, in execute_callable
    return self.python_callable(*self.op_args, **self.op_kwargs)
  File "/opt/airflow/dags/data_ingestion.py", line 67, in api_url
    print(f" url is {url}")
NameError: name 'url' is not defined
[2024-05-22 04:14:12,916] {local_task_job.py:154} INFO - Task exited with return code 1
[2024-05-22 04:14:13,433] {local_task_job.py:264} INFO - 0 downstream tasks scheduled from follow-on schedule check
[2024-05-22 04:17:37,394] {taskinstance.py:1032} INFO - Dependencies all met for <TaskInstance: purpleair_api_dag.fetch_data scheduled__2024-05-21T07:00:00+00:00 [queued]>
[2024-05-22 04:17:37,527] {taskinstance.py:1032} INFO - Dependencies all met for <TaskInstance: purpleair_api_dag.fetch_data scheduled__2024-05-21T07:00:00+00:00 [queued]>
[2024-05-22 04:17:37,527] {taskinstance.py:1238} INFO - 
--------------------------------------------------------------------------------
[2024-05-22 04:17:37,528] {taskinstance.py:1239} INFO - Starting attempt 1 of 2
[2024-05-22 04:17:37,528] {taskinstance.py:1240} INFO - 
--------------------------------------------------------------------------------
[2024-05-22 04:17:37,616] {taskinstance.py:1259} INFO - Executing <Task(PythonOperator): fetch_data> on 2024-05-21 07:00:00+00:00
[2024-05-22 04:17:37,630] {standard_task_runner.py:52} INFO - Started process 336 to run task
[2024-05-22 04:17:37,680] {standard_task_runner.py:76} INFO - Running: ['***', 'tasks', 'run', 'purpleair_api_dag', 'fetch_data', 'scheduled__2024-05-21T07:00:00+00:00', '--job-id', '27', '--raw', '--subdir', 'DAGS_FOLDER/data_ingestion.py', '--cfg-path', '/tmp/tmp52vhvwmb', '--error-file', '/tmp/tmpdqdm4ef7']
[2024-05-22 04:17:37,767] {standard_task_runner.py:77} INFO - Job 27: Subtask fetch_data
[2024-05-22 04:17:38,320] {logging_mixin.py:109} INFO - Running <TaskInstance: purpleair_api_dag.fetch_data scheduled__2024-05-21T07:00:00+00:00 [running]> on host 3419eee920a5
[2024-05-22 04:17:38,779] {taskinstance.py:1426} INFO - Exporting the following env vars:
AIRFLOW_CTX_DAG_OWNER=***
AIRFLOW_CTX_DAG_ID=purpleair_api_dag
AIRFLOW_CTX_TASK_ID=fetch_data
AIRFLOW_CTX_EXECUTION_DATE=2024-05-21T07:00:00+00:00
AIRFLOW_CTX_DAG_RUN_ID=scheduled__2024-05-21T07:00:00+00:00
[2024-05-22 04:17:38,819] {logging_mixin.py:109} INFO -  api is None
[2024-05-22 04:17:38,843] {logging_mixin.py:109} INFO - Full URL: https://api.purpleair.com/v1/sensors?fields=latitude%2Clongitude%2Chumidity%2Cpm2.5_60minute%2Clast_seen&location_type=0&max_age=300
[2024-05-22 04:17:38,852] {logging_mixin.py:109} INFO - Headers: {'X-API-Key': 'None'}
[2024-05-22 04:17:39,076] {logging_mixin.py:109} INFO - Status Code: 403
[2024-05-22 04:17:39,098] {logging_mixin.py:109} INFO - Response Content: {
  "api_version" : "V1.0.13-0.0.56",
  "time_stamp" : 1716351459,
  "error" : "ApiKeyInvalidError",
  "description" : "The provided api_key was not valid."
}
[2024-05-22 04:17:39,211] {logging_mixin.py:109} INFO - Failed to retrieve data: 403
[2024-05-22 04:17:39,252] {python.py:175} INFO - Done. Returned value was: None
[2024-05-22 04:17:39,293] {taskinstance.py:1277} INFO - Marking task as SUCCESS. dag_id=purpleair_api_dag, task_id=fetch_data, execution_date=20240521T070000, start_date=20240522T041737, end_date=20240522T041739
[2024-05-22 04:17:39,409] {local_task_job.py:154} INFO - Task exited with return code 0
[2024-05-22 04:17:39,496] {local_task_job.py:264} INFO - 0 downstream tasks scheduled from follow-on schedule check
