[2024-05-22 06:55:31,835] {taskinstance.py:1032} INFO - Dependencies all met for <TaskInstance: purpleair_api_dag.format_to_parquet_task scheduled__2024-05-21T07:00:00+00:00 [queued]>
[2024-05-22 06:55:31,856] {taskinstance.py:1032} INFO - Dependencies all met for <TaskInstance: purpleair_api_dag.format_to_parquet_task scheduled__2024-05-21T07:00:00+00:00 [queued]>
[2024-05-22 06:55:31,857] {taskinstance.py:1238} INFO - 
--------------------------------------------------------------------------------
[2024-05-22 06:55:31,858] {taskinstance.py:1239} INFO - Starting attempt 2 of 2
[2024-05-22 06:55:31,858] {taskinstance.py:1240} INFO - 
--------------------------------------------------------------------------------
[2024-05-22 06:55:31,886] {taskinstance.py:1259} INFO - Executing <Task(PythonOperator): format_to_parquet_task> on 2024-05-21 07:00:00+00:00
[2024-05-22 06:55:31,898] {standard_task_runner.py:52} INFO - Started process 464 to run task
[2024-05-22 06:55:31,919] {standard_task_runner.py:76} INFO - Running: ['***', 'tasks', 'run', 'purpleair_api_dag', 'format_to_parquet_task', 'scheduled__2024-05-21T07:00:00+00:00', '--job-id', '37', '--raw', '--subdir', 'DAGS_FOLDER/data_ingestion.py', '--cfg-path', '/tmp/tmpzr01733z', '--error-file', '/tmp/tmpk5gh27xf']
[2024-05-22 06:55:31,928] {standard_task_runner.py:77} INFO - Job 37: Subtask format_to_parquet_task
[2024-05-22 06:55:32,113] {logging_mixin.py:109} INFO - Running <TaskInstance: purpleair_api_dag.format_to_parquet_task scheduled__2024-05-21T07:00:00+00:00 [running]> on host 148b4063f71c
[2024-05-22 06:55:32,273] {warnings.py:99} WARNING - /home/***/.local/lib/python3.6/site-packages/***/utils/context.py:152: AirflowContextDeprecationWarning: Accessing 'execution_date' from the template is deprecated and will be removed in a future version. Please use 'data_interval_start' or 'logical_date' instead.
  warnings.warn(_create_deprecation_warning(key, self._deprecation_replacements[key]))

[2024-05-22 06:55:32,364] {taskinstance.py:1426} INFO - Exporting the following env vars:
AIRFLOW_CTX_DAG_OWNER=***
AIRFLOW_CTX_DAG_ID=purpleair_api_dag
AIRFLOW_CTX_TASK_ID=format_to_parquet_task
AIRFLOW_CTX_EXECUTION_DATE=2024-05-21T07:00:00+00:00
AIRFLOW_CTX_DAG_RUN_ID=scheduled__2024-05-21T07:00:00+00:00
[2024-05-22 06:55:32,366] {taskinstance.py:1700} ERROR - Task failed with exception
Traceback (most recent call last):
  File "/home/airflow/.local/lib/python3.6/site-packages/airflow/models/taskinstance.py", line 1329, in _run_raw_task
    self._execute_task_with_callbacks(context)
  File "/home/airflow/.local/lib/python3.6/site-packages/airflow/models/taskinstance.py", line 1455, in _execute_task_with_callbacks
    result = self._execute_task(context, self.task)
  File "/home/airflow/.local/lib/python3.6/site-packages/airflow/models/taskinstance.py", line 1511, in _execute_task
    result = execute_callable(context=context)
  File "/home/airflow/.local/lib/python3.6/site-packages/airflow/operators/python.py", line 174, in execute
    return_value = self.execute_callable()
  File "/home/airflow/.local/lib/python3.6/site-packages/airflow/operators/python.py", line 185, in execute_callable
    return self.python_callable(*self.op_args, **self.op_kwargs)
  File "/opt/airflow/dags/data_ingestion.py", line 110, in format_to_parquet
    fields = glom(src_file, 'fields')
TypeError: 'module' object is not callable
[2024-05-22 06:55:32,427] {taskinstance.py:1277} INFO - Marking task as FAILED. dag_id=purpleair_api_dag, task_id=format_to_parquet_task, execution_date=20240521T070000, start_date=20240522T065531, end_date=20240522T065532
[2024-05-22 06:55:32,483] {standard_task_runner.py:92} ERROR - Failed to execute job 37 for task format_to_parquet_task
Traceback (most recent call last):
  File "/home/airflow/.local/lib/python3.6/site-packages/airflow/task/task_runner/standard_task_runner.py", line 85, in _start_by_fork
    args.func(args, dag=self.dag)
  File "/home/airflow/.local/lib/python3.6/site-packages/airflow/cli/cli_parser.py", line 48, in command
    return func(*args, **kwargs)
  File "/home/airflow/.local/lib/python3.6/site-packages/airflow/utils/cli.py", line 92, in wrapper
    return f(*args, **kwargs)
  File "/home/airflow/.local/lib/python3.6/site-packages/airflow/cli/commands/task_command.py", line 298, in task_run
    _run_task_by_selected_method(args, dag, ti)
  File "/home/airflow/.local/lib/python3.6/site-packages/airflow/cli/commands/task_command.py", line 107, in _run_task_by_selected_method
    _run_raw_task(args, ti)
  File "/home/airflow/.local/lib/python3.6/site-packages/airflow/cli/commands/task_command.py", line 184, in _run_raw_task
    error_file=args.error_file,
  File "/home/airflow/.local/lib/python3.6/site-packages/airflow/utils/session.py", line 70, in wrapper
    return func(*args, session=session, **kwargs)
  File "/home/airflow/.local/lib/python3.6/site-packages/airflow/models/taskinstance.py", line 1329, in _run_raw_task
    self._execute_task_with_callbacks(context)
  File "/home/airflow/.local/lib/python3.6/site-packages/airflow/models/taskinstance.py", line 1455, in _execute_task_with_callbacks
    result = self._execute_task(context, self.task)
  File "/home/airflow/.local/lib/python3.6/site-packages/airflow/models/taskinstance.py", line 1511, in _execute_task
    result = execute_callable(context=context)
  File "/home/airflow/.local/lib/python3.6/site-packages/airflow/operators/python.py", line 174, in execute
    return_value = self.execute_callable()
  File "/home/airflow/.local/lib/python3.6/site-packages/airflow/operators/python.py", line 185, in execute_callable
    return self.python_callable(*self.op_args, **self.op_kwargs)
  File "/opt/airflow/dags/data_ingestion.py", line 110, in format_to_parquet
    fields = glom(src_file, 'fields')
TypeError: 'module' object is not callable
[2024-05-22 06:55:32,528] {local_task_job.py:154} INFO - Task exited with return code 1
[2024-05-22 06:55:33,011] {local_task_job.py:264} INFO - 0 downstream tasks scheduled from follow-on schedule check
[2024-05-22 07:04:35,910] {taskinstance.py:1032} INFO - Dependencies all met for <TaskInstance: purpleair_api_dag.format_to_parquet_task scheduled__2024-05-21T07:00:00+00:00 [queued]>
[2024-05-22 07:04:36,057] {taskinstance.py:1032} INFO - Dependencies all met for <TaskInstance: purpleair_api_dag.format_to_parquet_task scheduled__2024-05-21T07:00:00+00:00 [queued]>
[2024-05-22 07:04:36,057] {taskinstance.py:1238} INFO - 
--------------------------------------------------------------------------------
[2024-05-22 07:04:36,057] {taskinstance.py:1239} INFO - Starting attempt 2 of 2
[2024-05-22 07:04:36,058] {taskinstance.py:1240} INFO - 
--------------------------------------------------------------------------------
[2024-05-22 07:04:36,165] {taskinstance.py:1259} INFO - Executing <Task(PythonOperator): format_to_parquet_task> on 2024-05-21 07:00:00+00:00
[2024-05-22 07:04:36,235] {standard_task_runner.py:52} INFO - Started process 1069 to run task
[2024-05-22 07:04:36,319] {standard_task_runner.py:76} INFO - Running: ['***', 'tasks', 'run', 'purpleair_api_dag', 'format_to_parquet_task', 'scheduled__2024-05-21T07:00:00+00:00', '--job-id', '122', '--raw', '--subdir', 'DAGS_FOLDER/data_ingestion.py', '--cfg-path', '/tmp/tmpt8m_x9sv', '--error-file', '/tmp/tmpag7dqq9v']
[2024-05-22 07:04:36,375] {standard_task_runner.py:77} INFO - Job 122: Subtask format_to_parquet_task
[2024-05-22 07:04:36,742] {logging_mixin.py:109} INFO - Running <TaskInstance: purpleair_api_dag.format_to_parquet_task scheduled__2024-05-21T07:00:00+00:00 [running]> on host 148b4063f71c
[2024-05-22 07:04:37,174] {warnings.py:99} WARNING - /home/***/.local/lib/python3.6/site-packages/***/utils/context.py:152: AirflowContextDeprecationWarning: Accessing 'execution_date' from the template is deprecated and will be removed in a future version. Please use 'data_interval_start' or 'logical_date' instead.
  warnings.warn(_create_deprecation_warning(key, self._deprecation_replacements[key]))

[2024-05-22 07:04:37,306] {taskinstance.py:1426} INFO - Exporting the following env vars:
AIRFLOW_CTX_DAG_OWNER=***
AIRFLOW_CTX_DAG_ID=purpleair_api_dag
AIRFLOW_CTX_TASK_ID=format_to_parquet_task
AIRFLOW_CTX_EXECUTION_DATE=2024-05-21T07:00:00+00:00
AIRFLOW_CTX_DAG_RUN_ID=scheduled__2024-05-21T07:00:00+00:00
[2024-05-22 07:04:37,326] {taskinstance.py:1700} ERROR - Task failed with exception
Traceback (most recent call last):
  File "/home/airflow/.local/lib/python3.6/site-packages/airflow/models/taskinstance.py", line 1329, in _run_raw_task
    self._execute_task_with_callbacks(context)
  File "/home/airflow/.local/lib/python3.6/site-packages/airflow/models/taskinstance.py", line 1455, in _execute_task_with_callbacks
    result = self._execute_task(context, self.task)
  File "/home/airflow/.local/lib/python3.6/site-packages/airflow/models/taskinstance.py", line 1511, in _execute_task
    result = execute_callable(context=context)
  File "/home/airflow/.local/lib/python3.6/site-packages/airflow/operators/python.py", line 174, in execute
    return_value = self.execute_callable()
  File "/home/airflow/.local/lib/python3.6/site-packages/airflow/operators/python.py", line 185, in execute_callable
    return self.python_callable(*self.op_args, **self.op_kwargs)
  File "/opt/airflow/dags/data_ingestion.py", line 110, in format_to_parquet
    fields = glom(src_file, 'fields')
  File "/home/airflow/.local/lib/python3.6/site-packages/glom/core.py", line 2296, in glom
    raise err
glom.core.PathAccessError: error raised while processing, details below.
 Target-spec trace (most recent last):
 - Target: '/opt/airflow/2024-05-21-7.json'
 - Spec: 'fields'
glom.core.PathAccessError: could not access 'fields', part 0 of Path('fields'), got error: AttributeError("'str' object has no attribute 'fields'",)
[2024-05-22 07:04:37,399] {taskinstance.py:1277} INFO - Marking task as FAILED. dag_id=purpleair_api_dag, task_id=format_to_parquet_task, execution_date=20240521T070000, start_date=20240522T070435, end_date=20240522T070437
[2024-05-22 07:04:37,653] {standard_task_runner.py:92} ERROR - Failed to execute job 122 for task format_to_parquet_task
Traceback (most recent call last):
  File "/home/airflow/.local/lib/python3.6/site-packages/airflow/task/task_runner/standard_task_runner.py", line 85, in _start_by_fork
    args.func(args, dag=self.dag)
  File "/home/airflow/.local/lib/python3.6/site-packages/airflow/cli/cli_parser.py", line 48, in command
    return func(*args, **kwargs)
  File "/home/airflow/.local/lib/python3.6/site-packages/airflow/utils/cli.py", line 92, in wrapper
    return f(*args, **kwargs)
  File "/home/airflow/.local/lib/python3.6/site-packages/airflow/cli/commands/task_command.py", line 298, in task_run
    _run_task_by_selected_method(args, dag, ti)
  File "/home/airflow/.local/lib/python3.6/site-packages/airflow/cli/commands/task_command.py", line 107, in _run_task_by_selected_method
    _run_raw_task(args, ti)
  File "/home/airflow/.local/lib/python3.6/site-packages/airflow/cli/commands/task_command.py", line 184, in _run_raw_task
    error_file=args.error_file,
  File "/home/airflow/.local/lib/python3.6/site-packages/airflow/utils/session.py", line 70, in wrapper
    return func(*args, session=session, **kwargs)
  File "/home/airflow/.local/lib/python3.6/site-packages/airflow/models/taskinstance.py", line 1329, in _run_raw_task
    self._execute_task_with_callbacks(context)
  File "/home/airflow/.local/lib/python3.6/site-packages/airflow/models/taskinstance.py", line 1455, in _execute_task_with_callbacks
    result = self._execute_task(context, self.task)
  File "/home/airflow/.local/lib/python3.6/site-packages/airflow/models/taskinstance.py", line 1511, in _execute_task
    result = execute_callable(context=context)
  File "/home/airflow/.local/lib/python3.6/site-packages/airflow/operators/python.py", line 174, in execute
    return_value = self.execute_callable()
  File "/home/airflow/.local/lib/python3.6/site-packages/airflow/operators/python.py", line 185, in execute_callable
    return self.python_callable(*self.op_args, **self.op_kwargs)
  File "/opt/airflow/dags/data_ingestion.py", line 110, in format_to_parquet
    fields = glom(src_file, 'fields')
  File "/home/airflow/.local/lib/python3.6/site-packages/glom/core.py", line 2296, in glom
    raise err
glom.core.PathAccessError: error raised while processing, details below.
 Target-spec trace (most recent last):
 - Target: '/opt/airflow/2024-05-21-7.json'
 - Spec: 'fields'
glom.core.PathAccessError: could not access 'fields', part 0 of Path('fields'), got error: AttributeError("'str' object has no attribute 'fields'",)
[2024-05-22 07:04:37,786] {local_task_job.py:154} INFO - Task exited with return code 1
[2024-05-22 07:04:38,144] {local_task_job.py:264} INFO - 0 downstream tasks scheduled from follow-on schedule check
[2024-05-22 07:12:24,749] {taskinstance.py:1032} INFO - Dependencies all met for <TaskInstance: purpleair_api_dag.format_to_parquet_task scheduled__2024-05-21T07:00:00+00:00 [queued]>
[2024-05-22 07:12:24,913] {taskinstance.py:1032} INFO - Dependencies all met for <TaskInstance: purpleair_api_dag.format_to_parquet_task scheduled__2024-05-21T07:00:00+00:00 [queued]>
[2024-05-22 07:12:24,913] {taskinstance.py:1238} INFO - 
--------------------------------------------------------------------------------
[2024-05-22 07:12:24,913] {taskinstance.py:1239} INFO - Starting attempt 2 of 2
[2024-05-22 07:12:24,914] {taskinstance.py:1240} INFO - 
--------------------------------------------------------------------------------
[2024-05-22 07:12:25,012] {taskinstance.py:1259} INFO - Executing <Task(PythonOperator): format_to_parquet_task> on 2024-05-21 07:00:00+00:00
[2024-05-22 07:12:25,049] {standard_task_runner.py:52} INFO - Started process 1603 to run task
[2024-05-22 07:12:25,068] {standard_task_runner.py:76} INFO - Running: ['***', 'tasks', 'run', 'purpleair_api_dag', 'format_to_parquet_task', 'scheduled__2024-05-21T07:00:00+00:00', '--job-id', '205', '--raw', '--subdir', 'DAGS_FOLDER/data_ingestion.py', '--cfg-path', '/tmp/tmpdqvmbnzd', '--error-file', '/tmp/tmptzba3d75']
[2024-05-22 07:12:25,087] {standard_task_runner.py:77} INFO - Job 205: Subtask format_to_parquet_task
[2024-05-22 07:12:25,402] {logging_mixin.py:109} INFO - Running <TaskInstance: purpleair_api_dag.format_to_parquet_task scheduled__2024-05-21T07:00:00+00:00 [running]> on host 148b4063f71c
[2024-05-22 07:12:25,719] {warnings.py:99} WARNING - /home/***/.local/lib/python3.6/site-packages/***/utils/context.py:152: AirflowContextDeprecationWarning: Accessing 'execution_date' from the template is deprecated and will be removed in a future version. Please use 'data_interval_start' or 'logical_date' instead.
  warnings.warn(_create_deprecation_warning(key, self._deprecation_replacements[key]))

[2024-05-22 07:12:25,873] {taskinstance.py:1426} INFO - Exporting the following env vars:
AIRFLOW_CTX_DAG_OWNER=***
AIRFLOW_CTX_DAG_ID=purpleair_api_dag
AIRFLOW_CTX_TASK_ID=format_to_parquet_task
AIRFLOW_CTX_EXECUTION_DATE=2024-05-21T07:00:00+00:00
AIRFLOW_CTX_DAG_RUN_ID=scheduled__2024-05-21T07:00:00+00:00
[2024-05-22 07:12:25,874] {taskinstance.py:1700} ERROR - Task failed with exception
Traceback (most recent call last):
  File "/home/airflow/.local/lib/python3.6/site-packages/airflow/models/taskinstance.py", line 1329, in _run_raw_task
    self._execute_task_with_callbacks(context)
  File "/home/airflow/.local/lib/python3.6/site-packages/airflow/models/taskinstance.py", line 1455, in _execute_task_with_callbacks
    result = self._execute_task(context, self.task)
  File "/home/airflow/.local/lib/python3.6/site-packages/airflow/models/taskinstance.py", line 1511, in _execute_task
    result = execute_callable(context=context)
  File "/home/airflow/.local/lib/python3.6/site-packages/airflow/operators/python.py", line 174, in execute
    return_value = self.execute_callable()
  File "/home/airflow/.local/lib/python3.6/site-packages/airflow/operators/python.py", line 185, in execute_callable
    return self.python_callable(*self.op_args, **self.op_kwargs)
  File "/opt/airflow/dags/data_ingestion.py", line 108, in format_to_parquet
    with open(src_file, 'r') as file:
FileNotFoundError: [Errno 2] No such file or directory: '/opt/airflow/2024-05-21-7.json'
[2024-05-22 07:12:25,934] {taskinstance.py:1277} INFO - Marking task as FAILED. dag_id=purpleair_api_dag, task_id=format_to_parquet_task, execution_date=20240521T070000, start_date=20240522T071224, end_date=20240522T071225
[2024-05-22 07:12:26,101] {standard_task_runner.py:92} ERROR - Failed to execute job 205 for task format_to_parquet_task
Traceback (most recent call last):
  File "/home/airflow/.local/lib/python3.6/site-packages/airflow/task/task_runner/standard_task_runner.py", line 85, in _start_by_fork
    args.func(args, dag=self.dag)
  File "/home/airflow/.local/lib/python3.6/site-packages/airflow/cli/cli_parser.py", line 48, in command
    return func(*args, **kwargs)
  File "/home/airflow/.local/lib/python3.6/site-packages/airflow/utils/cli.py", line 92, in wrapper
    return f(*args, **kwargs)
  File "/home/airflow/.local/lib/python3.6/site-packages/airflow/cli/commands/task_command.py", line 298, in task_run
    _run_task_by_selected_method(args, dag, ti)
  File "/home/airflow/.local/lib/python3.6/site-packages/airflow/cli/commands/task_command.py", line 107, in _run_task_by_selected_method
    _run_raw_task(args, ti)
  File "/home/airflow/.local/lib/python3.6/site-packages/airflow/cli/commands/task_command.py", line 184, in _run_raw_task
    error_file=args.error_file,
  File "/home/airflow/.local/lib/python3.6/site-packages/airflow/utils/session.py", line 70, in wrapper
    return func(*args, session=session, **kwargs)
  File "/home/airflow/.local/lib/python3.6/site-packages/airflow/models/taskinstance.py", line 1329, in _run_raw_task
    self._execute_task_with_callbacks(context)
  File "/home/airflow/.local/lib/python3.6/site-packages/airflow/models/taskinstance.py", line 1455, in _execute_task_with_callbacks
    result = self._execute_task(context, self.task)
  File "/home/airflow/.local/lib/python3.6/site-packages/airflow/models/taskinstance.py", line 1511, in _execute_task
    result = execute_callable(context=context)
  File "/home/airflow/.local/lib/python3.6/site-packages/airflow/operators/python.py", line 174, in execute
    return_value = self.execute_callable()
  File "/home/airflow/.local/lib/python3.6/site-packages/airflow/operators/python.py", line 185, in execute_callable
    return self.python_callable(*self.op_args, **self.op_kwargs)
  File "/opt/airflow/dags/data_ingestion.py", line 108, in format_to_parquet
    with open(src_file, 'r') as file:
FileNotFoundError: [Errno 2] No such file or directory: '/opt/airflow/2024-05-21-7.json'
[2024-05-22 07:12:26,177] {local_task_job.py:154} INFO - Task exited with return code 1
[2024-05-22 07:12:26,486] {local_task_job.py:264} INFO - 0 downstream tasks scheduled from follow-on schedule check
[2024-05-22 07:22:02,908] {taskinstance.py:1032} INFO - Dependencies all met for <TaskInstance: purpleair_api_dag.format_to_parquet_task scheduled__2024-05-21T07:00:00+00:00 [queued]>
[2024-05-22 07:22:03,014] {taskinstance.py:1032} INFO - Dependencies all met for <TaskInstance: purpleair_api_dag.format_to_parquet_task scheduled__2024-05-21T07:00:00+00:00 [queued]>
[2024-05-22 07:22:03,020] {taskinstance.py:1238} INFO - 
--------------------------------------------------------------------------------
[2024-05-22 07:22:03,021] {taskinstance.py:1239} INFO - Starting attempt 2 of 2
[2024-05-22 07:22:03,022] {taskinstance.py:1240} INFO - 
--------------------------------------------------------------------------------
[2024-05-22 07:22:03,100] {taskinstance.py:1259} INFO - Executing <Task(PythonOperator): format_to_parquet_task> on 2024-05-21 07:00:00+00:00
[2024-05-22 07:22:03,146] {standard_task_runner.py:52} INFO - Started process 2292 to run task
[2024-05-22 07:22:03,187] {standard_task_runner.py:76} INFO - Running: ['***', 'tasks', 'run', 'purpleair_api_dag', 'format_to_parquet_task', 'scheduled__2024-05-21T07:00:00+00:00', '--job-id', '313', '--raw', '--subdir', 'DAGS_FOLDER/data_ingestion.py', '--cfg-path', '/tmp/tmpii0r4mc1', '--error-file', '/tmp/tmpj6rfew_6']
[2024-05-22 07:22:03,228] {standard_task_runner.py:77} INFO - Job 313: Subtask format_to_parquet_task
[2024-05-22 07:22:03,555] {logging_mixin.py:109} INFO - Running <TaskInstance: purpleair_api_dag.format_to_parquet_task scheduled__2024-05-21T07:00:00+00:00 [running]> on host 148b4063f71c
[2024-05-22 07:22:03,813] {warnings.py:99} WARNING - /home/***/.local/lib/python3.6/site-packages/***/utils/context.py:152: AirflowContextDeprecationWarning: Accessing 'execution_date' from the template is deprecated and will be removed in a future version. Please use 'data_interval_start' or 'logical_date' instead.
  warnings.warn(_create_deprecation_warning(key, self._deprecation_replacements[key]))

[2024-05-22 07:22:03,898] {taskinstance.py:1426} INFO - Exporting the following env vars:
AIRFLOW_CTX_DAG_OWNER=***
AIRFLOW_CTX_DAG_ID=purpleair_api_dag
AIRFLOW_CTX_TASK_ID=format_to_parquet_task
AIRFLOW_CTX_EXECUTION_DATE=2024-05-21T07:00:00+00:00
AIRFLOW_CTX_DAG_RUN_ID=scheduled__2024-05-21T07:00:00+00:00
[2024-05-22 07:22:03,899] {taskinstance.py:1700} ERROR - Task failed with exception
Traceback (most recent call last):
  File "/home/airflow/.local/lib/python3.6/site-packages/airflow/models/taskinstance.py", line 1329, in _run_raw_task
    self._execute_task_with_callbacks(context)
  File "/home/airflow/.local/lib/python3.6/site-packages/airflow/models/taskinstance.py", line 1455, in _execute_task_with_callbacks
    result = self._execute_task(context, self.task)
  File "/home/airflow/.local/lib/python3.6/site-packages/airflow/models/taskinstance.py", line 1511, in _execute_task
    result = execute_callable(context=context)
  File "/home/airflow/.local/lib/python3.6/site-packages/airflow/operators/python.py", line 174, in execute
    return_value = self.execute_callable()
  File "/home/airflow/.local/lib/python3.6/site-packages/airflow/operators/python.py", line 185, in execute_callable
    return self.python_callable(*self.op_args, **self.op_kwargs)
  File "/opt/airflow/dags/data_ingestion.py", line 108, in format_to_parquet
    with open(src_file, 'r') as file:
FileNotFoundError: [Errno 2] No such file or directory: '/opt/airflow/2024-05-21-7.json'
[2024-05-22 07:22:03,924] {taskinstance.py:1277} INFO - Marking task as FAILED. dag_id=purpleair_api_dag, task_id=format_to_parquet_task, execution_date=20240521T070000, start_date=20240522T072202, end_date=20240522T072203
[2024-05-22 07:22:03,970] {standard_task_runner.py:92} ERROR - Failed to execute job 313 for task format_to_parquet_task
Traceback (most recent call last):
  File "/home/airflow/.local/lib/python3.6/site-packages/airflow/task/task_runner/standard_task_runner.py", line 85, in _start_by_fork
    args.func(args, dag=self.dag)
  File "/home/airflow/.local/lib/python3.6/site-packages/airflow/cli/cli_parser.py", line 48, in command
    return func(*args, **kwargs)
  File "/home/airflow/.local/lib/python3.6/site-packages/airflow/utils/cli.py", line 92, in wrapper
    return f(*args, **kwargs)
  File "/home/airflow/.local/lib/python3.6/site-packages/airflow/cli/commands/task_command.py", line 298, in task_run
    _run_task_by_selected_method(args, dag, ti)
  File "/home/airflow/.local/lib/python3.6/site-packages/airflow/cli/commands/task_command.py", line 107, in _run_task_by_selected_method
    _run_raw_task(args, ti)
  File "/home/airflow/.local/lib/python3.6/site-packages/airflow/cli/commands/task_command.py", line 184, in _run_raw_task
    error_file=args.error_file,
  File "/home/airflow/.local/lib/python3.6/site-packages/airflow/utils/session.py", line 70, in wrapper
    return func(*args, session=session, **kwargs)
  File "/home/airflow/.local/lib/python3.6/site-packages/airflow/models/taskinstance.py", line 1329, in _run_raw_task
    self._execute_task_with_callbacks(context)
  File "/home/airflow/.local/lib/python3.6/site-packages/airflow/models/taskinstance.py", line 1455, in _execute_task_with_callbacks
    result = self._execute_task(context, self.task)
  File "/home/airflow/.local/lib/python3.6/site-packages/airflow/models/taskinstance.py", line 1511, in _execute_task
    result = execute_callable(context=context)
  File "/home/airflow/.local/lib/python3.6/site-packages/airflow/operators/python.py", line 174, in execute
    return_value = self.execute_callable()
  File "/home/airflow/.local/lib/python3.6/site-packages/airflow/operators/python.py", line 185, in execute_callable
    return self.python_callable(*self.op_args, **self.op_kwargs)
  File "/opt/airflow/dags/data_ingestion.py", line 108, in format_to_parquet
    with open(src_file, 'r') as file:
FileNotFoundError: [Errno 2] No such file or directory: '/opt/airflow/2024-05-21-7.json'
[2024-05-22 07:22:04,030] {local_task_job.py:154} INFO - Task exited with return code 1
[2024-05-22 07:22:04,181] {local_task_job.py:264} INFO - 0 downstream tasks scheduled from follow-on schedule check
