[2024-05-22 06:50:35,175] {taskinstance.py:1032} INFO - Dependencies all met for <TaskInstance: purpleair_api_dag.format_to_parquet_task scheduled__2024-05-21T03:00:00+00:00 [queued]>
[2024-05-22 06:50:35,260] {taskinstance.py:1032} INFO - Dependencies all met for <TaskInstance: purpleair_api_dag.format_to_parquet_task scheduled__2024-05-21T03:00:00+00:00 [queued]>
[2024-05-22 06:50:35,261] {taskinstance.py:1238} INFO - 
--------------------------------------------------------------------------------
[2024-05-22 06:50:35,261] {taskinstance.py:1239} INFO - Starting attempt 1 of 2
[2024-05-22 06:50:35,261] {taskinstance.py:1240} INFO - 
--------------------------------------------------------------------------------
[2024-05-22 06:50:35,355] {taskinstance.py:1259} INFO - Executing <Task(PythonOperator): format_to_parquet_task> on 2024-05-21 03:00:00+00:00
[2024-05-22 06:50:35,389] {standard_task_runner.py:52} INFO - Started process 256 to run task
[2024-05-22 06:50:35,434] {standard_task_runner.py:76} INFO - Running: ['***', 'tasks', 'run', 'purpleair_api_dag', 'format_to_parquet_task', 'scheduled__2024-05-21T03:00:00+00:00', '--job-id', '32', '--raw', '--subdir', 'DAGS_FOLDER/data_ingestion.py', '--cfg-path', '/tmp/tmpcnth9tf7', '--error-file', '/tmp/tmp3_i_aa5x']
[2024-05-22 06:50:35,453] {standard_task_runner.py:77} INFO - Job 32: Subtask format_to_parquet_task
[2024-05-22 06:50:35,743] {logging_mixin.py:109} INFO - Running <TaskInstance: purpleair_api_dag.format_to_parquet_task scheduled__2024-05-21T03:00:00+00:00 [running]> on host 148b4063f71c
[2024-05-22 06:50:35,921] {warnings.py:99} WARNING - /home/***/.local/lib/python3.6/site-packages/***/utils/context.py:152: AirflowContextDeprecationWarning: Accessing 'execution_date' from the template is deprecated and will be removed in a future version. Please use 'data_interval_start' or 'logical_date' instead.
  warnings.warn(_create_deprecation_warning(key, self._deprecation_replacements[key]))

[2024-05-22 06:50:35,997] {taskinstance.py:1426} INFO - Exporting the following env vars:
AIRFLOW_CTX_DAG_OWNER=***
AIRFLOW_CTX_DAG_ID=purpleair_api_dag
AIRFLOW_CTX_TASK_ID=format_to_parquet_task
AIRFLOW_CTX_EXECUTION_DATE=2024-05-21T03:00:00+00:00
AIRFLOW_CTX_DAG_RUN_ID=scheduled__2024-05-21T03:00:00+00:00
[2024-05-22 06:50:35,998] {taskinstance.py:1700} ERROR - Task failed with exception
Traceback (most recent call last):
  File "/home/airflow/.local/lib/python3.6/site-packages/airflow/models/taskinstance.py", line 1329, in _run_raw_task
    self._execute_task_with_callbacks(context)
  File "/home/airflow/.local/lib/python3.6/site-packages/airflow/models/taskinstance.py", line 1455, in _execute_task_with_callbacks
    result = self._execute_task(context, self.task)
  File "/home/airflow/.local/lib/python3.6/site-packages/airflow/models/taskinstance.py", line 1511, in _execute_task
    result = execute_callable(context=context)
  File "/home/airflow/.local/lib/python3.6/site-packages/airflow/operators/python.py", line 174, in execute
    return_value = self.execute_callable()
  File "/home/airflow/.local/lib/python3.6/site-packages/airflow/operators/python.py", line 185, in execute_callable
    return self.python_callable(*self.op_args, **self.op_kwargs)
  File "/opt/airflow/dags/data_ingestion.py", line 110, in format_to_parquet
    fields = glom(src_file, 'fields')
TypeError: 'module' object is not callable
[2024-05-22 06:50:36,034] {taskinstance.py:1277} INFO - Marking task as UP_FOR_RETRY. dag_id=purpleair_api_dag, task_id=format_to_parquet_task, execution_date=20240521T030000, start_date=20240522T065035, end_date=20240522T065036
[2024-05-22 06:50:36,094] {standard_task_runner.py:92} ERROR - Failed to execute job 32 for task format_to_parquet_task
Traceback (most recent call last):
  File "/home/airflow/.local/lib/python3.6/site-packages/airflow/task/task_runner/standard_task_runner.py", line 85, in _start_by_fork
    args.func(args, dag=self.dag)
  File "/home/airflow/.local/lib/python3.6/site-packages/airflow/cli/cli_parser.py", line 48, in command
    return func(*args, **kwargs)
  File "/home/airflow/.local/lib/python3.6/site-packages/airflow/utils/cli.py", line 92, in wrapper
    return f(*args, **kwargs)
  File "/home/airflow/.local/lib/python3.6/site-packages/airflow/cli/commands/task_command.py", line 298, in task_run
    _run_task_by_selected_method(args, dag, ti)
  File "/home/airflow/.local/lib/python3.6/site-packages/airflow/cli/commands/task_command.py", line 107, in _run_task_by_selected_method
    _run_raw_task(args, ti)
  File "/home/airflow/.local/lib/python3.6/site-packages/airflow/cli/commands/task_command.py", line 184, in _run_raw_task
    error_file=args.error_file,
  File "/home/airflow/.local/lib/python3.6/site-packages/airflow/utils/session.py", line 70, in wrapper
    return func(*args, session=session, **kwargs)
  File "/home/airflow/.local/lib/python3.6/site-packages/airflow/models/taskinstance.py", line 1329, in _run_raw_task
    self._execute_task_with_callbacks(context)
  File "/home/airflow/.local/lib/python3.6/site-packages/airflow/models/taskinstance.py", line 1455, in _execute_task_with_callbacks
    result = self._execute_task(context, self.task)
  File "/home/airflow/.local/lib/python3.6/site-packages/airflow/models/taskinstance.py", line 1511, in _execute_task
    result = execute_callable(context=context)
  File "/home/airflow/.local/lib/python3.6/site-packages/airflow/operators/python.py", line 174, in execute
    return_value = self.execute_callable()
  File "/home/airflow/.local/lib/python3.6/site-packages/airflow/operators/python.py", line 185, in execute_callable
    return self.python_callable(*self.op_args, **self.op_kwargs)
  File "/opt/airflow/dags/data_ingestion.py", line 110, in format_to_parquet
    fields = glom(src_file, 'fields')
TypeError: 'module' object is not callable
[2024-05-22 06:50:36,139] {local_task_job.py:154} INFO - Task exited with return code 1
[2024-05-22 06:50:36,398] {local_task_job.py:264} INFO - 0 downstream tasks scheduled from follow-on schedule check
[2024-05-22 06:59:18,661] {taskinstance.py:1032} INFO - Dependencies all met for <TaskInstance: purpleair_api_dag.format_to_parquet_task scheduled__2024-05-21T03:00:00+00:00 [queued]>
[2024-05-22 06:59:18,798] {taskinstance.py:1032} INFO - Dependencies all met for <TaskInstance: purpleair_api_dag.format_to_parquet_task scheduled__2024-05-21T03:00:00+00:00 [queued]>
[2024-05-22 06:59:18,820] {taskinstance.py:1238} INFO - 
--------------------------------------------------------------------------------
[2024-05-22 06:59:18,824] {taskinstance.py:1239} INFO - Starting attempt 1 of 2
[2024-05-22 06:59:18,825] {taskinstance.py:1240} INFO - 
--------------------------------------------------------------------------------
[2024-05-22 06:59:18,913] {taskinstance.py:1259} INFO - Executing <Task(PythonOperator): format_to_parquet_task> on 2024-05-21 03:00:00+00:00
[2024-05-22 06:59:18,952] {standard_task_runner.py:52} INFO - Started process 802 to run task
[2024-05-22 06:59:18,966] {standard_task_runner.py:76} INFO - Running: ['***', 'tasks', 'run', 'purpleair_api_dag', 'format_to_parquet_task', 'scheduled__2024-05-21T03:00:00+00:00', '--job-id', '100', '--raw', '--subdir', 'DAGS_FOLDER/data_ingestion.py', '--cfg-path', '/tmp/tmpy13g3lix', '--error-file', '/tmp/tmpx17gvr6v']
[2024-05-22 06:59:19,042] {standard_task_runner.py:77} INFO - Job 100: Subtask format_to_parquet_task
[2024-05-22 06:59:19,302] {logging_mixin.py:109} INFO - Running <TaskInstance: purpleair_api_dag.format_to_parquet_task scheduled__2024-05-21T03:00:00+00:00 [running]> on host 148b4063f71c
[2024-05-22 06:59:19,457] {warnings.py:99} WARNING - /home/***/.local/lib/python3.6/site-packages/***/utils/context.py:152: AirflowContextDeprecationWarning: Accessing 'execution_date' from the template is deprecated and will be removed in a future version. Please use 'data_interval_start' or 'logical_date' instead.
  warnings.warn(_create_deprecation_warning(key, self._deprecation_replacements[key]))

[2024-05-22 06:59:19,573] {taskinstance.py:1426} INFO - Exporting the following env vars:
AIRFLOW_CTX_DAG_OWNER=***
AIRFLOW_CTX_DAG_ID=purpleair_api_dag
AIRFLOW_CTX_TASK_ID=format_to_parquet_task
AIRFLOW_CTX_EXECUTION_DATE=2024-05-21T03:00:00+00:00
AIRFLOW_CTX_DAG_RUN_ID=scheduled__2024-05-21T03:00:00+00:00
[2024-05-22 06:59:19,597] {taskinstance.py:1700} ERROR - Task failed with exception
Traceback (most recent call last):
  File "/home/airflow/.local/lib/python3.6/site-packages/airflow/models/taskinstance.py", line 1329, in _run_raw_task
    self._execute_task_with_callbacks(context)
  File "/home/airflow/.local/lib/python3.6/site-packages/airflow/models/taskinstance.py", line 1455, in _execute_task_with_callbacks
    result = self._execute_task(context, self.task)
  File "/home/airflow/.local/lib/python3.6/site-packages/airflow/models/taskinstance.py", line 1511, in _execute_task
    result = execute_callable(context=context)
  File "/home/airflow/.local/lib/python3.6/site-packages/airflow/operators/python.py", line 174, in execute
    return_value = self.execute_callable()
  File "/home/airflow/.local/lib/python3.6/site-packages/airflow/operators/python.py", line 185, in execute_callable
    return self.python_callable(*self.op_args, **self.op_kwargs)
  File "/opt/airflow/dags/data_ingestion.py", line 110, in format_to_parquet
    fields = glom(src_file, 'fields')
  File "/home/airflow/.local/lib/python3.6/site-packages/glom/core.py", line 2296, in glom
    raise err
glom.core.PathAccessError: error raised while processing, details below.
 Target-spec trace (most recent last):
 - Target: '/opt/airflow/2024-05-21-3.json'
 - Spec: 'fields'
glom.core.PathAccessError: could not access 'fields', part 0 of Path('fields'), got error: AttributeError("'str' object has no attribute 'fields'",)
[2024-05-22 06:59:19,740] {taskinstance.py:1277} INFO - Marking task as UP_FOR_RETRY. dag_id=purpleair_api_dag, task_id=format_to_parquet_task, execution_date=20240521T030000, start_date=20240522T065918, end_date=20240522T065919
[2024-05-22 06:59:19,868] {standard_task_runner.py:92} ERROR - Failed to execute job 100 for task format_to_parquet_task
Traceback (most recent call last):
  File "/home/airflow/.local/lib/python3.6/site-packages/airflow/task/task_runner/standard_task_runner.py", line 85, in _start_by_fork
    args.func(args, dag=self.dag)
  File "/home/airflow/.local/lib/python3.6/site-packages/airflow/cli/cli_parser.py", line 48, in command
    return func(*args, **kwargs)
  File "/home/airflow/.local/lib/python3.6/site-packages/airflow/utils/cli.py", line 92, in wrapper
    return f(*args, **kwargs)
  File "/home/airflow/.local/lib/python3.6/site-packages/airflow/cli/commands/task_command.py", line 298, in task_run
    _run_task_by_selected_method(args, dag, ti)
  File "/home/airflow/.local/lib/python3.6/site-packages/airflow/cli/commands/task_command.py", line 107, in _run_task_by_selected_method
    _run_raw_task(args, ti)
  File "/home/airflow/.local/lib/python3.6/site-packages/airflow/cli/commands/task_command.py", line 184, in _run_raw_task
    error_file=args.error_file,
  File "/home/airflow/.local/lib/python3.6/site-packages/airflow/utils/session.py", line 70, in wrapper
    return func(*args, session=session, **kwargs)
  File "/home/airflow/.local/lib/python3.6/site-packages/airflow/models/taskinstance.py", line 1329, in _run_raw_task
    self._execute_task_with_callbacks(context)
  File "/home/airflow/.local/lib/python3.6/site-packages/airflow/models/taskinstance.py", line 1455, in _execute_task_with_callbacks
    result = self._execute_task(context, self.task)
  File "/home/airflow/.local/lib/python3.6/site-packages/airflow/models/taskinstance.py", line 1511, in _execute_task
    result = execute_callable(context=context)
  File "/home/airflow/.local/lib/python3.6/site-packages/airflow/operators/python.py", line 174, in execute
    return_value = self.execute_callable()
  File "/home/airflow/.local/lib/python3.6/site-packages/airflow/operators/python.py", line 185, in execute_callable
    return self.python_callable(*self.op_args, **self.op_kwargs)
  File "/opt/airflow/dags/data_ingestion.py", line 110, in format_to_parquet
    fields = glom(src_file, 'fields')
  File "/home/airflow/.local/lib/python3.6/site-packages/glom/core.py", line 2296, in glom
    raise err
glom.core.PathAccessError: error raised while processing, details below.
 Target-spec trace (most recent last):
 - Target: '/opt/airflow/2024-05-21-3.json'
 - Spec: 'fields'
glom.core.PathAccessError: could not access 'fields', part 0 of Path('fields'), got error: AttributeError("'str' object has no attribute 'fields'",)
[2024-05-22 06:59:19,977] {local_task_job.py:154} INFO - Task exited with return code 1
[2024-05-22 06:59:20,192] {local_task_job.py:264} INFO - 0 downstream tasks scheduled from follow-on schedule check
[2024-05-22 07:07:01,597] {taskinstance.py:1032} INFO - Dependencies all met for <TaskInstance: purpleair_api_dag.format_to_parquet_task scheduled__2024-05-21T03:00:00+00:00 [queued]>
[2024-05-22 07:07:01,870] {taskinstance.py:1032} INFO - Dependencies all met for <TaskInstance: purpleair_api_dag.format_to_parquet_task scheduled__2024-05-21T03:00:00+00:00 [queued]>
[2024-05-22 07:07:01,908] {taskinstance.py:1238} INFO - 
--------------------------------------------------------------------------------
[2024-05-22 07:07:01,910] {taskinstance.py:1239} INFO - Starting attempt 1 of 2
[2024-05-22 07:07:01,911] {taskinstance.py:1240} INFO - 
--------------------------------------------------------------------------------
[2024-05-22 07:07:02,156] {taskinstance.py:1259} INFO - Executing <Task(PythonOperator): format_to_parquet_task> on 2024-05-21 03:00:00+00:00
[2024-05-22 07:07:02,310] {standard_task_runner.py:52} INFO - Started process 1326 to run task
[2024-05-22 07:07:02,355] {standard_task_runner.py:76} INFO - Running: ['***', 'tasks', 'run', 'purpleair_api_dag', 'format_to_parquet_task', 'scheduled__2024-05-21T03:00:00+00:00', '--job-id', '179', '--raw', '--subdir', 'DAGS_FOLDER/data_ingestion.py', '--cfg-path', '/tmp/tmppbhagcaw', '--error-file', '/tmp/tmp1a8bf4cb']
[2024-05-22 07:07:02,561] {standard_task_runner.py:77} INFO - Job 179: Subtask format_to_parquet_task
[2024-05-22 07:07:03,260] {logging_mixin.py:109} INFO - Running <TaskInstance: purpleair_api_dag.format_to_parquet_task scheduled__2024-05-21T03:00:00+00:00 [running]> on host 148b4063f71c
[2024-05-22 07:07:03,461] {warnings.py:99} WARNING - /home/***/.local/lib/python3.6/site-packages/***/utils/context.py:152: AirflowContextDeprecationWarning: Accessing 'execution_date' from the template is deprecated and will be removed in a future version. Please use 'data_interval_start' or 'logical_date' instead.
  warnings.warn(_create_deprecation_warning(key, self._deprecation_replacements[key]))

[2024-05-22 07:07:03,569] {taskinstance.py:1426} INFO - Exporting the following env vars:
AIRFLOW_CTX_DAG_OWNER=***
AIRFLOW_CTX_DAG_ID=purpleair_api_dag
AIRFLOW_CTX_TASK_ID=format_to_parquet_task
AIRFLOW_CTX_EXECUTION_DATE=2024-05-21T03:00:00+00:00
AIRFLOW_CTX_DAG_RUN_ID=scheduled__2024-05-21T03:00:00+00:00
[2024-05-22 07:07:03,571] {taskinstance.py:1700} ERROR - Task failed with exception
Traceback (most recent call last):
  File "/home/airflow/.local/lib/python3.6/site-packages/airflow/models/taskinstance.py", line 1329, in _run_raw_task
    self._execute_task_with_callbacks(context)
  File "/home/airflow/.local/lib/python3.6/site-packages/airflow/models/taskinstance.py", line 1455, in _execute_task_with_callbacks
    result = self._execute_task(context, self.task)
  File "/home/airflow/.local/lib/python3.6/site-packages/airflow/models/taskinstance.py", line 1511, in _execute_task
    result = execute_callable(context=context)
  File "/home/airflow/.local/lib/python3.6/site-packages/airflow/operators/python.py", line 174, in execute
    return_value = self.execute_callable()
  File "/home/airflow/.local/lib/python3.6/site-packages/airflow/operators/python.py", line 185, in execute_callable
    return self.python_callable(*self.op_args, **self.op_kwargs)
  File "/opt/airflow/dags/data_ingestion.py", line 108, in format_to_parquet
    with open(src_file, 'r') as file:
FileNotFoundError: [Errno 2] No such file or directory: '/opt/airflow/2024-05-21-3.json'
[2024-05-22 07:07:03,730] {taskinstance.py:1277} INFO - Marking task as UP_FOR_RETRY. dag_id=purpleair_api_dag, task_id=format_to_parquet_task, execution_date=20240521T030000, start_date=20240522T070701, end_date=20240522T070703
[2024-05-22 07:07:04,005] {standard_task_runner.py:92} ERROR - Failed to execute job 179 for task format_to_parquet_task
Traceback (most recent call last):
  File "/home/airflow/.local/lib/python3.6/site-packages/airflow/task/task_runner/standard_task_runner.py", line 85, in _start_by_fork
    args.func(args, dag=self.dag)
  File "/home/airflow/.local/lib/python3.6/site-packages/airflow/cli/cli_parser.py", line 48, in command
    return func(*args, **kwargs)
  File "/home/airflow/.local/lib/python3.6/site-packages/airflow/utils/cli.py", line 92, in wrapper
    return f(*args, **kwargs)
  File "/home/airflow/.local/lib/python3.6/site-packages/airflow/cli/commands/task_command.py", line 298, in task_run
    _run_task_by_selected_method(args, dag, ti)
  File "/home/airflow/.local/lib/python3.6/site-packages/airflow/cli/commands/task_command.py", line 107, in _run_task_by_selected_method
    _run_raw_task(args, ti)
  File "/home/airflow/.local/lib/python3.6/site-packages/airflow/cli/commands/task_command.py", line 184, in _run_raw_task
    error_file=args.error_file,
  File "/home/airflow/.local/lib/python3.6/site-packages/airflow/utils/session.py", line 70, in wrapper
    return func(*args, session=session, **kwargs)
  File "/home/airflow/.local/lib/python3.6/site-packages/airflow/models/taskinstance.py", line 1329, in _run_raw_task
    self._execute_task_with_callbacks(context)
  File "/home/airflow/.local/lib/python3.6/site-packages/airflow/models/taskinstance.py", line 1455, in _execute_task_with_callbacks
    result = self._execute_task(context, self.task)
  File "/home/airflow/.local/lib/python3.6/site-packages/airflow/models/taskinstance.py", line 1511, in _execute_task
    result = execute_callable(context=context)
  File "/home/airflow/.local/lib/python3.6/site-packages/airflow/operators/python.py", line 174, in execute
    return_value = self.execute_callable()
  File "/home/airflow/.local/lib/python3.6/site-packages/airflow/operators/python.py", line 185, in execute_callable
    return self.python_callable(*self.op_args, **self.op_kwargs)
  File "/opt/airflow/dags/data_ingestion.py", line 108, in format_to_parquet
    with open(src_file, 'r') as file:
FileNotFoundError: [Errno 2] No such file or directory: '/opt/airflow/2024-05-21-3.json'
[2024-05-22 07:07:04,172] {local_task_job.py:154} INFO - Task exited with return code 1
[2024-05-22 07:07:04,712] {local_task_job.py:264} INFO - 0 downstream tasks scheduled from follow-on schedule check
[2024-05-22 07:14:21,694] {taskinstance.py:1032} INFO - Dependencies all met for <TaskInstance: purpleair_api_dag.format_to_parquet_task scheduled__2024-05-21T03:00:00+00:00 [queued]>
[2024-05-22 07:14:21,816] {taskinstance.py:1032} INFO - Dependencies all met for <TaskInstance: purpleair_api_dag.format_to_parquet_task scheduled__2024-05-21T03:00:00+00:00 [queued]>
[2024-05-22 07:14:21,824] {taskinstance.py:1238} INFO - 
--------------------------------------------------------------------------------
[2024-05-22 07:14:21,825] {taskinstance.py:1239} INFO - Starting attempt 1 of 2
[2024-05-22 07:14:21,826] {taskinstance.py:1240} INFO - 
--------------------------------------------------------------------------------
[2024-05-22 07:14:21,956] {taskinstance.py:1259} INFO - Executing <Task(PythonOperator): format_to_parquet_task> on 2024-05-21 03:00:00+00:00
[2024-05-22 07:14:22,060] {standard_task_runner.py:76} INFO - Running: ['***', 'tasks', 'run', 'purpleair_api_dag', 'format_to_parquet_task', 'scheduled__2024-05-21T03:00:00+00:00', '--job-id', '260', '--raw', '--subdir', 'DAGS_FOLDER/data_ingestion.py', '--cfg-path', '/tmp/tmpjvdk2gbf', '--error-file', '/tmp/tmpy0vf2btb']
[2024-05-22 07:14:22,107] {standard_task_runner.py:77} INFO - Job 260: Subtask format_to_parquet_task
[2024-05-22 07:14:22,019] {standard_task_runner.py:52} INFO - Started process 1845 to run task
[2024-05-22 07:14:22,804] {logging_mixin.py:109} INFO - Running <TaskInstance: purpleair_api_dag.format_to_parquet_task scheduled__2024-05-21T03:00:00+00:00 [running]> on host 148b4063f71c
[2024-05-22 07:14:23,235] {warnings.py:99} WARNING - /home/***/.local/lib/python3.6/site-packages/***/utils/context.py:152: AirflowContextDeprecationWarning: Accessing 'execution_date' from the template is deprecated and will be removed in a future version. Please use 'data_interval_start' or 'logical_date' instead.
  warnings.warn(_create_deprecation_warning(key, self._deprecation_replacements[key]))

[2024-05-22 07:14:23,484] {taskinstance.py:1426} INFO - Exporting the following env vars:
AIRFLOW_CTX_DAG_OWNER=***
AIRFLOW_CTX_DAG_ID=purpleair_api_dag
AIRFLOW_CTX_TASK_ID=format_to_parquet_task
AIRFLOW_CTX_EXECUTION_DATE=2024-05-21T03:00:00+00:00
AIRFLOW_CTX_DAG_RUN_ID=scheduled__2024-05-21T03:00:00+00:00
[2024-05-22 07:14:23,486] {taskinstance.py:1700} ERROR - Task failed with exception
Traceback (most recent call last):
  File "/home/airflow/.local/lib/python3.6/site-packages/airflow/models/taskinstance.py", line 1329, in _run_raw_task
    self._execute_task_with_callbacks(context)
  File "/home/airflow/.local/lib/python3.6/site-packages/airflow/models/taskinstance.py", line 1455, in _execute_task_with_callbacks
    result = self._execute_task(context, self.task)
  File "/home/airflow/.local/lib/python3.6/site-packages/airflow/models/taskinstance.py", line 1511, in _execute_task
    result = execute_callable(context=context)
  File "/home/airflow/.local/lib/python3.6/site-packages/airflow/operators/python.py", line 174, in execute
    return_value = self.execute_callable()
  File "/home/airflow/.local/lib/python3.6/site-packages/airflow/operators/python.py", line 185, in execute_callable
    return self.python_callable(*self.op_args, **self.op_kwargs)
  File "/opt/airflow/dags/data_ingestion.py", line 108, in format_to_parquet
    with open(src_file, 'r') as file:
FileNotFoundError: [Errno 2] No such file or directory: '/opt/airflow/2024-05-21-3.json'
[2024-05-22 07:14:23,555] {taskinstance.py:1277} INFO - Marking task as UP_FOR_RETRY. dag_id=purpleair_api_dag, task_id=format_to_parquet_task, execution_date=20240521T030000, start_date=20240522T071421, end_date=20240522T071423
[2024-05-22 07:14:23,739] {standard_task_runner.py:92} ERROR - Failed to execute job 260 for task format_to_parquet_task
Traceback (most recent call last):
  File "/home/airflow/.local/lib/python3.6/site-packages/airflow/task/task_runner/standard_task_runner.py", line 85, in _start_by_fork
    args.func(args, dag=self.dag)
  File "/home/airflow/.local/lib/python3.6/site-packages/airflow/cli/cli_parser.py", line 48, in command
    return func(*args, **kwargs)
  File "/home/airflow/.local/lib/python3.6/site-packages/airflow/utils/cli.py", line 92, in wrapper
    return f(*args, **kwargs)
  File "/home/airflow/.local/lib/python3.6/site-packages/airflow/cli/commands/task_command.py", line 298, in task_run
    _run_task_by_selected_method(args, dag, ti)
  File "/home/airflow/.local/lib/python3.6/site-packages/airflow/cli/commands/task_command.py", line 107, in _run_task_by_selected_method
    _run_raw_task(args, ti)
  File "/home/airflow/.local/lib/python3.6/site-packages/airflow/cli/commands/task_command.py", line 184, in _run_raw_task
    error_file=args.error_file,
  File "/home/airflow/.local/lib/python3.6/site-packages/airflow/utils/session.py", line 70, in wrapper
    return func(*args, session=session, **kwargs)
  File "/home/airflow/.local/lib/python3.6/site-packages/airflow/models/taskinstance.py", line 1329, in _run_raw_task
    self._execute_task_with_callbacks(context)
  File "/home/airflow/.local/lib/python3.6/site-packages/airflow/models/taskinstance.py", line 1455, in _execute_task_with_callbacks
    result = self._execute_task(context, self.task)
  File "/home/airflow/.local/lib/python3.6/site-packages/airflow/models/taskinstance.py", line 1511, in _execute_task
    result = execute_callable(context=context)
  File "/home/airflow/.local/lib/python3.6/site-packages/airflow/operators/python.py", line 174, in execute
    return_value = self.execute_callable()
  File "/home/airflow/.local/lib/python3.6/site-packages/airflow/operators/python.py", line 185, in execute_callable
    return self.python_callable(*self.op_args, **self.op_kwargs)
  File "/opt/airflow/dags/data_ingestion.py", line 108, in format_to_parquet
    with open(src_file, 'r') as file:
FileNotFoundError: [Errno 2] No such file or directory: '/opt/airflow/2024-05-21-3.json'
[2024-05-22 07:14:23,845] {local_task_job.py:154} INFO - Task exited with return code 1
[2024-05-22 07:14:24,181] {local_task_job.py:264} INFO - 0 downstream tasks scheduled from follow-on schedule check
[2024-05-22 07:16:47,413] {taskinstance.py:1032} INFO - Dependencies all met for <TaskInstance: purpleair_api_dag.format_to_parquet_task scheduled__2024-05-21T03:00:00+00:00 [queued]>
[2024-05-22 07:16:47,526] {taskinstance.py:1032} INFO - Dependencies all met for <TaskInstance: purpleair_api_dag.format_to_parquet_task scheduled__2024-05-21T03:00:00+00:00 [queued]>
[2024-05-22 07:16:47,526] {taskinstance.py:1238} INFO - 
--------------------------------------------------------------------------------
[2024-05-22 07:16:47,526] {taskinstance.py:1239} INFO - Starting attempt 1 of 2
[2024-05-22 07:16:47,526] {taskinstance.py:1240} INFO - 
--------------------------------------------------------------------------------
[2024-05-22 07:16:47,576] {taskinstance.py:1259} INFO - Executing <Task(PythonOperator): format_to_parquet_task> on 2024-05-21 03:00:00+00:00
[2024-05-22 07:16:47,602] {standard_task_runner.py:52} INFO - Started process 2032 to run task
[2024-05-22 07:16:47,655] {standard_task_runner.py:76} INFO - Running: ['***', 'tasks', 'run', 'purpleair_api_dag', 'format_to_parquet_task', 'scheduled__2024-05-21T03:00:00+00:00', '--job-id', '292', '--raw', '--subdir', 'DAGS_FOLDER/data_ingestion.py', '--cfg-path', '/tmp/tmpxsgvslaq', '--error-file', '/tmp/tmpvh04rjf4']
[2024-05-22 07:16:47,665] {standard_task_runner.py:77} INFO - Job 292: Subtask format_to_parquet_task
[2024-05-22 07:16:48,055] {logging_mixin.py:109} INFO - Running <TaskInstance: purpleair_api_dag.format_to_parquet_task scheduled__2024-05-21T03:00:00+00:00 [running]> on host 148b4063f71c
[2024-05-22 07:16:48,457] {warnings.py:99} WARNING - /home/***/.local/lib/python3.6/site-packages/***/utils/context.py:152: AirflowContextDeprecationWarning: Accessing 'execution_date' from the template is deprecated and will be removed in a future version. Please use 'data_interval_start' or 'logical_date' instead.
  warnings.warn(_create_deprecation_warning(key, self._deprecation_replacements[key]))

[2024-05-22 07:16:48,686] {taskinstance.py:1426} INFO - Exporting the following env vars:
AIRFLOW_CTX_DAG_OWNER=***
AIRFLOW_CTX_DAG_ID=purpleair_api_dag
AIRFLOW_CTX_TASK_ID=format_to_parquet_task
AIRFLOW_CTX_EXECUTION_DATE=2024-05-21T03:00:00+00:00
AIRFLOW_CTX_DAG_RUN_ID=scheduled__2024-05-21T03:00:00+00:00
[2024-05-22 07:16:48,688] {taskinstance.py:1700} ERROR - Task failed with exception
Traceback (most recent call last):
  File "/home/airflow/.local/lib/python3.6/site-packages/airflow/models/taskinstance.py", line 1329, in _run_raw_task
    self._execute_task_with_callbacks(context)
  File "/home/airflow/.local/lib/python3.6/site-packages/airflow/models/taskinstance.py", line 1455, in _execute_task_with_callbacks
    result = self._execute_task(context, self.task)
  File "/home/airflow/.local/lib/python3.6/site-packages/airflow/models/taskinstance.py", line 1511, in _execute_task
    result = execute_callable(context=context)
  File "/home/airflow/.local/lib/python3.6/site-packages/airflow/operators/python.py", line 174, in execute
    return_value = self.execute_callable()
  File "/home/airflow/.local/lib/python3.6/site-packages/airflow/operators/python.py", line 185, in execute_callable
    return self.python_callable(*self.op_args, **self.op_kwargs)
  File "/opt/airflow/dags/data_ingestion.py", line 108, in format_to_parquet
    with open(src_file, 'r') as file:
FileNotFoundError: [Errno 2] No such file or directory: '/opt/airflow/2024-05-21-3.json'
[2024-05-22 07:16:48,853] {taskinstance.py:1277} INFO - Marking task as UP_FOR_RETRY. dag_id=purpleair_api_dag, task_id=format_to_parquet_task, execution_date=20240521T030000, start_date=20240522T071647, end_date=20240522T071648
[2024-05-22 07:16:49,021] {standard_task_runner.py:92} ERROR - Failed to execute job 292 for task format_to_parquet_task
Traceback (most recent call last):
  File "/home/airflow/.local/lib/python3.6/site-packages/airflow/task/task_runner/standard_task_runner.py", line 85, in _start_by_fork
    args.func(args, dag=self.dag)
  File "/home/airflow/.local/lib/python3.6/site-packages/airflow/cli/cli_parser.py", line 48, in command
    return func(*args, **kwargs)
  File "/home/airflow/.local/lib/python3.6/site-packages/airflow/utils/cli.py", line 92, in wrapper
    return f(*args, **kwargs)
  File "/home/airflow/.local/lib/python3.6/site-packages/airflow/cli/commands/task_command.py", line 298, in task_run
    _run_task_by_selected_method(args, dag, ti)
  File "/home/airflow/.local/lib/python3.6/site-packages/airflow/cli/commands/task_command.py", line 107, in _run_task_by_selected_method
    _run_raw_task(args, ti)
  File "/home/airflow/.local/lib/python3.6/site-packages/airflow/cli/commands/task_command.py", line 184, in _run_raw_task
    error_file=args.error_file,
  File "/home/airflow/.local/lib/python3.6/site-packages/airflow/utils/session.py", line 70, in wrapper
    return func(*args, session=session, **kwargs)
  File "/home/airflow/.local/lib/python3.6/site-packages/airflow/models/taskinstance.py", line 1329, in _run_raw_task
    self._execute_task_with_callbacks(context)
  File "/home/airflow/.local/lib/python3.6/site-packages/airflow/models/taskinstance.py", line 1455, in _execute_task_with_callbacks
    result = self._execute_task(context, self.task)
  File "/home/airflow/.local/lib/python3.6/site-packages/airflow/models/taskinstance.py", line 1511, in _execute_task
    result = execute_callable(context=context)
  File "/home/airflow/.local/lib/python3.6/site-packages/airflow/operators/python.py", line 174, in execute
    return_value = self.execute_callable()
  File "/home/airflow/.local/lib/python3.6/site-packages/airflow/operators/python.py", line 185, in execute_callable
    return self.python_callable(*self.op_args, **self.op_kwargs)
  File "/opt/airflow/dags/data_ingestion.py", line 108, in format_to_parquet
    with open(src_file, 'r') as file:
FileNotFoundError: [Errno 2] No such file or directory: '/opt/airflow/2024-05-21-3.json'
[2024-05-22 07:16:49,128] {local_task_job.py:154} INFO - Task exited with return code 1
[2024-05-22 07:16:49,960] {local_task_job.py:264} INFO - 0 downstream tasks scheduled from follow-on schedule check
[2024-05-22 07:29:20,998] {taskinstance.py:1032} INFO - Dependencies all met for <TaskInstance: purpleair_api_dag.format_to_parquet_task scheduled__2024-05-21T03:00:00+00:00 [queued]>
[2024-05-22 07:29:21,210] {taskinstance.py:1032} INFO - Dependencies all met for <TaskInstance: purpleair_api_dag.format_to_parquet_task scheduled__2024-05-21T03:00:00+00:00 [queued]>
[2024-05-22 07:29:21,233] {taskinstance.py:1238} INFO - 
--------------------------------------------------------------------------------
[2024-05-22 07:29:21,234] {taskinstance.py:1239} INFO - Starting attempt 1 of 2
[2024-05-22 07:29:21,235] {taskinstance.py:1240} INFO - 
--------------------------------------------------------------------------------
[2024-05-22 07:29:21,457] {taskinstance.py:1259} INFO - Executing <Task(PythonOperator): format_to_parquet_task> on 2024-05-21 03:00:00+00:00
[2024-05-22 07:29:21,532] {standard_task_runner.py:52} INFO - Started process 2792 to run task
[2024-05-22 07:29:21,605] {standard_task_runner.py:76} INFO - Running: ['***', 'tasks', 'run', 'purpleair_api_dag', 'format_to_parquet_task', 'scheduled__2024-05-21T03:00:00+00:00', '--job-id', '388', '--raw', '--subdir', 'DAGS_FOLDER/data_ingestion.py', '--cfg-path', '/tmp/tmprf7gp4ff', '--error-file', '/tmp/tmpzp79vh75']
[2024-05-22 07:29:21,687] {standard_task_runner.py:77} INFO - Job 388: Subtask format_to_parquet_task
[2024-05-22 07:29:22,395] {logging_mixin.py:109} INFO - Running <TaskInstance: purpleair_api_dag.format_to_parquet_task scheduled__2024-05-21T03:00:00+00:00 [running]> on host 148b4063f71c
[2024-05-22 07:29:22,597] {warnings.py:99} WARNING - /home/***/.local/lib/python3.6/site-packages/***/utils/context.py:152: AirflowContextDeprecationWarning: Accessing 'execution_date' from the template is deprecated and will be removed in a future version. Please use 'data_interval_start' or 'logical_date' instead.
  warnings.warn(_create_deprecation_warning(key, self._deprecation_replacements[key]))

[2024-05-22 07:29:22,733] {taskinstance.py:1426} INFO - Exporting the following env vars:
AIRFLOW_CTX_DAG_OWNER=***
AIRFLOW_CTX_DAG_ID=purpleair_api_dag
AIRFLOW_CTX_TASK_ID=format_to_parquet_task
AIRFLOW_CTX_EXECUTION_DATE=2024-05-21T03:00:00+00:00
AIRFLOW_CTX_DAG_RUN_ID=scheduled__2024-05-21T03:00:00+00:00
[2024-05-22 07:29:22,735] {taskinstance.py:1700} ERROR - Task failed with exception
Traceback (most recent call last):
  File "/home/airflow/.local/lib/python3.6/site-packages/airflow/models/taskinstance.py", line 1329, in _run_raw_task
    self._execute_task_with_callbacks(context)
  File "/home/airflow/.local/lib/python3.6/site-packages/airflow/models/taskinstance.py", line 1455, in _execute_task_with_callbacks
    result = self._execute_task(context, self.task)
  File "/home/airflow/.local/lib/python3.6/site-packages/airflow/models/taskinstance.py", line 1511, in _execute_task
    result = execute_callable(context=context)
  File "/home/airflow/.local/lib/python3.6/site-packages/airflow/operators/python.py", line 174, in execute
    return_value = self.execute_callable()
  File "/home/airflow/.local/lib/python3.6/site-packages/airflow/operators/python.py", line 185, in execute_callable
    return self.python_callable(*self.op_args, **self.op_kwargs)
  File "/opt/airflow/dags/data_ingestion.py", line 108, in format_to_parquet
    with open(src_file, 'r') as file:
FileNotFoundError: [Errno 2] No such file or directory: '/opt/airflow/2024-05-21-3.json'
[2024-05-22 07:29:22,822] {taskinstance.py:1277} INFO - Marking task as UP_FOR_RETRY. dag_id=purpleair_api_dag, task_id=format_to_parquet_task, execution_date=20240521T030000, start_date=20240522T072921, end_date=20240522T072922
[2024-05-22 07:29:22,917] {standard_task_runner.py:92} ERROR - Failed to execute job 388 for task format_to_parquet_task
Traceback (most recent call last):
  File "/home/airflow/.local/lib/python3.6/site-packages/airflow/task/task_runner/standard_task_runner.py", line 85, in _start_by_fork
    args.func(args, dag=self.dag)
  File "/home/airflow/.local/lib/python3.6/site-packages/airflow/cli/cli_parser.py", line 48, in command
    return func(*args, **kwargs)
  File "/home/airflow/.local/lib/python3.6/site-packages/airflow/utils/cli.py", line 92, in wrapper
    return f(*args, **kwargs)
  File "/home/airflow/.local/lib/python3.6/site-packages/airflow/cli/commands/task_command.py", line 298, in task_run
    _run_task_by_selected_method(args, dag, ti)
  File "/home/airflow/.local/lib/python3.6/site-packages/airflow/cli/commands/task_command.py", line 107, in _run_task_by_selected_method
    _run_raw_task(args, ti)
  File "/home/airflow/.local/lib/python3.6/site-packages/airflow/cli/commands/task_command.py", line 184, in _run_raw_task
    error_file=args.error_file,
  File "/home/airflow/.local/lib/python3.6/site-packages/airflow/utils/session.py", line 70, in wrapper
    return func(*args, session=session, **kwargs)
  File "/home/airflow/.local/lib/python3.6/site-packages/airflow/models/taskinstance.py", line 1329, in _run_raw_task
    self._execute_task_with_callbacks(context)
  File "/home/airflow/.local/lib/python3.6/site-packages/airflow/models/taskinstance.py", line 1455, in _execute_task_with_callbacks
    result = self._execute_task(context, self.task)
  File "/home/airflow/.local/lib/python3.6/site-packages/airflow/models/taskinstance.py", line 1511, in _execute_task
    result = execute_callable(context=context)
  File "/home/airflow/.local/lib/python3.6/site-packages/airflow/operators/python.py", line 174, in execute
    return_value = self.execute_callable()
  File "/home/airflow/.local/lib/python3.6/site-packages/airflow/operators/python.py", line 185, in execute_callable
    return self.python_callable(*self.op_args, **self.op_kwargs)
  File "/opt/airflow/dags/data_ingestion.py", line 108, in format_to_parquet
    with open(src_file, 'r') as file:
FileNotFoundError: [Errno 2] No such file or directory: '/opt/airflow/2024-05-21-3.json'
[2024-05-22 07:29:23,004] {local_task_job.py:154} INFO - Task exited with return code 1
[2024-05-22 07:29:23,365] {local_task_job.py:264} INFO - 0 downstream tasks scheduled from follow-on schedule check
[2024-05-22 07:33:26,074] {taskinstance.py:1032} INFO - Dependencies all met for <TaskInstance: purpleair_api_dag.format_to_parquet_task scheduled__2024-05-21T03:00:00+00:00 [queued]>
[2024-05-22 07:33:26,188] {taskinstance.py:1032} INFO - Dependencies all met for <TaskInstance: purpleair_api_dag.format_to_parquet_task scheduled__2024-05-21T03:00:00+00:00 [queued]>
[2024-05-22 07:33:26,188] {taskinstance.py:1238} INFO - 
--------------------------------------------------------------------------------
[2024-05-22 07:33:26,188] {taskinstance.py:1239} INFO - Starting attempt 1 of 2
[2024-05-22 07:33:26,188] {taskinstance.py:1240} INFO - 
--------------------------------------------------------------------------------
[2024-05-22 07:33:26,241] {taskinstance.py:1259} INFO - Executing <Task(PythonOperator): format_to_parquet_task> on 2024-05-21 03:00:00+00:00
[2024-05-22 07:33:26,399] {standard_task_runner.py:76} INFO - Running: ['***', 'tasks', 'run', 'purpleair_api_dag', 'format_to_parquet_task', 'scheduled__2024-05-21T03:00:00+00:00', '--job-id', '418', '--raw', '--subdir', 'DAGS_FOLDER/data_ingestion.py', '--cfg-path', '/tmp/tmpfbfjf3x1', '--error-file', '/tmp/tmppqtb9it5']
[2024-05-22 07:33:26,375] {standard_task_runner.py:52} INFO - Started process 3033 to run task
[2024-05-22 07:33:26,519] {standard_task_runner.py:77} INFO - Job 418: Subtask format_to_parquet_task
[2024-05-22 07:33:27,115] {logging_mixin.py:109} INFO - Running <TaskInstance: purpleair_api_dag.format_to_parquet_task scheduled__2024-05-21T03:00:00+00:00 [running]> on host 148b4063f71c
[2024-05-22 07:33:27,624] {warnings.py:99} WARNING - /home/***/.local/lib/python3.6/site-packages/***/utils/context.py:152: AirflowContextDeprecationWarning: Accessing 'execution_date' from the template is deprecated and will be removed in a future version. Please use 'data_interval_start' or 'logical_date' instead.
  warnings.warn(_create_deprecation_warning(key, self._deprecation_replacements[key]))

[2024-05-22 07:33:27,880] {taskinstance.py:1426} INFO - Exporting the following env vars:
AIRFLOW_CTX_DAG_OWNER=***
AIRFLOW_CTX_DAG_ID=purpleair_api_dag
AIRFLOW_CTX_TASK_ID=format_to_parquet_task
AIRFLOW_CTX_EXECUTION_DATE=2024-05-21T03:00:00+00:00
AIRFLOW_CTX_DAG_RUN_ID=scheduled__2024-05-21T03:00:00+00:00
[2024-05-22 07:33:27,881] {logging_mixin.py:109} INFO - The file 'data.json' was not found.
[2024-05-22 07:33:27,882] {taskinstance.py:1700} ERROR - Task failed with exception
Traceback (most recent call last):
  File "/home/airflow/.local/lib/python3.6/site-packages/airflow/models/taskinstance.py", line 1329, in _run_raw_task
    self._execute_task_with_callbacks(context)
  File "/home/airflow/.local/lib/python3.6/site-packages/airflow/models/taskinstance.py", line 1455, in _execute_task_with_callbacks
    result = self._execute_task(context, self.task)
  File "/home/airflow/.local/lib/python3.6/site-packages/airflow/models/taskinstance.py", line 1511, in _execute_task
    result = execute_callable(context=context)
  File "/home/airflow/.local/lib/python3.6/site-packages/airflow/operators/python.py", line 174, in execute
    return_value = self.execute_callable()
  File "/home/airflow/.local/lib/python3.6/site-packages/airflow/operators/python.py", line 185, in execute_callable
    return self.python_callable(*self.op_args, **self.op_kwargs)
  File "/opt/airflow/dags/data_ingestion.py", line 120, in format_to_parquet
    print(glom(json_data, 'fields'))
UnboundLocalError: local variable 'json_data' referenced before assignment
[2024-05-22 07:33:27,959] {taskinstance.py:1277} INFO - Marking task as UP_FOR_RETRY. dag_id=purpleair_api_dag, task_id=format_to_parquet_task, execution_date=20240521T030000, start_date=20240522T073326, end_date=20240522T073327
[2024-05-22 07:33:28,196] {standard_task_runner.py:92} ERROR - Failed to execute job 418 for task format_to_parquet_task
Traceback (most recent call last):
  File "/home/airflow/.local/lib/python3.6/site-packages/airflow/task/task_runner/standard_task_runner.py", line 85, in _start_by_fork
    args.func(args, dag=self.dag)
  File "/home/airflow/.local/lib/python3.6/site-packages/airflow/cli/cli_parser.py", line 48, in command
    return func(*args, **kwargs)
  File "/home/airflow/.local/lib/python3.6/site-packages/airflow/utils/cli.py", line 92, in wrapper
    return f(*args, **kwargs)
  File "/home/airflow/.local/lib/python3.6/site-packages/airflow/cli/commands/task_command.py", line 298, in task_run
    _run_task_by_selected_method(args, dag, ti)
  File "/home/airflow/.local/lib/python3.6/site-packages/airflow/cli/commands/task_command.py", line 107, in _run_task_by_selected_method
    _run_raw_task(args, ti)
  File "/home/airflow/.local/lib/python3.6/site-packages/airflow/cli/commands/task_command.py", line 184, in _run_raw_task
    error_file=args.error_file,
  File "/home/airflow/.local/lib/python3.6/site-packages/airflow/utils/session.py", line 70, in wrapper
    return func(*args, session=session, **kwargs)
  File "/home/airflow/.local/lib/python3.6/site-packages/airflow/models/taskinstance.py", line 1329, in _run_raw_task
    self._execute_task_with_callbacks(context)
  File "/home/airflow/.local/lib/python3.6/site-packages/airflow/models/taskinstance.py", line 1455, in _execute_task_with_callbacks
    result = self._execute_task(context, self.task)
  File "/home/airflow/.local/lib/python3.6/site-packages/airflow/models/taskinstance.py", line 1511, in _execute_task
    result = execute_callable(context=context)
  File "/home/airflow/.local/lib/python3.6/site-packages/airflow/operators/python.py", line 174, in execute
    return_value = self.execute_callable()
  File "/home/airflow/.local/lib/python3.6/site-packages/airflow/operators/python.py", line 185, in execute_callable
    return self.python_callable(*self.op_args, **self.op_kwargs)
  File "/opt/airflow/dags/data_ingestion.py", line 120, in format_to_parquet
    print(glom(json_data, 'fields'))
UnboundLocalError: local variable 'json_data' referenced before assignment
[2024-05-22 07:33:28,309] {local_task_job.py:154} INFO - Task exited with return code 1
[2024-05-22 07:33:28,454] {local_task_job.py:264} INFO - 0 downstream tasks scheduled from follow-on schedule check
