[2024-05-22 02:20:21,245] {taskinstance.py:1032} INFO - Dependencies all met for <TaskInstance: purpleair_api_dag.fetch_data scheduled__2024-05-21T01:00:00+00:00 [queued]>
[2024-05-22 02:20:21,451] {taskinstance.py:1032} INFO - Dependencies all met for <TaskInstance: purpleair_api_dag.fetch_data scheduled__2024-05-21T01:00:00+00:00 [queued]>
[2024-05-22 02:20:21,451] {taskinstance.py:1238} INFO - 
--------------------------------------------------------------------------------
[2024-05-22 02:20:21,451] {taskinstance.py:1239} INFO - Starting attempt 1 of 2
[2024-05-22 02:20:21,451] {taskinstance.py:1240} INFO - 
--------------------------------------------------------------------------------
[2024-05-22 02:20:21,556] {taskinstance.py:1259} INFO - Executing <Task(PythonOperator): fetch_data> on 2024-05-21 01:00:00+00:00
[2024-05-22 02:20:21,576] {standard_task_runner.py:52} INFO - Started process 2349 to run task
[2024-05-22 02:20:21,678] {standard_task_runner.py:76} INFO - Running: ['***', 'tasks', 'run', 'purpleair_api_dag', 'fetch_data', 'scheduled__2024-05-21T01:00:00+00:00', '--job-id', '4', '--raw', '--subdir', 'DAGS_FOLDER/data_ingestion.py', '--cfg-path', '/tmp/tmpqv42mqxr', '--error-file', '/tmp/tmpad_4e5eh']
[2024-05-22 02:20:21,726] {standard_task_runner.py:77} INFO - Job 4: Subtask fetch_data
[2024-05-22 02:20:22,301] {logging_mixin.py:109} INFO - Running <TaskInstance: purpleair_api_dag.fetch_data scheduled__2024-05-21T01:00:00+00:00 [running]> on host 8fe6997c1526
[2024-05-22 02:20:22,796] {taskinstance.py:1426} INFO - Exporting the following env vars:
AIRFLOW_CTX_DAG_OWNER=***
AIRFLOW_CTX_DAG_ID=purpleair_api_dag
AIRFLOW_CTX_TASK_ID=fetch_data
AIRFLOW_CTX_EXECUTION_DATE=2024-05-21T01:00:00+00:00
AIRFLOW_CTX_DAG_RUN_ID=scheduled__2024-05-21T01:00:00+00:00
[2024-05-22 02:20:23,014] {logging_mixin.py:109} INFO - Failed to retrieve data: 403
[2024-05-22 02:20:23,015] {python.py:175} INFO - Done. Returned value was: None
[2024-05-22 02:20:24,111] {taskinstance.py:1277} INFO - Marking task as SUCCESS. dag_id=purpleair_api_dag, task_id=fetch_data, execution_date=20240521T010000, start_date=20240522T022021, end_date=20240522T022024
[2024-05-22 02:20:24,251] {local_task_job.py:154} INFO - Task exited with return code 0
[2024-05-22 02:20:24,409] {local_task_job.py:264} INFO - 0 downstream tasks scheduled from follow-on schedule check
[2024-05-22 04:14:08,153] {taskinstance.py:1032} INFO - Dependencies all met for <TaskInstance: purpleair_api_dag.fetch_data scheduled__2024-05-21T01:00:00+00:00 [queued]>
[2024-05-22 04:14:08,269] {taskinstance.py:1032} INFO - Dependencies all met for <TaskInstance: purpleair_api_dag.fetch_data scheduled__2024-05-21T01:00:00+00:00 [queued]>
[2024-05-22 04:14:08,286] {taskinstance.py:1238} INFO - 
--------------------------------------------------------------------------------
[2024-05-22 04:14:08,287] {taskinstance.py:1239} INFO - Starting attempt 1 of 2
[2024-05-22 04:14:08,288] {taskinstance.py:1240} INFO - 
--------------------------------------------------------------------------------
[2024-05-22 04:14:08,377] {taskinstance.py:1259} INFO - Executing <Task(PythonOperator): fetch_data> on 2024-05-21 01:00:00+00:00
[2024-05-22 04:14:08,426] {standard_task_runner.py:52} INFO - Started process 132 to run task
[2024-05-22 04:14:08,530] {standard_task_runner.py:76} INFO - Running: ['***', 'tasks', 'run', 'purpleair_api_dag', 'fetch_data', 'scheduled__2024-05-21T01:00:00+00:00', '--job-id', '3', '--raw', '--subdir', 'DAGS_FOLDER/data_ingestion.py', '--cfg-path', '/tmp/tmphc02m832', '--error-file', '/tmp/tmppvfawtbz']
[2024-05-22 04:14:08,617] {standard_task_runner.py:77} INFO - Job 3: Subtask fetch_data
[2024-05-22 04:14:08,985] {logging_mixin.py:109} INFO - Running <TaskInstance: purpleair_api_dag.fetch_data scheduled__2024-05-21T01:00:00+00:00 [running]> on host 3419eee920a5
[2024-05-22 04:14:09,503] {taskinstance.py:1426} INFO - Exporting the following env vars:
AIRFLOW_CTX_DAG_OWNER=***
AIRFLOW_CTX_DAG_ID=purpleair_api_dag
AIRFLOW_CTX_TASK_ID=fetch_data
AIRFLOW_CTX_EXECUTION_DATE=2024-05-21T01:00:00+00:00
AIRFLOW_CTX_DAG_RUN_ID=scheduled__2024-05-21T01:00:00+00:00
[2024-05-22 04:14:09,525] {taskinstance.py:1700} ERROR - Task failed with exception
Traceback (most recent call last):
  File "/home/airflow/.local/lib/python3.6/site-packages/airflow/models/taskinstance.py", line 1329, in _run_raw_task
    self._execute_task_with_callbacks(context)
  File "/home/airflow/.local/lib/python3.6/site-packages/airflow/models/taskinstance.py", line 1455, in _execute_task_with_callbacks
    result = self._execute_task(context, self.task)
  File "/home/airflow/.local/lib/python3.6/site-packages/airflow/models/taskinstance.py", line 1511, in _execute_task
    result = execute_callable(context=context)
  File "/home/airflow/.local/lib/python3.6/site-packages/airflow/operators/python.py", line 174, in execute
    return_value = self.execute_callable()
  File "/home/airflow/.local/lib/python3.6/site-packages/airflow/operators/python.py", line 185, in execute_callable
    return self.python_callable(*self.op_args, **self.op_kwargs)
  File "/opt/airflow/dags/data_ingestion.py", line 67, in api_url
    print(f" url is {url}")
NameError: name 'url' is not defined
[2024-05-22 04:14:09,675] {taskinstance.py:1277} INFO - Marking task as UP_FOR_RETRY. dag_id=purpleair_api_dag, task_id=fetch_data, execution_date=20240521T010000, start_date=20240522T041408, end_date=20240522T041409
[2024-05-22 04:14:09,821] {standard_task_runner.py:92} ERROR - Failed to execute job 3 for task fetch_data
Traceback (most recent call last):
  File "/home/airflow/.local/lib/python3.6/site-packages/airflow/task/task_runner/standard_task_runner.py", line 85, in _start_by_fork
    args.func(args, dag=self.dag)
  File "/home/airflow/.local/lib/python3.6/site-packages/airflow/cli/cli_parser.py", line 48, in command
    return func(*args, **kwargs)
  File "/home/airflow/.local/lib/python3.6/site-packages/airflow/utils/cli.py", line 92, in wrapper
    return f(*args, **kwargs)
  File "/home/airflow/.local/lib/python3.6/site-packages/airflow/cli/commands/task_command.py", line 298, in task_run
    _run_task_by_selected_method(args, dag, ti)
  File "/home/airflow/.local/lib/python3.6/site-packages/airflow/cli/commands/task_command.py", line 107, in _run_task_by_selected_method
    _run_raw_task(args, ti)
  File "/home/airflow/.local/lib/python3.6/site-packages/airflow/cli/commands/task_command.py", line 184, in _run_raw_task
    error_file=args.error_file,
  File "/home/airflow/.local/lib/python3.6/site-packages/airflow/utils/session.py", line 70, in wrapper
    return func(*args, session=session, **kwargs)
  File "/home/airflow/.local/lib/python3.6/site-packages/airflow/models/taskinstance.py", line 1329, in _run_raw_task
    self._execute_task_with_callbacks(context)
  File "/home/airflow/.local/lib/python3.6/site-packages/airflow/models/taskinstance.py", line 1455, in _execute_task_with_callbacks
    result = self._execute_task(context, self.task)
  File "/home/airflow/.local/lib/python3.6/site-packages/airflow/models/taskinstance.py", line 1511, in _execute_task
    result = execute_callable(context=context)
  File "/home/airflow/.local/lib/python3.6/site-packages/airflow/operators/python.py", line 174, in execute
    return_value = self.execute_callable()
  File "/home/airflow/.local/lib/python3.6/site-packages/airflow/operators/python.py", line 185, in execute_callable
    return self.python_callable(*self.op_args, **self.op_kwargs)
  File "/opt/airflow/dags/data_ingestion.py", line 67, in api_url
    print(f" url is {url}")
NameError: name 'url' is not defined
[2024-05-22 04:14:09,947] {local_task_job.py:154} INFO - Task exited with return code 1
[2024-05-22 04:14:10,149] {local_task_job.py:264} INFO - 0 downstream tasks scheduled from follow-on schedule check
[2024-05-22 04:17:32,603] {taskinstance.py:1032} INFO - Dependencies all met for <TaskInstance: purpleair_api_dag.fetch_data scheduled__2024-05-21T01:00:00+00:00 [queued]>
[2024-05-22 04:17:32,823] {taskinstance.py:1032} INFO - Dependencies all met for <TaskInstance: purpleair_api_dag.fetch_data scheduled__2024-05-21T01:00:00+00:00 [queued]>
[2024-05-22 04:17:32,872] {taskinstance.py:1238} INFO - 
--------------------------------------------------------------------------------
[2024-05-22 04:17:32,873] {taskinstance.py:1239} INFO - Starting attempt 1 of 2
[2024-05-22 04:17:32,889] {taskinstance.py:1240} INFO - 
--------------------------------------------------------------------------------
[2024-05-22 04:17:33,162] {taskinstance.py:1259} INFO - Executing <Task(PythonOperator): fetch_data> on 2024-05-21 01:00:00+00:00
[2024-05-22 04:17:33,242] {standard_task_runner.py:52} INFO - Started process 322 to run task
[2024-05-22 04:17:33,441] {standard_task_runner.py:76} INFO - Running: ['***', 'tasks', 'run', 'purpleair_api_dag', 'fetch_data', 'scheduled__2024-05-21T01:00:00+00:00', '--job-id', '21', '--raw', '--subdir', 'DAGS_FOLDER/data_ingestion.py', '--cfg-path', '/tmp/tmpsmd490yu', '--error-file', '/tmp/tmpd6hb54gh']
[2024-05-22 04:17:33,780] {standard_task_runner.py:77} INFO - Job 21: Subtask fetch_data
[2024-05-22 04:17:34,405] {logging_mixin.py:109} INFO - Running <TaskInstance: purpleair_api_dag.fetch_data scheduled__2024-05-21T01:00:00+00:00 [running]> on host 3419eee920a5
[2024-05-22 04:17:35,192] {taskinstance.py:1426} INFO - Exporting the following env vars:
AIRFLOW_CTX_DAG_OWNER=***
AIRFLOW_CTX_DAG_ID=purpleair_api_dag
AIRFLOW_CTX_TASK_ID=fetch_data
AIRFLOW_CTX_EXECUTION_DATE=2024-05-21T01:00:00+00:00
AIRFLOW_CTX_DAG_RUN_ID=scheduled__2024-05-21T01:00:00+00:00
[2024-05-22 04:17:35,196] {logging_mixin.py:109} INFO -  api is None
[2024-05-22 04:17:35,274] {logging_mixin.py:109} INFO - Full URL: https://api.purpleair.com/v1/sensors?fields=latitude%2Clongitude%2Chumidity%2Cpm2.5_60minute%2Clast_seen&location_type=0&max_age=300
[2024-05-22 04:17:35,275] {logging_mixin.py:109} INFO - Headers: {'X-API-Key': 'None'}
[2024-05-22 04:17:35,639] {logging_mixin.py:109} INFO - Status Code: 403
[2024-05-22 04:17:35,708] {logging_mixin.py:109} INFO - Response Content: {
  "api_version" : "V1.0.13-0.0.56",
  "time_stamp" : 1716351455,
  "error" : "ApiKeyInvalidError",
  "description" : "The provided api_key was not valid."
}
[2024-05-22 04:17:35,902] {logging_mixin.py:109} INFO - Failed to retrieve data: 403
[2024-05-22 04:17:35,924] {python.py:175} INFO - Done. Returned value was: None
[2024-05-22 04:17:36,016] {taskinstance.py:1277} INFO - Marking task as SUCCESS. dag_id=purpleair_api_dag, task_id=fetch_data, execution_date=20240521T010000, start_date=20240522T041732, end_date=20240522T041736
[2024-05-22 04:17:36,237] {local_task_job.py:154} INFO - Task exited with return code 0
[2024-05-22 04:17:36,345] {local_task_job.py:264} INFO - 0 downstream tasks scheduled from follow-on schedule check
